Workbook
Name IDS: "Rectangle 3"

Sheet Drilling
L5: =[1]Control!AU10 -> 25 Nov - 24 Dec 2025 | AP5: =[1]Control!AU10 -> 25 Nov - 24 Dec 2025
C7: FUEL COST | E7: CHARTER RATE | G7: MOB / DEMOB | I7: TOTAL COST | J7: PCT | L7: BOAT HOURS | M7: PCT | AG7: FUEL COST | AI7: CHARTER RATE | AK7: MOB / DEMOB | AM7: TOTAL COST | AN7: PCT | AP7: BOAT HOURS | AQ7: PCT
L8: Logistics Cost Sharing | AP8: Logistics Cost Sharing
A9: =[1]Control!$GP$10 -> RUN EXPLOSIVE | C9: =Distribute!C42 -> 0 | E9: =Distribute!D42 -> 0 | G9: =Distribute!E42 -> 0 | I9: =SUM(C9:G9) -> 0 | J9: =(I9/I$23)*100% -> 0 | L9: ='[2]AHTS-1'!FR42+'[2]AHTS-2'!FR42+'[2]AHTS-3'!FR42+'[2]AHTS-4'!FR42+'[2]AHTS-5'!FR42+'[2]AHTS-6'!FR42+'[2]AHTS-7'!FR42+'[2]AHTS-8'!FR42+'[3]CB-1'!FR42+'[3]CB-2'!FR42+'[3]CB-3'!FR42+'[3]CB-4'!FR42+'[3]CB-5'!FR42+'[3]CB-6'!FR42+'[3]CB-7'!FR42+'[3]CB-8'!FR42+'[3]CB-9'!FR42+'[3]CB-10'!FR42+'[3]CB-11'!FR42+'[3]CB-12'!FR42+'[3]CB-13'!FR42+'[3]CB-14'!FR42+'[3]CB-15'!FR42+'[3]CB-16'!FR42+'[3]CB-17'!FR42+'[3]CB-18'!FR42+'[3]CB-19'!FR42+'[3]CB-20'!FR42+'[3]CB-21'!FR42+'[3]CB-22'!FR42+'[3]CB-23'!FR42+'[3]CB-24'!FR42+'[4]LCT-1'!FR42+'[4]LCT-2'!FR42+'[4]LCT-3'!FR42+'[4]LCT-4'!FR42+'[4]LCT-5'!FR42+'[4]LCT-6'!FR42+'[4]LCT-7'!FR42+'[4]LCT-8'!FR42+'[5]TB-1'!FR42+'[5]TB-2'!FR42+'[5]TB-3'!FR42+'[5]TB-4'!FR42+'[5]TB-5'!FR42+'[5]TB-6'!FR42+'[5]TB-7'!FR42+'[5]TB-8'!FR42+'[5]TB-9'!FR42+'[5]TB-10'!FR42+'[6]DSV-1'!FR42+'[6]DSV-2'!FR42+'[6]DSV-3'!FR42+'[7]TUB-1'!FR42+'[7]TUB-2'!FR42+'[8]Barge-1'!FR42+'[8]Barge-2'!FR42+'[8]Barge-3'!FR42+'[8]Barge-4'!FR42 -> 0 | M9: =(L9/L$23)*100% -> 0 | AE9: =[1]Control!$GP$10 -> RUN EXPLOSIVE | AG9: =Distribute!AT42 -> 0 | AI9: =Distribute!AU42 -> 0 | AK9: =Distribute!AV42 -> 0 | AM9: =SUM(AG9:AK9) -> 0 | AN9: =(AM9/AM$23)*100% -> 0 | AP9: ='[2]AHTS-1'!FR42+'[2]AHTS-2'!FR42+'[2]AHTS-3'!FR42+'[2]AHTS-4'!FR42+'[2]AHTS-5'!FR42+'[2]AHTS-6'!FR42+'[2]AHTS-7'!FR42+'[2]AHTS-8'!FR42+'[3]CB-1'!FR42+'[3]CB-2'!FR42+'[3]CB-3'!FR42+'[3]CB-4'!FR42+'[3]CB-5'!FR42+'[3]CB-6'!FR42+'[3]CB-7'!FR42+'[3]CB-8'!FR42+'[3]CB-9'!FR42+'[3]CB-10'!FR42+'[3]CB-11'!FR42+'[3]CB-12'!FR42+'[3]CB-13'!FR42+'[3]CB-14'!FR42+'[3]CB-15'!FR42+'[3]CB-16'!FR42+'[3]CB-17'!FR42+'[3]CB-18'!FR42+'[3]CB-19'!FR42+'[3]CB-20'!FR42+'[3]CB-21'!FR42+'[3]CB-22'!FR42+'[3]CB-23'!FR42+'[3]CB-24'!FR42+'[4]LCT-1'!FR42+'[4]LCT-2'!FR42+'[4]LCT-3'!FR42+'[4]LCT-4'!FR42+'[4]LCT-5'!FR42+'[4]LCT-6'!FR42+'[4]LCT-7'!FR42+'[4]LCT-8'!FR42+'[5]TB-1'!FR42+'[5]TB-2'!FR42+'[5]TB-3'!FR42+'[5]TB-4'!FR42+'[5]TB-5'!FR42+'[5]TB-6'!FR42+'[5]TB-7'!FR42+'[5]TB-8'!FR42+'[5]TB-9'!FR42+'[5]TB-10'!FR42+'[6]DSV-1'!FR42+'[6]DSV-2'!FR42+'[6]DSV-3'!FR42+'[7]TUB-1'!FR42+'[7]TUB-2'!FR42+'[8]Barge-1'!FR42+'[8]Barge-2'!FR42+'[8]Barge-3'!FR42+'[8]Barge-4'!FR42 -> 0 | AQ9: =(AP9/AP$23)*100% -> 0
A10: =[1]Control!$GQ$10 -> ASSET | C10: =Distribute!F42 -> 0 | E10: =Distribute!G42 -> 0 | G10: =Distribute!H42 -> 0 | I10: =SUM(C10:G10) -> 0 | J10: =(I10/I$23)*100% -> 0 | L10: ='[2]AHTS-1'!FS42+'[2]AHTS-2'!FS42+'[2]AHTS-3'!FS42+'[2]AHTS-4'!FS42+'[2]AHTS-5'!FS42+'[2]AHTS-6'!FS42+'[2]AHTS-7'!FS42+'[2]AHTS-8'!FS42+'[3]CB-1'!FS42+'[3]CB-2'!FS42+'[3]CB-3'!FS42+'[3]CB-4'!FS42+'[3]CB-5'!FS42+'[3]CB-6'!FS42+'[3]CB-7'!FS42+'[3]CB-8'!FS42+'[3]CB-9'!FS42+'[3]CB-10'!FS42+'[3]CB-11'!FS42+'[3]CB-12'!FS42+'[3]CB-13'!FS42+'[3]CB-14'!FS42+'[3]CB-15'!FS42+'[3]CB-16'!FS42+'[3]CB-17'!FS42+'[3]CB-18'!FS42+'[3]CB-19'!FS42+'[3]CB-20'!FS42+'[3]CB-21'!FS42+'[3]CB-22'!FS42+'[3]CB-23'!FS42+'[3]CB-24'!FS42+'[4]LCT-1'!FS42+'[4]LCT-2'!FS42+'[4]LCT-3'!FS42+'[4]LCT-4'!FS42+'[4]LCT-5'!FS42+'[4]LCT-6'!FS42+'[4]LCT-7'!FS42+'[4]LCT-8'!FS42+'[5]TB-1'!FS42+'[5]TB-2'!FS42+'[5]TB-3'!FS42+'[5]TB-4'!FS42+'[5]TB-5'!FS42+'[5]TB-6'!FS42+'[5]TB-7'!FS42+'[5]TB-8'!FS42+'[5]TB-9'!FS42+'[5]TB-10'!FS42+'[6]DSV-1'!FS42+'[6]DSV-2'!FS42+'[6]DSV-3'!FS42+'[7]TUB-1'!FS42+'[7]TUB-2'!FS42+'[8]Barge-1'!FS42+'[8]Barge-2'!FS42+'[8]Barge-3'!FS42+'[8]Barge-4'!FS42 -> 0 | M10: =(L10/L$23)*100% -> 0 | AE10: =[1]Control!$GQ$10 -> ASSET | AG10: =Distribute!AW42 -> 0 | AI10: =Distribute!AX42 -> 0 | AK10: =Distribute!AY42 -> 0 | AM10: =SUM(AG10:AK10) -> 0 | AN10: =(AM10/AM$23)*100% -> 0 | AP10: ='[2]AHTS-1'!FS42+'[2]AHTS-2'!FS42+'[2]AHTS-3'!FS42+'[2]AHTS-4'!FS42+'[2]AHTS-5'!FS42+'[2]AHTS-6'!FS42+'[2]AHTS-7'!FS42+'[2]AHTS-8'!FS42+'[3]CB-1'!FS42+'[3]CB-2'!FS42+'[3]CB-3'!FS42+'[3]CB-4'!FS42+'[3]CB-5'!FS42+'[3]CB-6'!FS42+'[3]CB-7'!FS42+'[3]CB-8'!FS42+'[3]CB-9'!FS42+'[3]CB-10'!FS42+'[3]CB-11'!FS42+'[3]CB-12'!FS42+'[3]CB-13'!FS42+'[3]CB-14'!FS42+'[3]CB-15'!FS42+'[3]CB-16'!FS42+'[3]CB-17'!FS42+'[3]CB-18'!FS42+'[3]CB-19'!FS42+'[3]CB-20'!FS42+'[3]CB-21'!FS42+'[3]CB-22'!FS42+'[3]CB-23'!FS42+'[3]CB-24'!FS42+'[4]LCT-1'!FS42+'[4]LCT-2'!FS42+'[4]LCT-3'!FS42+'[4]LCT-4'!FS42+'[4]LCT-5'!FS42+'[4]LCT-6'!FS42+'[4]LCT-7'!FS42+'[4]LCT-8'!FS42+'[5]TB-1'!FS42+'[5]TB-2'!FS42+'[5]TB-3'!FS42+'[5]TB-4'!FS42+'[5]TB-5'!FS42+'[5]TB-6'!FS42+'[5]TB-7'!FS42+'[5]TB-8'!FS42+'[5]TB-9'!FS42+'[5]TB-10'!FS42+'[6]DSV-1'!FS42+'[6]DSV-2'!FS42+'[6]DSV-3'!FS42+'[7]TUB-1'!FS42+'[7]TUB-2'!FS42+'[8]Barge-1'!FS42+'[8]Barge-2'!FS42+'[8]Barge-3'!FS42+'[8]Barge-4'!FS42 -> 0 | AQ10: =(AP10/AP$23)*100% -> 0
A11: =[1]Control!$GR$10 -> TIRTA RAJAWALI | C11: =Distribute!I42 -> 128396.58 | E11: =Distribute!J42 -> 126759.82 | G11: =Distribute!K42 -> 0 | I11: =SUM(C11:G11) -> 255156.4 | J11: =(I11/I$23)*100% -> 0.71113059 | L11: ='[2]AHTS-1'!FT42+'[2]AHTS-2'!FT42+'[2]AHTS-3'!FT42+'[2]AHTS-4'!FT42+'[2]AHTS-5'!FT42+'[2]AHTS-6'!FT42+'[2]AHTS-7'!FT42+'[2]AHTS-8'!FT42+'[3]CB-1'!FT42+'[3]CB-2'!FT42+'[3]CB-3'!FT42+'[3]CB-4'!FT42+'[3]CB-5'!FT42+'[3]CB-6'!FT42+'[3]CB-7'!FT42+'[3]CB-8'!FT42+'[3]CB-9'!FT42+'[3]CB-10'!FT42+'[3]CB-11'!FT42+'[3]CB-12'!FT42+'[3]CB-13'!FT42+'[3]CB-14'!FT42+'[3]CB-15'!FT42+'[3]CB-16'!FT42+'[3]CB-17'!FT42+'[3]CB-18'!FT42+'[3]CB-19'!FT42+'[3]CB-20'!FT42+'[3]CB-21'!FT42+'[3]CB-22'!FT42+'[3]CB-23'!FT42+'[3]CB-24'!FT42+'[4]LCT-1'!FT42+'[4]LCT-2'!FT42+'[4]LCT-3'!FT42+'[4]LCT-4'!FT42+'[4]LCT-5'!FT42+'[4]LCT-6'!FT42+'[4]LCT-7'!FT42+'[4]LCT-8'!FT42+'[5]TB-1'!FT42+'[5]TB-2'!FT42+'[5]TB-3'!FT42+'[5]TB-4'!FT42+'[5]TB-5'!FT42+'[5]TB-6'!FT42+'[5]TB-7'!FT42+'[5]TB-8'!FT42+'[5]TB-9'!FT42+'[5]TB-10'!FT42+'[6]DSV-1'!FT42+'[6]DSV-2'!FT42+'[6]DSV-3'!FT42+'[7]TUB-1'!FT42+'[7]TUB-2'!FT42+'[8]Barge-1'!FT42+'[8]Barge-2'!FT42+'[8]Barge-3'!FT42+'[8]Barge-4'!FT42 -> 2113.9333 | M11: =(L11/L$23)*100% -> 0.76062656 | AE11: =[1]Control!$GR$10 -> TIRTA RAJAWALI | AG11: =Distribute!AZ42 -> 2.0224265e+09 | AI11: =Distribute!BA42 -> 1.9975417e+09 | AK11: =Distribute!BB42 -> 0 | AM11: =SUM(AG11:AK11) -> 4.0199682e+09 | AN11: =(AM11/AM$23)*100% -> 0.71122795 | AP11: ='[2]AHTS-1'!FT42+'[2]AHTS-2'!FT42+'[2]AHTS-3'!FT42+'[2]AHTS-4'!FT42+'[2]AHTS-5'!FT42+'[2]AHTS-6'!FT42+'[2]AHTS-7'!FT42+'[2]AHTS-8'!FT42+'[3]CB-1'!FT42+'[3]CB-2'!FT42+'[3]CB-3'!FT42+'[3]CB-4'!FT42+'[3]CB-5'!FT42+'[3]CB-6'!FT42+'[3]CB-7'!FT42+'[3]CB-8'!FT42+'[3]CB-9'!FT42+'[3]CB-10'!FT42+'[3]CB-11'!FT42+'[3]CB-12'!FT42+'[3]CB-13'!FT42+'[3]CB-14'!FT42+'[3]CB-15'!FT42+'[3]CB-16'!FT42+'[3]CB-17'!FT42+'[3]CB-18'!FT42+'[3]CB-19'!FT42+'[3]CB-20'!FT42+'[3]CB-21'!FT42+'[3]CB-22'!FT42+'[3]CB-23'!FT42+'[3]CB-24'!FT42+'[4]LCT-1'!FT42+'[4]LCT-2'!FT42+'[4]LCT-3'!FT42+'[4]LCT-4'!FT42+'[4]LCT-5'!FT42+'[4]LCT-6'!FT42+'[4]LCT-7'!FT42+'[4]LCT-8'!FT42+'[5]TB-1'!FT42+'[5]TB-2'!FT42+'[5]TB-3'!FT42+'[5]TB-4'!FT42+'[5]TB-5'!FT42+'[5]TB-6'!FT42+'[5]TB-7'!FT42+'[5]TB-8'!FT42+'[5]TB-9'!FT42+'[5]TB-10'!FT42+'[6]DSV-1'!FT42+'[6]DSV-2'!FT42+'[6]DSV-3'!FT42+'[7]TUB-1'!FT42+'[7]TUB-2'!FT42+'[8]Barge-1'!FT42+'[8]Barge-2'!FT42+'[8]Barge-3'!FT42+'[8]Barge-4'!FT42 -> 2113.9333 | AQ11: =(AP11/AP$23)*100% -> 0.76062656
A12: =[1]Control!$GS$10 -> S: SLICKLINE UNIT | C12: =Distribute!L42 -> 24122.514 | E12: =Distribute!M42 -> 21379.192 | G12: =Distribute!N42 -> 0 | I12: =SUM(C12:G12) -> 45501.705 | J12: =(I12/I$23)*100% -> 0.12681498 | L12: ='[2]AHTS-1'!FU42+'[2]AHTS-2'!FU42+'[2]AHTS-3'!FU42+'[2]AHTS-4'!FU42+'[2]AHTS-5'!FU42+'[2]AHTS-6'!FU42+'[2]AHTS-7'!FU42+'[2]AHTS-8'!FU42+'[3]CB-1'!FU42+'[3]CB-2'!FU42+'[3]CB-3'!FU42+'[3]CB-4'!FU42+'[3]CB-5'!FU42+'[3]CB-6'!FU42+'[3]CB-7'!FU42+'[3]CB-8'!FU42+'[3]CB-9'!FU42+'[3]CB-10'!FU42+'[3]CB-11'!FU42+'[3]CB-12'!FU42+'[3]CB-13'!FU42+'[3]CB-14'!FU42+'[3]CB-15'!FU42+'[3]CB-16'!FU42+'[3]CB-17'!FU42+'[3]CB-18'!FU42+'[3]CB-19'!FU42+'[3]CB-20'!FU42+'[3]CB-21'!FU42+'[3]CB-22'!FU42+'[3]CB-23'!FU42+'[3]CB-24'!FU42+'[4]LCT-1'!FU42+'[4]LCT-2'!FU42+'[4]LCT-3'!FU42+'[4]LCT-4'!FU42+'[4]LCT-5'!FU42+'[4]LCT-6'!FU42+'[4]LCT-7'!FU42+'[4]LCT-8'!FU42+'[5]TB-1'!FU42+'[5]TB-2'!FU42+'[5]TB-3'!FU42+'[5]TB-4'!FU42+'[5]TB-5'!FU42+'[5]TB-6'!FU42+'[5]TB-7'!FU42+'[5]TB-8'!FU42+'[5]TB-9'!FU42+'[5]TB-10'!FU42+'[6]DSV-1'!FU42+'[6]DSV-2'!FU42+'[6]DSV-3'!FU42+'[7]TUB-1'!FU42+'[7]TUB-2'!FU42+'[8]Barge-1'!FU42+'[8]Barge-2'!FU42+'[8]Barge-3'!FU42+'[8]Barge-4'!FU42 -> 292 | M12: =(L12/L$23)*100% -> 0.10506621 | AE12: =[1]Control!$GS$10 -> S: SLICKLINE UNIT | AG12: =Distribute!BC42 -> 3.7990722e+08 | AI12: =Distribute!BD42 -> 336975000 | AK12: =Distribute!BE42 -> 0 | AM12: =SUM(AG12:AK12) -> 7.1688222e+08 | AN12: =(AM12/AM$23)*100% -> 0.12683351 | AP12: ='[2]AHTS-1'!FU42+'[2]AHTS-2'!FU42+'[2]AHTS-3'!FU42+'[2]AHTS-4'!FU42+'[2]AHTS-5'!FU42+'[2]AHTS-6'!FU42+'[2]AHTS-7'!FU42+'[2]AHTS-8'!FU42+'[3]CB-1'!FU42+'[3]CB-2'!FU42+'[3]CB-3'!FU42+'[3]CB-4'!FU42+'[3]CB-5'!FU42+'[3]CB-6'!FU42+'[3]CB-7'!FU42+'[3]CB-8'!FU42+'[3]CB-9'!FU42+'[3]CB-10'!FU42+'[3]CB-11'!FU42+'[3]CB-12'!FU42+'[3]CB-13'!FU42+'[3]CB-14'!FU42+'[3]CB-15'!FU42+'[3]CB-16'!FU42+'[3]CB-17'!FU42+'[3]CB-18'!FU42+'[3]CB-19'!FU42+'[3]CB-20'!FU42+'[3]CB-21'!FU42+'[3]CB-22'!FU42+'[3]CB-23'!FU42+'[3]CB-24'!FU42+'[4]LCT-1'!FU42+'[4]LCT-2'!FU42+'[4]LCT-3'!FU42+'[4]LCT-4'!FU42+'[4]LCT-5'!FU42+'[4]LCT-6'!FU42+'[4]LCT-7'!FU42+'[4]LCT-8'!FU42+'[5]TB-1'!FU42+'[5]TB-2'!FU42+'[5]TB-3'!FU42+'[5]TB-4'!FU42+'[5]TB-5'!FU42+'[5]TB-6'!FU42+'[5]TB-7'!FU42+'[5]TB-8'!FU42+'[5]TB-9'!FU42+'[5]TB-10'!FU42+'[6]DSV-1'!FU42+'[6]DSV-2'!FU42+'[6]DSV-3'!FU42+'[7]TUB-1'!FU42+'[7]TUB-2'!FU42+'[8]Barge-1'!FU42+'[8]Barge-2'!FU42+'[8]Barge-3'!FU42+'[8]Barge-4'!FU42 -> 292 | AQ12: =(AP12/AP$23)*100% -> 0.10506621
A13: =[1]Control!$GT$10 -> N: SLICKLINE (1) | C13: =Distribute!O42 -> 0 | E13: =Distribute!P42 -> 0 | G13: =Distribute!Q42 -> 0 | I13: =SUM(C13:G13) -> 0 | J13: =(I13/I$23)*100% -> 0 | L13: ='[2]AHTS-1'!FV42+'[2]AHTS-2'!FV42+'[2]AHTS-3'!FV42+'[2]AHTS-4'!FV42+'[2]AHTS-5'!FV42+'[2]AHTS-6'!FV42+'[2]AHTS-7'!FV42+'[2]AHTS-8'!FV42+'[3]CB-1'!FV42+'[3]CB-2'!FV42+'[3]CB-3'!FV42+'[3]CB-4'!FV42+'[3]CB-5'!FV42+'[3]CB-6'!FV42+'[3]CB-7'!FV42+'[3]CB-8'!FV42+'[3]CB-9'!FV42+'[3]CB-10'!FV42+'[3]CB-11'!FV42+'[3]CB-12'!FV42+'[3]CB-13'!FV42+'[3]CB-14'!FV42+'[3]CB-15'!FV42+'[3]CB-16'!FV42+'[3]CB-17'!FV42+'[3]CB-18'!FV42+'[3]CB-19'!FV42+'[3]CB-20'!FV42+'[3]CB-21'!FV42+'[3]CB-22'!FV42+'[3]CB-23'!FV42+'[3]CB-24'!FV42+'[4]LCT-1'!FV42+'[4]LCT-2'!FV42+'[4]LCT-3'!FV42+'[4]LCT-4'!FV42+'[4]LCT-5'!FV42+'[4]LCT-6'!FV42+'[4]LCT-7'!FV42+'[4]LCT-8'!FV42+'[5]TB-1'!FV42+'[5]TB-2'!FV42+'[5]TB-3'!FV42+'[5]TB-4'!FV42+'[5]TB-5'!FV42+'[5]TB-6'!FV42+'[5]TB-7'!FV42+'[5]TB-8'!FV42+'[5]TB-9'!FV42+'[5]TB-10'!FV42+'[6]DSV-1'!FV42+'[6]DSV-2'!FV42+'[6]DSV-3'!FV42+'[7]TUB-1'!FV42+'[7]TUB-2'!FV42+'[8]Barge-1'!FV42+'[8]Barge-2'!FV42+'[8]Barge-3'!FV42+'[8]Barge-4'!FV42 -> 0 | M13: =(L13/L$23)*100% -> 0 | AE13: =[1]Control!$GT$10 -> N: SLICKLINE (1) | AG13: =Distribute!BF42 -> 0 | AI13: =Distribute!BG42 -> 0 | AK13: =Distribute!BH42 -> 0 | AM13: =SUM(AG13:AK13) -> 0 | AN13: =(AM13/AM$23)*100% -> 0 | AP13: ='[2]AHTS-1'!FV42+'[2]AHTS-2'!FV42+'[2]AHTS-3'!FV42+'[2]AHTS-4'!FV42+'[2]AHTS-5'!FV42+'[2]AHTS-6'!FV42+'[2]AHTS-7'!FV42+'[2]AHTS-8'!FV42+'[3]CB-1'!FV42+'[3]CB-2'!FV42+'[3]CB-3'!FV42+'[3]CB-4'!FV42+'[3]CB-5'!FV42+'[3]CB-6'!FV42+'[3]CB-7'!FV42+'[3]CB-8'!FV42+'[3]CB-9'!FV42+'[3]CB-10'!FV42+'[3]CB-11'!FV42+'[3]CB-12'!FV42+'[3]CB-13'!FV42+'[3]CB-14'!FV42+'[3]CB-15'!FV42+'[3]CB-16'!FV42+'[3]CB-17'!FV42+'[3]CB-18'!FV42+'[3]CB-19'!FV42+'[3]CB-20'!FV42+'[3]CB-21'!FV42+'[3]CB-22'!FV42+'[3]CB-23'!FV42+'[3]CB-24'!FV42+'[4]LCT-1'!FV42+'[4]LCT-2'!FV42+'[4]LCT-3'!FV42+'[4]LCT-4'!FV42+'[4]LCT-5'!FV42+'[4]LCT-6'!FV42+'[4]LCT-7'!FV42+'[4]LCT-8'!FV42+'[5]TB-1'!FV42+'[5]TB-2'!FV42+'[5]TB-3'!FV42+'[5]TB-4'!FV42+'[5]TB-5'!FV42+'[5]TB-6'!FV42+'[5]TB-7'!FV42+'[5]TB-8'!FV42+'[5]TB-9'!FV42+'[5]TB-10'!FV42+'[6]DSV-1'!FV42+'[6]DSV-2'!FV42+'[6]DSV-3'!FV42+'[7]TUB-1'!FV42+'[7]TUB-2'!FV42+'[8]Barge-1'!FV42+'[8]Barge-2'!FV42+'[8]Barge-3'!FV42+'[8]Barge-4'!FV42 -> 0 | AQ13: =(AP13/AP$23)*100% -> 0
A14: =[1]Control!$GU$10 -> LAIN-LAIN | C14: =Distribute!R42 -> 7362.5152 | E14: =Distribute!S42 -> 4446.8616 | G14: =Distribute!T42 -> 0 | I14: =SUM(C14:G14) -> 11809.377 | J14: =(I14/I$23)*100% -> 0.032913182 | L14: ='[2]AHTS-1'!FW42+'[2]AHTS-2'!FW42+'[2]AHTS-3'!FW42+'[2]AHTS-4'!FW42+'[2]AHTS-5'!FW42+'[2]AHTS-6'!FW42+'[2]AHTS-7'!FW42+'[2]AHTS-8'!FW42+'[3]CB-1'!FW42+'[3]CB-2'!FW42+'[3]CB-3'!FW42+'[3]CB-4'!FW42+'[3]CB-5'!FW42+'[3]CB-6'!FW42+'[3]CB-7'!FW42+'[3]CB-8'!FW42+'[3]CB-9'!FW42+'[3]CB-10'!FW42+'[3]CB-11'!FW42+'[3]CB-12'!FW42+'[3]CB-13'!FW42+'[3]CB-14'!FW42+'[3]CB-15'!FW42+'[3]CB-16'!FW42+'[3]CB-17'!FW42+'[3]CB-18'!FW42+'[3]CB-19'!FW42+'[3]CB-20'!FW42+'[3]CB-21'!FW42+'[3]CB-22'!FW42+'[3]CB-23'!FW42+'[3]CB-24'!FW42+'[4]LCT-1'!FW42+'[4]LCT-2'!FW42+'[4]LCT-3'!FW42+'[4]LCT-4'!FW42+'[4]LCT-5'!FW42+'[4]LCT-6'!FW42+'[4]LCT-7'!FW42+'[4]LCT-8'!FW42+'[5]TB-1'!FW42+'[5]TB-2'!FW42+'[5]TB-3'!FW42+'[5]TB-4'!FW42+'[5]TB-5'!FW42+'[5]TB-6'!FW42+'[5]TB-7'!FW42+'[5]TB-8'!FW42+'[5]TB-9'!FW42+'[5]TB-10'!FW42+'[6]DSV-1'!FW42+'[6]DSV-2'!FW42+'[6]DSV-3'!FW42+'[7]TUB-1'!FW42+'[7]TUB-2'!FW42+'[8]Barge-1'!FW42+'[8]Barge-2'!FW42+'[8]Barge-3'!FW42+'[8]Barge-4'!FW42 -> 56 | M14: =(L14/L$23)*100% -> 0.020149683 | AE14: =[1]Control!$GU$10 -> LAIN-LAIN | AG14: =Distribute!BI42 -> 115068750 | AI14: =Distribute!BJ42 -> 69500000 | AK14: =Distribute!BK42 -> 0 | AM14: =SUM(AG14:AK14) -> 184568750 | AN14: =(AM14/AM$23)*100% -> 0.0326546 | AP14: ='[2]AHTS-1'!FW42+'[2]AHTS-2'!FW42+'[2]AHTS-3'!FW42+'[2]AHTS-4'!FW42+'[2]AHTS-5'!FW42+'[2]AHTS-6'!FW42+'[2]AHTS-7'!FW42+'[2]AHTS-8'!FW42+'[3]CB-1'!FW42+'[3]CB-2'!FW42+'[3]CB-3'!FW42+'[3]CB-4'!FW42+'[3]CB-5'!FW42+'[3]CB-6'!FW42+'[3]CB-7'!FW42+'[3]CB-8'!FW42+'[3]CB-9'!FW42+'[3]CB-10'!FW42+'[3]CB-11'!FW42+'[3]CB-12'!FW42+'[3]CB-13'!FW42+'[3]CB-14'!FW42+'[3]CB-15'!FW42+'[3]CB-16'!FW42+'[3]CB-17'!FW42+'[3]CB-18'!FW42+'[3]CB-19'!FW42+'[3]CB-20'!FW42+'[3]CB-21'!FW42+'[3]CB-22'!FW42+'[3]CB-23'!FW42+'[3]CB-24'!FW42+'[4]LCT-1'!FW42+'[4]LCT-2'!FW42+'[4]LCT-3'!FW42+'[4]LCT-4'!FW42+'[4]LCT-5'!FW42+'[4]LCT-6'!FW42+'[4]LCT-7'!FW42+'[4]LCT-8'!FW42+'[5]TB-1'!FW42+'[5]TB-2'!FW42+'[5]TB-3'!FW42+'[5]TB-4'!FW42+'[5]TB-5'!FW42+'[5]TB-6'!FW42+'[5]TB-7'!FW42+'[5]TB-8'!FW42+'[5]TB-9'!FW42+'[5]TB-10'!FW42+'[6]DSV-1'!FW42+'[6]DSV-2'!FW42+'[6]DSV-3'!FW42+'[7]TUB-1'!FW42+'[7]TUB-2'!FW42+'[8]Barge-1'!FW42+'[8]Barge-2'!FW42+'[8]Barge-3'!FW42+'[8]Barge-4'!FW42 -> 56 | AQ14: =(AP14/AP$23)*100% -> 0.020149683
A15: =[1]Control!$GV$10 -> SOIL BORING | C15: =Distribute!U42 -> 0 | E15: =Distribute!V42 -> 0 | G15: =Distribute!W42 -> 0 | I15: =SUM(C15:G15) -> 0 | J15: =(I15/I$23)*100% -> 0 | L15: ='[2]AHTS-1'!FX42+'[2]AHTS-2'!FX42+'[2]AHTS-3'!FX42+'[2]AHTS-4'!FX42+'[2]AHTS-5'!FX42+'[2]AHTS-6'!FX42+'[2]AHTS-7'!FX42+'[2]AHTS-8'!FX42+'[3]CB-1'!FX42+'[3]CB-2'!FX42+'[3]CB-3'!FX42+'[3]CB-4'!FX42+'[3]CB-5'!FX42+'[3]CB-6'!FX42+'[3]CB-7'!FX42+'[3]CB-8'!FX42+'[3]CB-9'!FX42+'[3]CB-10'!FX42+'[3]CB-11'!FX42+'[3]CB-12'!FX42+'[3]CB-13'!FX42+'[3]CB-14'!FX42+'[3]CB-15'!FX42+'[3]CB-16'!FX42+'[3]CB-17'!FX42+'[3]CB-18'!FX42+'[3]CB-19'!FX42+'[3]CB-20'!FX42+'[3]CB-21'!FX42+'[3]CB-22'!FX42+'[3]CB-23'!FX42+'[3]CB-24'!FX42+'[4]LCT-1'!FX42+'[4]LCT-2'!FX42+'[4]LCT-3'!FX42+'[4]LCT-4'!FX42+'[4]LCT-5'!FX42+'[4]LCT-6'!FX42+'[4]LCT-7'!FX42+'[4]LCT-8'!FX42+'[5]TB-1'!FX42+'[5]TB-2'!FX42+'[5]TB-3'!FX42+'[5]TB-4'!FX42+'[5]TB-5'!FX42+'[5]TB-6'!FX42+'[5]TB-7'!FX42+'[5]TB-8'!FX42+'[5]TB-9'!FX42+'[5]TB-10'!FX42+'[6]DSV-1'!FX42+'[6]DSV-2'!FX42+'[6]DSV-3'!FX42+'[7]TUB-1'!FX42+'[7]TUB-2'!FX42+'[8]Barge-1'!FX42+'[8]Barge-2'!FX42+'[8]Barge-3'!FX42+'[8]Barge-4'!FX42 -> 0 | M15: =(L15/L$23)*100% -> 0 | AE15: =[1]Control!$GV$10 -> SOIL BORING | AG15: =Distribute!BL42 -> 0 | AI15: =Distribute!BM42 -> 0 | AK15: =Distribute!BN42 -> 0 | AM15: =SUM(AG15:AK15) -> 0 | AN15: =(AM15/AM$23)*100% -> 0 | AP15: ='[2]AHTS-1'!FX42+'[2]AHTS-2'!FX42+'[2]AHTS-3'!FX42+'[2]AHTS-4'!FX42+'[2]AHTS-5'!FX42+'[2]AHTS-6'!FX42+'[2]AHTS-7'!FX42+'[2]AHTS-8'!FX42+'[3]CB-1'!FX42+'[3]CB-2'!FX42+'[3]CB-3'!FX42+'[3]CB-4'!FX42+'[3]CB-5'!FX42+'[3]CB-6'!FX42+'[3]CB-7'!FX42+'[3]CB-8'!FX42+'[3]CB-9'!FX42+'[3]CB-10'!FX42+'[3]CB-11'!FX42+'[3]CB-12'!FX42+'[3]CB-13'!FX42+'[3]CB-14'!FX42+'[3]CB-15'!FX42+'[3]CB-16'!FX42+'[3]CB-17'!FX42+'[3]CB-18'!FX42+'[3]CB-19'!FX42+'[3]CB-20'!FX42+'[3]CB-21'!FX42+'[3]CB-22'!FX42+'[3]CB-23'!FX42+'[3]CB-24'!FX42+'[4]LCT-1'!FX42+'[4]LCT-2'!FX42+'[4]LCT-3'!FX42+'[4]LCT-4'!FX42+'[4]LCT-5'!FX42+'[4]LCT-6'!FX42+'[4]LCT-7'!FX42+'[4]LCT-8'!FX42+'[5]TB-1'!FX42+'[5]TB-2'!FX42+'[5]TB-3'!FX42+'[5]TB-4'!FX42+'[5]TB-5'!FX42+'[5]TB-6'!FX42+'[5]TB-7'!FX42+'[5]TB-8'!FX42+'[5]TB-9'!FX42+'[5]TB-10'!FX42+'[6]DSV-1'!FX42+'[6]DSV-2'!FX42+'[6]DSV-3'!FX42+'[7]TUB-1'!FX42+'[7]TUB-2'!FX42+'[8]Barge-1'!FX42+'[8]Barge-2'!FX42+'[8]Barge-3'!FX42+'[8]Barge-4'!FX42 -> 0 | AQ15: =(AP15/AP$23)*100% -> 0
A16: =[1]Control!$GW$10 -> N: SLICKLINE (2) | C16: =Distribute!X42 -> 23722.988 | E16: =Distribute!Y42 -> 22613.391 | G16: =Distribute!Z42 -> 0 | I16: =SUM(C16:G16) -> 46336.379 | J16: =(I16/I$23)*100% -> 0.12914125 | L16: ='[2]AHTS-1'!FY42+'[2]AHTS-2'!FY42+'[2]AHTS-3'!FY42+'[2]AHTS-4'!FY42+'[2]AHTS-5'!FY42+'[2]AHTS-6'!FY42+'[2]AHTS-7'!FY42+'[2]AHTS-8'!FY42+'[3]CB-1'!FY42+'[3]CB-2'!FY42+'[3]CB-3'!FY42+'[3]CB-4'!FY42+'[3]CB-5'!FY42+'[3]CB-6'!FY42+'[3]CB-7'!FY42+'[3]CB-8'!FY42+'[3]CB-9'!FY42+'[3]CB-10'!FY42+'[3]CB-11'!FY42+'[3]CB-12'!FY42+'[3]CB-13'!FY42+'[3]CB-14'!FY42+'[3]CB-15'!FY42+'[3]CB-16'!FY42+'[3]CB-17'!FY42+'[3]CB-18'!FY42+'[3]CB-19'!FY42+'[3]CB-20'!FY42+'[3]CB-21'!FY42+'[3]CB-22'!FY42+'[3]CB-23'!FY42+'[3]CB-24'!FY42+'[4]LCT-1'!FY42+'[4]LCT-2'!FY42+'[4]LCT-3'!FY42+'[4]LCT-4'!FY42+'[4]LCT-5'!FY42+'[4]LCT-6'!FY42+'[4]LCT-7'!FY42+'[4]LCT-8'!FY42+'[5]TB-1'!FY42+'[5]TB-2'!FY42+'[5]TB-3'!FY42+'[5]TB-4'!FY42+'[5]TB-5'!FY42+'[5]TB-6'!FY42+'[5]TB-7'!FY42+'[5]TB-8'!FY42+'[5]TB-9'!FY42+'[5]TB-10'!FY42+'[6]DSV-1'!FY42+'[6]DSV-2'!FY42+'[6]DSV-3'!FY42+'[7]TUB-1'!FY42+'[7]TUB-2'!FY42+'[8]Barge-1'!FY42+'[8]Barge-2'!FY42+'[8]Barge-3'!FY42+'[8]Barge-4'!FY42 -> 317.26667 | M16: =(L16/L$23)*100% -> 0.11415755 | AE16: =[1]Control!$GW$10 -> N: SLICKLINE (2) | AG16: =Distribute!BO42 -> 3.7408747e+08 | AI16: =Distribute!BP42 -> 3.56645e+08 | AK16: =Distribute!BQ42 -> 0 | AM16: =SUM(AG16:AK16) -> 7.3073247e+08 | AN16: =(AM16/AM$23)*100% -> 0.12928395 | AP16: ='[2]AHTS-1'!FY42+'[2]AHTS-2'!FY42+'[2]AHTS-3'!FY42+'[2]AHTS-4'!FY42+'[2]AHTS-5'!FY42+'[2]AHTS-6'!FY42+'[2]AHTS-7'!FY42+'[2]AHTS-8'!FY42+'[3]CB-1'!FY42+'[3]CB-2'!FY42+'[3]CB-3'!FY42+'[3]CB-4'!FY42+'[3]CB-5'!FY42+'[3]CB-6'!FY42+'[3]CB-7'!FY42+'[3]CB-8'!FY42+'[3]CB-9'!FY42+'[3]CB-10'!FY42+'[3]CB-11'!FY42+'[3]CB-12'!FY42+'[3]CB-13'!FY42+'[3]CB-14'!FY42+'[3]CB-15'!FY42+'[3]CB-16'!FY42+'[3]CB-17'!FY42+'[3]CB-18'!FY42+'[3]CB-19'!FY42+'[3]CB-20'!FY42+'[3]CB-21'!FY42+'[3]CB-22'!FY42+'[3]CB-23'!FY42+'[3]CB-24'!FY42+'[4]LCT-1'!FY42+'[4]LCT-2'!FY42+'[4]LCT-3'!FY42+'[4]LCT-4'!FY42+'[4]LCT-5'!FY42+'[4]LCT-6'!FY42+'[4]LCT-7'!FY42+'[4]LCT-8'!FY42+'[5]TB-1'!FY42+'[5]TB-2'!FY42+'[5]TB-3'!FY42+'[5]TB-4'!FY42+'[5]TB-5'!FY42+'[5]TB-6'!FY42+'[5]TB-7'!FY42+'[5]TB-8'!FY42+'[5]TB-9'!FY42+'[5]TB-10'!FY42+'[6]DSV-1'!FY42+'[6]DSV-2'!FY42+'[6]DSV-3'!FY42+'[7]TUB-1'!FY42+'[7]TUB-2'!FY42+'[8]Barge-1'!FY42+'[8]Barge-2'!FY42+'[8]Barge-3'!FY42+'[8]Barge-4'!FY42 -> 317.26667 | AQ16: =(AP16/AP$23)*100% -> 0.11415755
A17: =[1]Control!$GX$10 -> DEBRIS SURVEY | C17: =Distribute!AA42 -> 0 | E17: =Distribute!AB42 -> 0 | G17: =Distribute!AC42 -> 0 | I17: =SUM(C17:G17) -> 0 | J17: =(I17/I$23)*100% -> 0 | L17: ='[2]AHTS-1'!FZ42+'[2]AHTS-2'!FZ42+'[2]AHTS-3'!FZ42+'[2]AHTS-4'!FZ42+'[2]AHTS-5'!FZ42+'[2]AHTS-6'!FZ42+'[2]AHTS-7'!FZ42+'[2]AHTS-8'!FZ42+'[3]CB-1'!FZ42+'[3]CB-2'!FZ42+'[3]CB-3'!FZ42+'[3]CB-4'!FZ42+'[3]CB-5'!FZ42+'[3]CB-6'!FZ42+'[3]CB-7'!FZ42+'[3]CB-8'!FZ42+'[3]CB-9'!FZ42+'[3]CB-10'!FZ42+'[3]CB-11'!FZ42+'[3]CB-12'!FZ42+'[3]CB-13'!FZ42+'[3]CB-14'!FZ42+'[3]CB-15'!FZ42+'[3]CB-16'!FZ42+'[3]CB-17'!FZ42+'[3]CB-18'!FZ42+'[3]CB-19'!FZ42+'[3]CB-20'!FZ42+'[3]CB-21'!FZ42+'[3]CB-22'!FZ42+'[3]CB-23'!FZ42+'[3]CB-24'!FZ42+'[4]LCT-1'!FZ42+'[4]LCT-2'!FZ42+'[4]LCT-3'!FZ42+'[4]LCT-4'!FZ42+'[4]LCT-5'!FZ42+'[4]LCT-6'!FZ42+'[4]LCT-7'!FZ42+'[4]LCT-8'!FZ42+'[5]TB-1'!FZ42+'[5]TB-2'!FZ42+'[5]TB-3'!FZ42+'[5]TB-4'!FZ42+'[5]TB-5'!FZ42+'[5]TB-6'!FZ42+'[5]TB-7'!FZ42+'[5]TB-8'!FZ42+'[5]TB-9'!FZ42+'[5]TB-10'!FZ42+'[6]DSV-1'!FZ42+'[6]DSV-2'!FZ42+'[6]DSV-3'!FZ42+'[7]TUB-1'!FZ42+'[7]TUB-2'!FZ42+'[8]Barge-1'!FZ42+'[8]Barge-2'!FZ42+'[8]Barge-3'!FZ42+'[8]Barge-4'!FZ42 -> 0 | M17: =(L17/L$23)*100% -> 0 | AE17: =[1]Control!$GX$10 -> DEBRIS SURVEY | AG17: =Distribute!BR42 -> 0 | AI17: =Distribute!BS42 -> 0 | AK17: =Distribute!BT42 -> 0 | AM17: =SUM(AG17:AK17) -> 0 | AN17: =(AM17/AM$23)*100% -> 0 | AP17: ='[2]AHTS-1'!FZ42+'[2]AHTS-2'!FZ42+'[2]AHTS-3'!FZ42+'[2]AHTS-4'!FZ42+'[2]AHTS-5'!FZ42+'[2]AHTS-6'!FZ42+'[2]AHTS-7'!FZ42+'[2]AHTS-8'!FZ42+'[3]CB-1'!FZ42+'[3]CB-2'!FZ42+'[3]CB-3'!FZ42+'[3]CB-4'!FZ42+'[3]CB-5'!FZ42+'[3]CB-6'!FZ42+'[3]CB-7'!FZ42+'[3]CB-8'!FZ42+'[3]CB-9'!FZ42+'[3]CB-10'!FZ42+'[3]CB-11'!FZ42+'[3]CB-12'!FZ42+'[3]CB-13'!FZ42+'[3]CB-14'!FZ42+'[3]CB-15'!FZ42+'[3]CB-16'!FZ42+'[3]CB-17'!FZ42+'[3]CB-18'!FZ42+'[3]CB-19'!FZ42+'[3]CB-20'!FZ42+'[3]CB-21'!FZ42+'[3]CB-22'!FZ42+'[3]CB-23'!FZ42+'[3]CB-24'!FZ42+'[4]LCT-1'!FZ42+'[4]LCT-2'!FZ42+'[4]LCT-3'!FZ42+'[4]LCT-4'!FZ42+'[4]LCT-5'!FZ42+'[4]LCT-6'!FZ42+'[4]LCT-7'!FZ42+'[4]LCT-8'!FZ42+'[5]TB-1'!FZ42+'[5]TB-2'!FZ42+'[5]TB-3'!FZ42+'[5]TB-4'!FZ42+'[5]TB-5'!FZ42+'[5]TB-6'!FZ42+'[5]TB-7'!FZ42+'[5]TB-8'!FZ42+'[5]TB-9'!FZ42+'[5]TB-10'!FZ42+'[6]DSV-1'!FZ42+'[6]DSV-2'!FZ42+'[6]DSV-3'!FZ42+'[7]TUB-1'!FZ42+'[7]TUB-2'!FZ42+'[8]Barge-1'!FZ42+'[8]Barge-2'!FZ42+'[8]Barge-3'!FZ42+'[8]Barge-4'!FZ42 -> 0 | AQ17: =(AP17/AP$23)*100% -> 0
A18: =[1]Control!$GY$10 -> STORK (WLI) | C18: =Distribute!AD42 -> 0 | E18: =Distribute!AE42 -> 0 | G18: =Distribute!AF42 -> 0 | I18: =SUM(C18:G18) -> 0 | J18: =(I18/I$23)*100% -> 0 | L18: ='[2]AHTS-1'!GA42+'[2]AHTS-2'!GA42+'[2]AHTS-3'!GA42+'[2]AHTS-4'!GA42+'[2]AHTS-5'!GA42+'[2]AHTS-6'!GA42+'[2]AHTS-7'!GA42+'[2]AHTS-8'!GA42+'[3]CB-1'!GA42+'[3]CB-2'!GA42+'[3]CB-3'!GA42+'[3]CB-4'!GA42+'[3]CB-5'!GA42+'[3]CB-6'!GA42+'[3]CB-7'!GA42+'[3]CB-8'!GA42+'[3]CB-9'!GA42+'[3]CB-10'!GA42+'[3]CB-11'!GA42+'[3]CB-12'!GA42+'[3]CB-13'!GA42+'[3]CB-14'!GA42+'[3]CB-15'!GA42+'[3]CB-16'!GA42+'[3]CB-17'!GA42+'[3]CB-18'!GA42+'[3]CB-19'!GA42+'[3]CB-20'!GA42+'[3]CB-21'!GA42+'[3]CB-22'!GA42+'[3]CB-23'!GA42+'[3]CB-24'!GA42+'[4]LCT-1'!GA42+'[4]LCT-2'!GA42+'[4]LCT-3'!GA42+'[4]LCT-4'!GA42+'[4]LCT-5'!GA42+'[4]LCT-6'!GA42+'[4]LCT-7'!GA42+'[4]LCT-8'!GA42+'[5]TB-1'!GA42+'[5]TB-2'!GA42+'[5]TB-3'!GA42+'[5]TB-4'!GA42+'[5]TB-5'!GA42+'[5]TB-6'!GA42+'[5]TB-7'!GA42+'[5]TB-8'!GA42+'[5]TB-9'!GA42+'[5]TB-10'!GA42+'[6]DSV-1'!GA42+'[6]DSV-2'!GA42+'[6]DSV-3'!GA42+'[7]TUB-1'!GA42+'[7]TUB-2'!GA42+'[8]Barge-1'!GA42+'[8]Barge-2'!GA42+'[8]Barge-3'!GA42+'[8]Barge-4'!GA42 -> 0 | M18: =(L18/L$23)*100% -> 0 | AE18: =[1]Control!$GY$10 -> STORK (WLI) | AG18: =Distribute!BU42 -> 0 | AI18: =Distribute!BV42 -> 0 | AK18: =Distribute!BW42 -> 0 | AM18: =SUM(AG18:AK18) -> 0 | AN18: =(AM18/AM$23)*100% -> 0 | AP18: ='[2]AHTS-1'!GA42+'[2]AHTS-2'!GA42+'[2]AHTS-3'!GA42+'[2]AHTS-4'!GA42+'[2]AHTS-5'!GA42+'[2]AHTS-6'!GA42+'[2]AHTS-7'!GA42+'[2]AHTS-8'!GA42+'[3]CB-1'!GA42+'[3]CB-2'!GA42+'[3]CB-3'!GA42+'[3]CB-4'!GA42+'[3]CB-5'!GA42+'[3]CB-6'!GA42+'[3]CB-7'!GA42+'[3]CB-8'!GA42+'[3]CB-9'!GA42+'[3]CB-10'!GA42+'[3]CB-11'!GA42+'[3]CB-12'!GA42+'[3]CB-13'!GA42+'[3]CB-14'!GA42+'[3]CB-15'!GA42+'[3]CB-16'!GA42+'[3]CB-17'!GA42+'[3]CB-18'!GA42+'[3]CB-19'!GA42+'[3]CB-20'!GA42+'[3]CB-21'!GA42+'[3]CB-22'!GA42+'[3]CB-23'!GA42+'[3]CB-24'!GA42+'[4]LCT-1'!GA42+'[4]LCT-2'!GA42+'[4]LCT-3'!GA42+'[4]LCT-4'!GA42+'[4]LCT-5'!GA42+'[4]LCT-6'!GA42+'[4]LCT-7'!GA42+'[4]LCT-8'!GA42+'[5]TB-1'!GA42+'[5]TB-2'!GA42+'[5]TB-3'!GA42+'[5]TB-4'!GA42+'[5]TB-5'!GA42+'[5]TB-6'!GA42+'[5]TB-7'!GA42+'[5]TB-8'!GA42+'[5]TB-9'!GA42+'[5]TB-10'!GA42+'[6]DSV-1'!GA42+'[6]DSV-2'!GA42+'[6]DSV-3'!GA42+'[7]TUB-1'!GA42+'[7]TUB-2'!GA42+'[8]Barge-1'!GA42+'[8]Barge-2'!GA42+'[8]Barge-3'!GA42+'[8]Barge-4'!GA42 -> 0 | AQ18: =(AP18/AP$23)*100% -> 0
A19: =[1]Control!$GZ$10 -> - | C19: =Distribute!AG42 -> 0 | E19: =Distribute!AH42 -> 0 | G19: =Distribute!AI42 -> 0 | I19: =SUM(C19:G19) -> 0 | J19: =(I19/I$23)*100% -> 0 | L19: ='[2]AHTS-1'!GB42+'[2]AHTS-2'!GB42+'[2]AHTS-3'!GB42+'[2]AHTS-4'!GB42+'[2]AHTS-5'!GB42+'[2]AHTS-6'!GB42+'[2]AHTS-7'!GB42+'[2]AHTS-8'!GB42+'[3]CB-1'!GB42+'[3]CB-2'!GB42+'[3]CB-3'!GB42+'[3]CB-4'!GB42+'[3]CB-5'!GB42+'[3]CB-6'!GB42+'[3]CB-7'!GB42+'[3]CB-8'!GB42+'[3]CB-9'!GB42+'[3]CB-10'!GB42+'[3]CB-11'!GB42+'[3]CB-12'!GB42+'[3]CB-13'!GB42+'[3]CB-14'!GB42+'[3]CB-15'!GB42+'[3]CB-16'!GB42+'[3]CB-17'!GB42+'[3]CB-18'!GB42+'[3]CB-19'!GB42+'[3]CB-20'!GB42+'[3]CB-21'!GB42+'[3]CB-22'!GB42+'[3]CB-23'!GB42+'[3]CB-24'!GB42+'[4]LCT-1'!GB42+'[4]LCT-2'!GB42+'[4]LCT-3'!GB42+'[4]LCT-4'!GB42+'[4]LCT-5'!GB42+'[4]LCT-6'!GB42+'[4]LCT-7'!GB42+'[4]LCT-8'!GB42+'[5]TB-1'!GB42+'[5]TB-2'!GB42+'[5]TB-3'!GB42+'[5]TB-4'!GB42+'[5]TB-5'!GB42+'[5]TB-6'!GB42+'[5]TB-7'!GB42+'[5]TB-8'!GB42+'[5]TB-9'!GB42+'[5]TB-10'!GB42+'[6]DSV-1'!GB42+'[6]DSV-2'!GB42+'[6]DSV-3'!GB42+'[7]TUB-1'!GB42+'[7]TUB-2'!GB42+'[8]Barge-1'!GB42+'[8]Barge-2'!GB42+'[8]Barge-3'!GB42+'[8]Barge-4'!GB42 -> 0 | M19: =(L19/L$23)*100% -> 0 | AE19: =[1]Control!$GZ$10 -> - | AG19: =Distribute!BX42 -> 0 | AI19: =Distribute!BY42 -> 0 | AK19: =Distribute!BZ42 -> 0 | AM19: =SUM(AG19:AK19) -> 0 | AN19: =(AM19/AM$23)*100% -> 0 | AP19: ='[2]AHTS-1'!GB42+'[2]AHTS-2'!GB42+'[2]AHTS-3'!GB42+'[2]AHTS-4'!GB42+'[2]AHTS-5'!GB42+'[2]AHTS-6'!GB42+'[2]AHTS-7'!GB42+'[2]AHTS-8'!GB42+'[3]CB-1'!GB42+'[3]CB-2'!GB42+'[3]CB-3'!GB42+'[3]CB-4'!GB42+'[3]CB-5'!GB42+'[3]CB-6'!GB42+'[3]CB-7'!GB42+'[3]CB-8'!GB42+'[3]CB-9'!GB42+'[3]CB-10'!GB42+'[3]CB-11'!GB42+'[3]CB-12'!GB42+'[3]CB-13'!GB42+'[3]CB-14'!GB42+'[3]CB-15'!GB42+'[3]CB-16'!GB42+'[3]CB-17'!GB42+'[3]CB-18'!GB42+'[3]CB-19'!GB42+'[3]CB-20'!GB42+'[3]CB-21'!GB42+'[3]CB-22'!GB42+'[3]CB-23'!GB42+'[3]CB-24'!GB42+'[4]LCT-1'!GB42+'[4]LCT-2'!GB42+'[4]LCT-3'!GB42+'[4]LCT-4'!GB42+'[4]LCT-5'!GB42+'[4]LCT-6'!GB42+'[4]LCT-7'!GB42+'[4]LCT-8'!GB42+'[5]TB-1'!GB42+'[5]TB-2'!GB42+'[5]TB-3'!GB42+'[5]TB-4'!GB42+'[5]TB-5'!GB42+'[5]TB-6'!GB42+'[5]TB-7'!GB42+'[5]TB-8'!GB42+'[5]TB-9'!GB42+'[5]TB-10'!GB42+'[6]DSV-1'!GB42+'[6]DSV-2'!GB42+'[6]DSV-3'!GB42+'[7]TUB-1'!GB42+'[7]TUB-2'!GB42+'[8]Barge-1'!GB42+'[8]Barge-2'!GB42+'[8]Barge-3'!GB42+'[8]Barge-4'!GB42 -> 0 | AQ19: =(AP19/AP$23)*100% -> 0
A20: =[1]Control!$HA$10 -> - | C20: =Distribute!AJ42 -> 0 | E20: =Distribute!AK42 -> 0 | G20: =Distribute!AL42 -> 0 | I20: =SUM(C20:G20) -> 0 | J20: =(I20/I$23)*100% -> 0 | L20: ='[2]AHTS-1'!GC42+'[2]AHTS-2'!GC42+'[2]AHTS-3'!GC42+'[2]AHTS-4'!GC42+'[2]AHTS-5'!GC42+'[2]AHTS-6'!GC42+'[2]AHTS-7'!GC42+'[2]AHTS-8'!GC42+'[3]CB-1'!GC42+'[3]CB-2'!GC42+'[3]CB-3'!GC42+'[3]CB-4'!GC42+'[3]CB-5'!GC42+'[3]CB-6'!GC42+'[3]CB-7'!GC42+'[3]CB-8'!GC42+'[3]CB-9'!GC42+'[3]CB-10'!GC42+'[3]CB-11'!GC42+'[3]CB-12'!GC42+'[3]CB-13'!GC42+'[3]CB-14'!GC42+'[3]CB-15'!GC42+'[3]CB-16'!GC42+'[3]CB-17'!GC42+'[3]CB-18'!GC42+'[3]CB-19'!GC42+'[3]CB-20'!GC42+'[3]CB-21'!GC42+'[3]CB-22'!GC42+'[3]CB-23'!GC42+'[3]CB-24'!GC42+'[4]LCT-1'!GC42+'[4]LCT-2'!GC42+'[4]LCT-3'!GC42+'[4]LCT-4'!GC42+'[4]LCT-5'!GC42+'[4]LCT-6'!GC42+'[4]LCT-7'!GC42+'[4]LCT-8'!GC42+'[5]TB-1'!GC42+'[5]TB-2'!GC42+'[5]TB-3'!GC42+'[5]TB-4'!GC42+'[5]TB-5'!GC42+'[5]TB-6'!GC42+'[5]TB-7'!GC42+'[5]TB-8'!GC42+'[5]TB-9'!GC42+'[5]TB-10'!GC42+'[6]DSV-1'!GC42+'[6]DSV-2'!GC42+'[6]DSV-3'!GC42+'[7]TUB-1'!GC42+'[7]TUB-2'!GC42+'[8]Barge-1'!GC42+'[8]Barge-2'!GC42+'[8]Barge-3'!GC42+'[8]Barge-4'!GC42 -> 0 | M20: =(L20/L$23)*100% -> 0 | AE20: =[1]Control!$HA$10 -> - | AG20: =Distribute!CA42 -> 0 | AI20: =Distribute!CB42 -> 0 | AK20: =Distribute!CC42 -> 0 | AM20: =SUM(AG20:AK20) -> 0 | AN20: =(AM20/AM$23)*100% -> 0 | AP20: ='[2]AHTS-1'!GC42+'[2]AHTS-2'!GC42+'[2]AHTS-3'!GC42+'[2]AHTS-4'!GC42+'[2]AHTS-5'!GC42+'[2]AHTS-6'!GC42+'[2]AHTS-7'!GC42+'[2]AHTS-8'!GC42+'[3]CB-1'!GC42+'[3]CB-2'!GC42+'[3]CB-3'!GC42+'[3]CB-4'!GC42+'[3]CB-5'!GC42+'[3]CB-6'!GC42+'[3]CB-7'!GC42+'[3]CB-8'!GC42+'[3]CB-9'!GC42+'[3]CB-10'!GC42+'[3]CB-11'!GC42+'[3]CB-12'!GC42+'[3]CB-13'!GC42+'[3]CB-14'!GC42+'[3]CB-15'!GC42+'[3]CB-16'!GC42+'[3]CB-17'!GC42+'[3]CB-18'!GC42+'[3]CB-19'!GC42+'[3]CB-20'!GC42+'[3]CB-21'!GC42+'[3]CB-22'!GC42+'[3]CB-23'!GC42+'[3]CB-24'!GC42+'[4]LCT-1'!GC42+'[4]LCT-2'!GC42+'[4]LCT-3'!GC42+'[4]LCT-4'!GC42+'[4]LCT-5'!GC42+'[4]LCT-6'!GC42+'[4]LCT-7'!GC42+'[4]LCT-8'!GC42+'[5]TB-1'!GC42+'[5]TB-2'!GC42+'[5]TB-3'!GC42+'[5]TB-4'!GC42+'[5]TB-5'!GC42+'[5]TB-6'!GC42+'[5]TB-7'!GC42+'[5]TB-8'!GC42+'[5]TB-9'!GC42+'[5]TB-10'!GC42+'[6]DSV-1'!GC42+'[6]DSV-2'!GC42+'[6]DSV-3'!GC42+'[7]TUB-1'!GC42+'[7]TUB-2'!GC42+'[8]Barge-1'!GC42+'[8]Barge-2'!GC42+'[8]Barge-3'!GC42+'[8]Barge-4'!GC42 -> 0 | AQ20: =(AP20/AP$23)*100% -> 0
A21: =[1]Control!$HB$10 -> - | C21: =Distribute!AM42 -> 0 | E21: =Distribute!AN42 -> 0 | G21: =Distribute!AO42 -> 0 | I21: =SUM(C21:G21) -> 0 | J21: =(I21/I$23)*100% -> 0 | L21: ='[2]AHTS-1'!GD42+'[2]AHTS-2'!GD42+'[2]AHTS-3'!GD42+'[2]AHTS-4'!GD42+'[2]AHTS-5'!GD42+'[2]AHTS-6'!GD42+'[2]AHTS-7'!GD42+'[2]AHTS-8'!GD42+'[3]CB-1'!GD42+'[3]CB-2'!GD42+'[3]CB-3'!GD42+'[3]CB-4'!GD42+'[3]CB-5'!GD42+'[3]CB-6'!GD42+'[3]CB-7'!GD42+'[3]CB-8'!GD42+'[3]CB-9'!GD42+'[3]CB-10'!GD42+'[3]CB-11'!GD42+'[3]CB-12'!GD42+'[3]CB-13'!GD42+'[3]CB-14'!GD42+'[3]CB-15'!GD42+'[3]CB-16'!GD42+'[3]CB-17'!GD42+'[3]CB-18'!GD42+'[3]CB-19'!GD42+'[3]CB-20'!GD42+'[3]CB-21'!GD42+'[3]CB-22'!GD42+'[3]CB-23'!GD42+'[3]CB-24'!GD42+'[4]LCT-1'!GD42+'[4]LCT-2'!GD42+'[4]LCT-3'!GD42+'[4]LCT-4'!GD42+'[4]LCT-5'!GD42+'[4]LCT-6'!GD42+'[4]LCT-7'!GD42+'[4]LCT-8'!GD42+'[5]TB-1'!GD42+'[5]TB-2'!GD42+'[5]TB-3'!GD42+'[5]TB-4'!GD42+'[5]TB-5'!GD42+'[5]TB-6'!GD42+'[5]TB-7'!GD42+'[5]TB-8'!GD42+'[5]TB-9'!GD42+'[5]TB-10'!GD42+'[6]DSV-1'!GD42+'[6]DSV-2'!GD42+'[6]DSV-3'!GD42+'[7]TUB-1'!GD42+'[7]TUB-2'!GD42+'[8]Barge-1'!GD42+'[8]Barge-2'!GD42+'[8]Barge-3'!GD42+'[8]Barge-4'!GD42 -> 0 | M21: =(L21/L$23)*100% -> 0 | AE21: =[1]Control!$HB$10 -> - | AG21: =Distribute!CD42 -> 0 | AI21: =Distribute!CE42 -> 0 | AK21: =Distribute!CF42 -> 0 | AM21: =SUM(AG21:AK21) -> 0 | AN21: =(AM21/AM$23)*100% -> 0 | AP21: ='[2]AHTS-1'!GD42+'[2]AHTS-2'!GD42+'[2]AHTS-3'!GD42+'[2]AHTS-4'!GD42+'[2]AHTS-5'!GD42+'[2]AHTS-6'!GD42+'[2]AHTS-7'!GD42+'[2]AHTS-8'!GD42+'[3]CB-1'!GD42+'[3]CB-2'!GD42+'[3]CB-3'!GD42+'[3]CB-4'!GD42+'[3]CB-5'!GD42+'[3]CB-6'!GD42+'[3]CB-7'!GD42+'[3]CB-8'!GD42+'[3]CB-9'!GD42+'[3]CB-10'!GD42+'[3]CB-11'!GD42+'[3]CB-12'!GD42+'[3]CB-13'!GD42+'[3]CB-14'!GD42+'[3]CB-15'!GD42+'[3]CB-16'!GD42+'[3]CB-17'!GD42+'[3]CB-18'!GD42+'[3]CB-19'!GD42+'[3]CB-20'!GD42+'[3]CB-21'!GD42+'[3]CB-22'!GD42+'[3]CB-23'!GD42+'[3]CB-24'!GD42+'[4]LCT-1'!GD42+'[4]LCT-2'!GD42+'[4]LCT-3'!GD42+'[4]LCT-4'!GD42+'[4]LCT-5'!GD42+'[4]LCT-6'!GD42+'[4]LCT-7'!GD42+'[4]LCT-8'!GD42+'[5]TB-1'!GD42+'[5]TB-2'!GD42+'[5]TB-3'!GD42+'[5]TB-4'!GD42+'[5]TB-5'!GD42+'[5]TB-6'!GD42+'[5]TB-7'!GD42+'[5]TB-8'!GD42+'[5]TB-9'!GD42+'[5]TB-10'!GD42+'[6]DSV-1'!GD42+'[6]DSV-2'!GD42+'[6]DSV-3'!GD42+'[7]TUB-1'!GD42+'[7]TUB-2'!GD42+'[8]Barge-1'!GD42+'[8]Barge-2'!GD42+'[8]Barge-3'!GD42+'[8]Barge-4'!GD42 -> 0 | AQ21: =(AP21/AP$23)*100% -> 0
A23: TOTAL COST | C23: =SUM(C9:C21) -> 183604.59 | E23: =SUM(E9:E21) -> 175199.27 | G23: =SUM(G9:G21) -> 0 | I23: =SUM(I9:I21) -> 358803.86 | J23: =SUM(J9:J21) -> 1 | L23: =SUM(L9:L21) -> 2779.2 | M23: =SUM(M9:M21) -> 1 | AE23: TOTAL COST | AG23: =SUM(AG9:AG21) -> 2.89149e+09 | AI23: =SUM(AI9:AI21) -> 2.7606617e+09 | AK23: =SUM(AK9:AK21) -> 0 | AM23: =SUM(AM9:AM21) -> 5.6521517e+09 | AN23: =SUM(AN9:AN21) -> 1 | AP23: =SUM(AP9:AP21) -> 2779.2 | AQ23: =SUM(AQ9:AQ21) -> 1
E27: Summary | I27: Daily Boat Cost Distribution to Rigs, WO Barges & Units | O27: D&C Boat Cost Analysis | AI27: Summary | AM27: Daily Boat Cost Distribution to Rigs, WO Barges & Units | AS27: D&C Boat Cost Analysis
A46: =L5 -> 25 Nov - 24 Dec 2025 | C46: Fuel (liter)
A47: =A9 -> RUN EXPLOSIVE | C47: =Distribute!C83 -> 0
A48: =A10 -> ASSET | C48: =Distribute!F83 -> 0
A49: =A11 -> TIRTA RAJAWALI | C49: =Distribute!I83 -> 125227.65
A50: =A12 -> S: SLICKLINE UNIT | C50: =Distribute!L83 -> 23523.667
A51: =A13 -> N: SLICKLINE (1) | C51: =Distribute!O83 -> 0
A52: =A14 -> LAIN-LAIN | C52: =Distribute!R83 -> 7125
A53: =A15 -> SOIL BORING | C53: =Distribute!U83 -> 0
A54: =A16 -> N: SLICKLINE (2) | C54: =Distribute!X83 -> 23163.311
A55: =A17 -> DEBRIS SURVEY | C55: =Distribute!AA83 -> 0
A56: =A18 -> STORK (WLI) | C56: =Distribute!AD83 -> 0
A57: =A19 -> - | C57: =Distribute!AG83 -> 0
A58: =A20 -> - | C58: =Distribute!AJ83 -> 0
A59: =A21 -> - | C59: =Distribute!AM83 -> 0
A61: TOTAL (liter) | C61: =SUM(C47:C60) -> 179039.63

Sheet Distribute
D8: 1 | G8: 2 | J8: 3 | M8: 4 | P8: 5 | S8: 6 | V8: 7 | Y8: 8 | AB8: 9 | AE8: 10 | AH8: 11 | AK8: 12 | AN8: 13 | AU8: 1 | AX8: 2 | BA8: 3 | BD8: 4 | BG8: 5 | BJ8: 6 | BM8: 7 | BP8: 8 | BS8: 9 | BV8: 10 | BY8: 11 | CB8: 12 | CE8: 13
C9: =[1]Control!GP10 -> RUN EXPLOSIVE | F9: =[1]Control!GQ10 -> ASSET | I9: =[1]Control!GR10 -> TIRTA RAJAWALI | L9: =[1]Control!GS10 -> S: SLICKLINE UNIT | O9: =[1]Control!GT10 -> N: SLICKLINE (1) | R9: =[1]Control!GU10 -> LAIN-LAIN | U9: =[1]Control!GV10 -> SOIL BORING | X9: =[1]Control!GW10 -> N: SLICKLINE (2) | AA9: =[1]Control!GX10 -> DEBRIS SURVEY | AD9: =[1]Control!GY10 -> STORK (WLI) | AG9: =[1]Control!GZ10 -> - | AJ9: =[1]Control!HA10 -> - | AM9: =[1]Control!HB10 -> - | AT9: =[1]Control!GP10 -> RUN EXPLOSIVE | AW9: =[1]Control!GQ10 -> ASSET | AZ9: =[1]Control!GR10 -> TIRTA RAJAWALI | BC9: =[1]Control!$GS$10 -> S: SLICKLINE UNIT | BF9: =[1]Control!$GT$10 -> N: SLICKLINE (1) | BI9: =[1]Control!$GU$10 -> LAIN-LAIN | BL9: =[1]Control!$GV$10 -> SOIL BORING | BO9: =[1]Control!$GW$10 -> N: SLICKLINE (2) | BR9: =[1]Control!$GX$10 -> DEBRIS SURVEY | BU9: =[1]Control!$GY$10 -> STORK (WLI) | BX9: =[1]Control!$GZ$10 -> - | CA9: =[1]Control!$HA$10 -> - | CD9: =[1]Control!$HB$10 -> -
A10: DATE | C10: FUEL | D10: DAYRATE | E10: MOB / DEMOB | F10: FUEL | G10: DAYRATE | H10: MOB / DEMOB | I10: FUEL | J10: DAYRATE | K10: MOB / DEMOB | L10: FUEL | M10: DAYRATE | N10: MOB / DEMOB | O10: FUEL | P10: DAYRATE | Q10: MOB / DEMOB | R10: FUEL | S10: DAYRATE | T10: MOB / DEMOB | U10: FUEL | V10: DAYRATE | W10: MOB / DEMOB | X10: FUEL | Y10: DAYRATE | Z10: MOB / DEMOB | AA10: FUEL | AB10: DAYRATE | AC10: MOB / DEMOB | AD10: FUEL | AE10: DAYRATE | AF10: MOB / DEMOB | AG10: FUEL | AH10: DAYRATE | AI10: MOB / DEMOB | AJ10: FUEL | AK10: DAYRATE | AL10: MOB / DEMOB | AM10: FUEL | AN10: DAYRATE | AO10: MOB / DEMOB | AR10: DATE | AT10: FUEL | AU10: DAYRATE | AV10: MOB / DEMOB | AW10: FUEL | AX10: DAYRATE | AY10: MOB / DEMOB | AZ10: FUEL | BA10: DAYRATE | BB10: MOB / DEMOB | BC10: FUEL | BD10: DAYRATE | BE10: MOB / DEMOB | BF10: FUEL | BG10: DAYRATE | BH10: MOB / DEMOB | BI10: FUEL | BJ10: DAYRATE | BK10: MOB / DEMOB | BL10: FUEL | BM10: DAYRATE | BN10: MOB / DEMOB | BO10: FUEL | BP10: DAYRATE | BQ10: MOB / DEMOB | BR10: FUEL | BS10: DAYRATE | BT10: MOB / DEMOB | BU10: FUEL | BV10: DAYRATE | BW10: MOB / DEMOB | BX10: FUEL | BY10: DAYRATE | BZ10: MOB / DEMOB | CA10: FUEL | CB10: DAYRATE | CC10: MOB / DEMOB | CD10: FUEL | CE10: DAYRATE | CF10: MOB / DEMOB
