Workbook
Name IDS: "Rectangle 3"

Sheet EnC
L5: =[1]Control!AU10 -> 25 Nov - 24 Dec 2025 | AE5: =[1]Control!AU10 -> 25 Nov - 24 Dec 2025
C7: FUEL COST | E7: CHARTER RATE | G7: MOB / DEMOB | I7: TOTAL COST | J7: PCT | L7: BOAT HOURS | M7: PCT | V7: FUEL COST | X7: CHARTER RATE | Z7: MOB / DEMOB | AB7: TOTAL COST | AC7: PCT | AE7: BOAT HOURS | AF7: PCT
L8: Logistics Cost Sharing | AE8: Logistics Cost Sharing
A9: SOUTH _OSF | C9: =Distribute!C42 -> 45728.79 | E9: =Distribute!D42 -> 25643.066 | G9: =Distribute!E42 -> 0 | I9: =SUM(C9,E9,G9) -> 71371.856 | J9: =(I9/I21)*100% -> 0.247323 | L9: ='[2]AHTS-1'!GE42+'[2]AHTS-2'!GE42+'[2]AHTS-3'!GE42+'[2]AHTS-4'!GE42+'[2]AHTS-5'!GE42+'[2]AHTS-6'!GE42+'[2]AHTS-7'!GE42+'[2]AHTS-8'!GE42+'[3]CB-1'!GE42+'[3]CB-2'!GE42+'[3]CB-3'!GE42+'[3]CB-4'!GE42+'[3]CB-5'!GE42+'[3]CB-6'!GE42+'[3]CB-7'!GE42+'[3]CB-8'!GE42+'[3]CB-9'!GE42+'[3]CB-10'!GE42+'[3]CB-11'!GE42+'[3]CB-12'!GE42+'[3]CB-13'!GE42+'[3]CB-14'!GE42+'[3]CB-15'!GE42+'[3]CB-16'!GE42+'[3]CB-17'!GE42+'[3]CB-18'!GE42+'[3]CB-19'!GE42+'[3]CB-20'!GE42+'[3]CB-21'!GE42+'[3]CB-22'!GE42+'[3]CB-23'!GE42+'[3]CB-24'!GE42+'[4]LCT-1'!GE42+'[4]LCT-2'!GE42+'[4]LCT-3'!GE42+'[4]LCT-4'!GE42+'[4]LCT-5'!GE42+'[4]LCT-6'!GE42+'[4]LCT-7'!GE42+'[4]LCT-8'!GE42+'[5]TB-1'!GE42+'[5]TB-2'!GE42+'[5]TB-3'!GE42+'[5]TB-4'!GE42+'[5]TB-5'!GE42+'[5]TB-6'!GE42+'[5]TB-7'!GE42+'[5]TB-8'!GE42+'[5]TB-9'!GE42+'[5]TB-10'!GE42+'[6]DSV-1'!GE42+'[6]DSV-2'!GE42+'[6]DSV-3'!GE42+'[7]TUB-1'!GE42+'[7]TUB-2'!GE42+'[8]Barge-1'!GE42+'[8]Barge-2'!GE42+'[8]Barge-3'!GE42+'[8]Barge-4'!GE42 -> 402 | M9: =(L9/L21)*100% -> 0.16175544 | T9: SOUTH_OSF | V9: =Distribute!W42 -> 725280350 | X9: =Distribute!X42 -> 407125000 | Z9: =Distribute!Y42 -> 0 | AB9: =SUM(V9,X9,Z9) -> 1132405350 | AC9: =(AB9/AB21)*100% -> 0.24880435 | AE9: ='[2]AHTS-1'!GE42+'[2]AHTS-2'!GE42+'[2]AHTS-3'!GE42+'[2]AHTS-4'!GE42+'[2]AHTS-5'!GE42+'[2]AHTS-6'!GE42+'[2]AHTS-7'!GE42+'[2]AHTS-8'!GE42+'[3]CB-1'!GE42+'[3]CB-2'!GE42+'[3]CB-3'!GE42+'[3]CB-4'!GE42+'[3]CB-5'!GE42+'[3]CB-6'!GE42+'[3]CB-7'!GE42+'[3]CB-8'!GE42+'[3]CB-9'!GE42+'[3]CB-10'!GE42+'[3]CB-11'!GE42+'[3]CB-12'!GE42+'[3]CB-13'!GE42+'[3]CB-14'!GE42+'[3]CB-15'!GE42+'[3]CB-16'!GE42+'[3]CB-17'!GE42+'[3]CB-18'!GE42+'[3]CB-19'!GE42+'[3]CB-20'!GE42+'[3]CB-21'!GE42+'[3]CB-22'!GE42+'[3]CB-23'!GE42+'[3]CB-24'!GE42+'[4]LCT-1'!GE42+'[4]LCT-2'!GE42+'[4]LCT-3'!GE42+'[4]LCT-4'!GE42+'[4]LCT-5'!GE42+'[4]LCT-6'!GE42+'[4]LCT-7'!GE42+'[4]LCT-8'!GE42+'[5]TB-1'!GE42+'[5]TB-2'!GE42+'[5]TB-3'!GE42+'[5]TB-4'!GE42+'[5]TB-5'!GE42+'[5]TB-6'!GE42+'[5]TB-7'!GE42+'[5]TB-8'!GE42+'[5]TB-9'!GE42+'[5]TB-10'!GE42+'[6]DSV-1'!GE42+'[6]DSV-2'!GE42+'[6]DSV-3'!GE42+'[7]TUB-1'!GE42+'[7]TUB-2'!GE42+'[8]Barge-1'!GE42+'[8]Barge-2'!GE42+'[8]Barge-3'!GE42+'[8]Barge-4'!GE42 -> 402 | AF9: =(AE9/AE21)*100% -> 0.19022982
A11: NORTH_OSF | C11: =Distribute!F42 -> 117224.8 | E11: =Distribute!G42 -> 99980.859 | G11: =Distribute!H42 -> 0 | I11: =SUM(C11,E11,G11) -> 217205.66 | J11: =(I11/I21)*100% -> 0.752677 | L11: ='[2]AHTS-1'!GF42+'[2]AHTS-2'!GF42+'[2]AHTS-3'!GF42+'[2]AHTS-4'!GF42+'[2]AHTS-5'!GF42+'[2]AHTS-6'!GF42+'[2]AHTS-7'!GF42+'[2]AHTS-8'!GF42+'[3]CB-1'!GF42+'[3]CB-2'!GF42+'[3]CB-3'!GF42+'[3]CB-4'!GF42+'[3]CB-5'!GF42+'[3]CB-6'!GF42+'[3]CB-7'!GF42+'[3]CB-8'!GF42+'[3]CB-9'!GF42+'[3]CB-10'!GF42+'[3]CB-11'!GF42+'[3]CB-12'!GF42+'[3]CB-13'!GF42+'[3]CB-14'!GF42+'[3]CB-15'!GF42+'[3]CB-16'!GF42+'[3]CB-17'!GF42+'[3]CB-18'!GF42+'[3]CB-19'!GF42+'[3]CB-20'!GF42+'[3]CB-21'!GF42+'[3]CB-22'!GF42+'[3]CB-23'!GF42+'[3]CB-24'!GF42+'[4]LCT-1'!GF42+'[4]LCT-2'!GF42+'[4]LCT-3'!GF42+'[4]LCT-4'!GF42+'[4]LCT-5'!GF42+'[4]LCT-6'!GF42+'[4]LCT-7'!GF42+'[4]LCT-8'!GF42+'[5]TB-1'!GF42+'[5]TB-2'!GF42+'[5]TB-3'!GF42+'[5]TB-4'!GF42+'[5]TB-5'!GF42+'[5]TB-6'!GF42+'[5]TB-7'!GF42+'[5]TB-8'!GF42+'[5]TB-9'!GF42+'[5]TB-10'!GF42+'[6]DSV-1'!GF42+'[6]DSV-2'!GF42+'[6]DSV-3'!GF42+'[7]TUB-1'!GF42+'[7]TUB-2'!GF42+'[8]Barge-1'!GF42+'[8]Barge-2'!GF42+'[8]Barge-3'!GF42+'[8]Barge-4'!GF42 -> 2083.2333 | M11: =(L11/L21)*100% -> 0.83824456 | T11: NORTH_OSF | V11: =Distribute!Z42 -> 1.8446665e+09 | X11: =Distribute!AA42 -> 1.5743169e+09 | Z11: =Distribute!AB42 -> 0 | AB11: =SUM(V11,X11,Z11) -> 3.4189835e+09 | AC11: =(AB11/AB21)*100% -> 0.75119565 | AE11: ='[2]AHTS-1'!GF42+'[2]AHTS-2'!GF42+'[2]AHTS-3'!GF42+'[2]AHTS-4'!GF42+'[2]AHTS-5'!GF42+'[2]AHTS-6'!GF42+'[2]AHTS-7'!GF42+'[2]AHTS-8'!GF42+'[3]CB-1'!GF42+'[3]CB-2'!GF42+'[3]CB-3'!GF42+'[3]CB-4'!GF42+'[3]CB-5'!GF42+'[3]CB-6'!GF42+'[3]CB-7'!GF42+'[3]CB-8'!GF42+'[3]CB-9'!GF42+'[3]CB-10'!GF42+'[3]CB-11'!GF42+'[3]CB-12'!GF42+'[3]CB-13'!GF42+'[3]CB-14'!GF42+'[3]CB-15'!GF42+'[3]CB-16'!GF42+'[3]CB-17'!GF42+'[3]CB-18'!GF42+'[3]CB-19'!GF42+'[3]CB-20'!GF42+'[3]CB-21'!GF42+'[3]CB-22'!GF42+'[3]CB-23'!GF42+'[3]CB-24'!GF42+'[4]LCT-1'!GF42+'[4]LCT-2'!GF42+'[4]LCT-3'!GF42+'[4]LCT-4'!GF42+'[4]LCT-5'!GF42+'[4]LCT-6'!GF42+'[4]LCT-7'!GF42+'[4]LCT-8'!GF42+'[5]TB-1'!GE42+'[5]TB-2'!GE42+'[5]TB-3'!GE42+'[5]TB-4'!GE42+'[5]TB-5'!GE42+'[5]TB-6'!GE42+'[5]TB-7'!GE42+'[5]TB-8'!GE42+'[5]TB-9'!GE42+'[5]TB-10'!GE42+'[6]DSV-1'!GF42+'[6]DSV-2'!GF42+'[6]DSV-3'!GF42+'[7]TUB-1'!GF42+'[7]TUB-2'!GF42+'[8]Barge-1'!GF42+'[8]Barge-2'!GF42+'[8]Barge-3'!GF42+'[8]Barge-4'!GF42 -> 1711.2333 | AF11: =(AE11/AE21)*100% -> 0.80977018
A21: TOTAL COST | C21: =SUM(C9:C20) -> 162953.59 | E21: =SUM(E9:E20) -> 125623.93 | G21: =SUM(G9:G20) -> 0 | I21: =SUM(I9,I11) -> 288577.51 | J21: =SUM(J9,J11) -> 1 | L21: =SUM(L9,L11) -> 2485.2333 | M21: =SUM(M9,M11) -> 1 | T21: TOTAL COST | V21: =SUM(V9:V20) -> 2.5699469e+09 | X21: =SUM(X9:X20) -> 1.9814419e+09 | Z21: =SUM(Z9:Z20) -> 0 | AB21: =SUM(AB9,AB11) -> 4.5513888e+09 | AC21: =SUM(AC9,AC11) -> 1 | AE21: =SUM(AE9,AE11) -> 2113.2333 | AF21: =SUM(AF9,AF11) -> 1
E25: Summary | I25: Daily Boat Cost Distribution to FE&C South & North | O25: FE&C Boat Cost Analysis | X25: Summary | AB25: Daily Boat Cost Distribution to FE&C South & North | AH25: FE&C Boat Cost Analysis
A44: =L5 -> 25 Nov - 24 Dec 2025 | C44: Fuel (liter)
A45: =A9 -> SOUTH _OSF | C45: =Distribute!C82 -> 44909
A46: =A11 -> NORTH_OSF | C46: =Distribute!F82 -> 114220.84
A47: TOTAL (liter) | C47: =SUM(C45:C46) -> 159129.84

Sheet Distribute
D8: 1 | G8: 2 | X8: 1 | AA8: 2
C9: =[1]Control!$HC$10 -> SOUTH OSF | F9: =[1]Control!$HD$10 -> NORTH OSF | W9: =[1]Control!$HC$10 -> SOUTH OSF | Z9: =[1]Control!$HD$10 -> NORTH OSF
A10: DATE | C10: FUEL | D10: DAYRATE | E10: MOB / DEMOB | F10: FUEL | G10: DAYRATE | H10: MOB / DEMOB | U10: DATE | W10: FUEL | X10: DAYRATE | Y10: MOB / DEMOB | Z10: FUEL | AA10: DAYRATE | AB10: MOB / DEMOB
A11: =[1]Control!AZ11 -> 45986 | C11: ='[2]AHTS-1'!AT11+'[2]AHTS-2'!AT11+'[2]AHTS-3'!AT11+'[2]AHTS-4'!AT11+'[2]AHTS-5'!AT11+'[2]AHTS-6'!AT11+'[2]AHTS-7'!AT11+'[2]AHTS-8'!AT11+'[3]CB-1'!AT11+'[3]CB-2'!AT11+'[3]CB-3'!AT11+'[3]CB-4'!AT11+'[3]CB-5'!AT11+'[3]CB-6'!AT11+'[3]CB-7'!AT11+'[3]CB-8'!AT11+'[3]CB-9'!AT11+'[3]CB-10'!AT11+'[3]CB-11'!AT11+'[3]CB-12'!AT11+'[3]CB-13'!AT11+'[3]CB-14'!AT11+'[3]CB-15'!AT11+'[3]CB-16'!AT11+'[3]CB-17'!AT11+'[3]CB-18'!AT11+'[3]CB-19'!AT11+'[3]CB-20'!AT11+'[3]CB-21'!AT11+'[3]CB-22'!AT11+'[3]CB-23'!AT11+'[3]CB-24'!AT11+'[4]LCT-1'!AT11+'[4]LCT-2'!AT11+'[4]LCT-3'!AT11+'[4]LCT-4'!AT11+'[4]LCT-5'!AT11+'[4]LCT-6'!AT11+'[4]LCT-7'!AT11+'[4]LCT-8'!AT11+'[5]TB-1'!AT11+'[5]TB-2'!AT11+'[5]TB-3'!AT11+'[5]TB-4'!AT11+'[5]TB-5'!AT11+'[5]TB-6'!AT11+'[5]TB-7'!AT11+'[5]TB-8'!AT11+'[5]TB-9'!AT11+'[5]TB-10'!AT11+'[6]DSV-1'!AT11+'[6]DSV-2'!AT11+'[6]DSV-3'!AT11+'[7]TUB-1'!AT11+'[7]TUB-2'!AT11+'[8]Barge-1'!AT11+'[8]Barge-2'!AT11+'[8]Barge-3'!AT11+'[8]Barge-4'!AT11 -> 0 | D11: ='[2]AHTS-1'!BP11+'[2]AHTS-2'!BP11+'[2]AHTS-3'!BP11+'[2]AHTS-4'!BP11+'[2]AHTS-5'!BP11+'[2]AHTS-6'!BP11+'[2]AHTS-7'!BP11+'[2]AHTS-8'!BP11+'[3]CB-1'!BP11+'[3]CB-2'!BP11+'[3]CB-3'!BP11+'[3]CB-4'!BP11+'[3]CB-5'!BP11+'[3]CB-6'!BP11+'[3]CB-7'!BP11+'[3]CB-8'!BP11+'[3]CB-9'!BP11+'[3]CB-10'!BP11+'[3]CB-11'!BP11+'[3]CB-12'!BP11+'[3]CB-13'!BP11+'[3]CB-14'!BP11+'[3]CB-15'!BP11+'[3]CB-16'!BP11+'[3]CB-17'!BP11+'[3]CB-18'!BP11+'[3]CB-19'!BP11+'[3]CB-20'!BP11+'[3]CB-21'!BP11+'[3]CB-22'!BP11+'[3]CB-23'!BP11+'[3]CB-24'!BP11+'[4]LCT-1'!BP11+'[4]LCT-2'!BP11+'[4]LCT-3'!BP11+'[4]LCT-4'!BP11+'[4]LCT-5'!BP11+'[4]LCT-6'!BP11+'[4]LCT-7'!BP11+'[4]LCT-8'!BP11+'[5]TB-1'!BP11+'[5]TB-2'!BP11+'[5]TB-3'!BP11+'[5]TB-4'!BP11+'[5]TB-5'!BP11+'[5]TB-6'!BP11+'[5]TB-7'!BP11+'[5]TB-8'!BP11+'[5]TB-9'!BP11+'[5]TB-10'!BP11+'[6]DSV-1'!BP11+'[6]DSV-2'!BP11+'[6]DSV-3'!BP11+'[7]TUB-1'!BP11+'[7]TUB-2'!BP11+'[8]Barge-1'!BP11+'[8]Barge-2'!BP11+'[8]Barge-3'!BP11+'[8]Barge-4'!BP11 -> 0 | E11: ='[2]AHTS-1'!CL11+'[2]AHTS-2'!CL11+'[2]AHTS-3'!CL11+'[2]AHTS-4'!CL11+'[2]AHTS-5'!CL11+'[2]AHTS-6'!CL11+'[2]AHTS-7'!CL11+'[2]AHTS-8'!CL11+'[3]CB-1'!CL11+'[3]CB-2'!CL11+'[3]CB-3'!CL11+'[3]CB-4'!CL11+'[3]CB-5'!CL11+'[3]CB-6'!CL11+'[3]CB-7'!CL11+'[3]CB-8'!CL11+'[3]CB-9'!CL11+'[3]CB-10'!CL11+'[3]CB-11'!CL11+'[3]CB-12'!CL11+'[3]CB-13'!CL11+'[3]CB-14'!CL11+'[3]CB-15'!CL11+'[3]CB-16'!CL11+'[3]CB-17'!CL11+'[3]CB-18'!CL11+'[3]CB-19'!CL11+'[3]CB-20'!CL11+'[3]CB-21'!CL11+'[3]CB-22'!CL11+'[3]CB-23'!CL11+'[3]CB-24'!CL11+'[4]LCT-1'!CL11+'[4]LCT-2'!CL11+'[4]LCT-3'!CL11+'[4]LCT-4'!CL11+'[4]LCT-5'!CL11+'[4]LCT-6'!CL11+'[4]LCT-7'!CL11+'[4]LCT-8'!CL11+'[5]TB-1'!CL11+'[5]TB-2'!CL11+'[5]TB-3'!CL11+'[5]TB-4'!CL11+'[5]TB-5'!CL11+'[5]TB-6'!CL11+'[5]TB-7'!CL11+'[5]TB-8'!CL11+'[5]TB-9'!CL11+'[5]TB-10'!CL11+'[6]DSV-1'!CL11+'[6]DSV-2'!CL11+'[6]DSV-3'!CL11+'[7]TUB-1'!CL11+'[7]TUB-2'!CL11+'[8]Barge-1'!CL11+'[8]Barge-2'!CL11+'[8]Barge-3'!CL11+'[8]Barge-4'!CL11 -> 0 | F11: ='[2]AHTS-1'!AU11+'[2]AHTS-2'!AU11+'[2]AHTS-3'!AU11+'[2]AHTS-4'!AU11+'[2]AHTS-5'!AU11+'[2]AHTS-6'!AU11+'[2]AHTS-7'!AU11+'[2]AHTS-8'!AU11+'[3]CB-1'!AU11+'[3]CB-2'!AU11+'[3]CB-3'!AU11+'[3]CB-4'!AU11+'[3]CB-5'!AU11+'[3]CB-6'!AU11+'[3]CB-7'!AU11+'[3]CB-8'!AU11+'[3]CB-9'!AU11+'[3]CB-10'!AU11+'[3]CB-11'!AU11+'[3]CB-12'!AU11+'[3]CB-13'!AU11+'[3]CB-14'!AU11+'[3]CB-15'!AU11+'[3]CB-16'!AU11+'[3]CB-17'!AU11+'[3]CB-18'!AU11+'[3]CB-19'!AU11+'[3]CB-20'!AU11+'[3]CB-21'!AU11+'[3]CB-22'!AU11+'[3]CB-23'!AU11+'[3]CB-24'!AU11+'[4]LCT-1'!AU11+'[4]LCT-2'!AU11+'[4]LCT-3'!AU11+'[4]LCT-4'!AU11+'[4]LCT-5'!AU11+'[4]LCT-6'!AU11+'[4]LCT-7'!AU11+'[4]LCT-8'!AU11+'[5]TB-1'!AU11+'[5]TB-2'!AU11+'[5]TB-3'!AU11+'[5]TB-4'!AU11+'[5]TB-5'!AU11+'[5]TB-6'!AU11+'[5]TB-7'!AU11+'[5]TB-8'!AU11+'[5]TB-9'!AU11+'[5]TB-10'!AU11+'[6]DSV-1'!AU11+'[6]DSV-2'!AU11+'[6]DSV-3'!AU11+'[7]TUB-1'!AU11+'[7]TUB-2'!AU11+'[8]Barge-1'!AU11+'[8]Barge-2'!AU11+'[8]Barge-3'!AU11+'[8]Barge-4'!AU11 -> 13399.433 | G11: ='[2]AHTS-1'!BQ11+'[2]AHTS-2'!BQ11+'[2]AHTS-3'!BQ11+'[2]AHTS-4'!BQ11+'[2]AHTS-5'!BQ11+'[2]AHTS-6'!BQ11+'[2]AHTS-7'!BQ11+'[2]AHTS-8'!BQ11+'[3]CB-1'!BQ11+'[3]CB-2'!BQ11+'[3]CB-3'!BQ11+'[3]CB-4'!BQ11+'[3]CB-5'!BQ11+'[3]CB-6'!BQ11+'[3]CB-7'!BQ11+'[3]CB-8'!BQ11+'[3]CB-9'!BQ11+'[3]CB-10'!BQ11+'[3]CB-11'!BQ11+'[3]CB-12'!BQ11+'[3]CB-13'!BQ11+'[3]CB-14'!BQ11+'[3]CB-15'!BQ11+'[3]CB-16'!BQ11+'[3]CB-17'!BQ11+'[3]CB-18'!BQ11+'[3]CB-19'!BQ11+'[3]CB-20'!BQ11+'[3]CB-21'!BQ11+'[3]CB-22'!BQ11+'[3]CB-23'!BQ11+'[3]CB-24'!BQ11+'[4]LCT-1'!BQ11+'[4]LCT-2'!BQ11+'[4]LCT-3'!BQ11+'[4]LCT-4'!BQ11+'[4]LCT-5'!BQ11+'[4]LCT-6'!BQ11+'[4]LCT-7'!BQ11+'[4]LCT-8'!BQ11+'[5]TB-1'!BQ11+'[5]TB-2'!BQ11+'[5]TB-3'!BQ11+'[5]TB-4'!BQ11+'[5]TB-5'!BQ11+'[5]TB-6'!BQ11+'[5]TB-7'!BQ11+'[5]TB-8'!BQ11+'[5]TB-9'!BQ11+'[5]TB-10'!BQ11+'[6]DSV-1'!BQ11+'[6]DSV-2'!BQ11+'[6]DSV-3'!BQ11+'[7]TUB-1'!BQ11+'[7]TUB-2'!BQ11+'[8]Barge-1'!BQ11+'[8]Barge-2'!BQ11+'[8]Barge-3'!BQ11+'[8]Barge-4'!BQ11 -> 8165.3763 | H11: ='[2]AHTS-1'!CM11+'[2]AHTS-2'!CM11+'[2]AHTS-3'!CM11+'[2]AHTS-4'!CM11+'[2]AHTS-5'!CM11+'[2]AHTS-6'!CM11+'[2]AHTS-7'!CM11+'[2]AHTS-8'!CM11+'[3]CB-1'!CM11+'[3]CB-2'!CM11+'[3]CB-3'!CM11+'[3]CB-4'!CM11+'[3]CB-5'!CM11+'[3]CB-6'!CM11+'[3]CB-7'!CM11+'[3]CB-8'!CM11+'[3]CB-9'!CM11+'[3]CB-10'!CM11+'[3]CB-11'!CM11+'[3]CB-12'!CM11+'[3]CB-13'!CM11+'[3]CB-14'!CM11+'[3]CB-15'!CM11+'[3]CB-16'!CM11+'[3]CB-17'!CM11+'[3]CB-18'!CM11+'[3]CB-19'!CM11+'[3]CB-20'!CM11+'[3]CB-21'!CM11+'[3]CB-22'!CM11+'[3]CB-23'!CM11+'[3]CB-24'!CM11+'[4]LCT-1'!CM11+'[4]LCT-2'!CM11+'[4]LCT-3'!CM11+'[4]LCT-4'!CM11+'[4]LCT-5'!CM11+'[4]LCT-6'!CM11+'[4]LCT-7'!CM11+'[4]LCT-8'!CM11+'[5]TB-1'!CM11+'[5]TB-2'!CM11+'[5]TB-3'!CM11+'[5]TB-4'!CM11+'[5]TB-5'!CM11+'[5]TB-6'!CM11+'[5]TB-7'!CM11+'[5]TB-8'!CM11+'[5]TB-9'!CM11+'[5]TB-10'!CM11+'[6]DSV-1'!CM11+'[6]DSV-2'!CM11+'[6]DSV-3'!CM11+'[7]TUB-1'!CM11+'[7]TUB-2'!CM11+'[8]Barge-1'!CM11+'[8]Barge-2'!CM11+'[8]Barge-3'!CM11+'[8]Barge-4'!CM11 -> 0 | U11: =[1]Control!AZ11 -> 45986 | W11: ='[2]AHTS-1'!IA49+'[2]AHTS-2'!IA49+'[2]AHTS-3'!IA49+'[2]AHTS-4'!IA49+'[2]AHTS-5'!IA49+'[2]AHTS-6'!IA49+'[2]AHTS-7'!IA49+'[2]AHTS-8'!IA49+'[3]CB-1'!IA49+'[3]CB-2'!IA49+'[3]CB-3'!IA49+'[3]CB-4'!IA49+'[3]CB-5'!IA49+'[3]CB-6'!IA49+'[3]CB-7'!IA49+'[3]CB-8'!IA49+'[3]CB-9'!IA49+'[3]CB-10'!IA49+'[3]CB-11'!IA49+'[3]CB-12'!IA49+'[3]CB-13'!IA49+'[3]CB-14'!IA49+'[3]CB-15'!IA49+'[3]CB-16'!IA49+'[3]CB-17'!IA49+'[3]CB-18'!IA49+'[3]CB-19'!IA49+'[3]CB-20'!IA49+'[3]CB-21'!IA49+'[3]CB-22'!IA49+'[3]CB-23'!IA49+'[3]CB-24'!IA49+'[4]LCT-1'!IA49+'[4]LCT-2'!IA49+'[4]LCT-3'!IA49+'[4]LCT-4'!IA49+'[4]LCT-5'!IA49+'[4]LCT-6'!IA49+'[4]LCT-7'!IA49+'[4]LCT-8'!IA49+'[5]TB-1'!IA49+'[5]TB-2'!IA49+'[5]TB-3'!IA49+'[5]TB-4'!IA49+'[5]TB-5'!IA49+'[5]TB-6'!IA49+'[5]TB-7'!IA49+'[5]TB-8'!IA49+'[5]TB-9'!IA49+'[5]TB-10'!IA49+'[6]DSV-1'!IA49+'[6]DSV-2'!IA49+'[6]DSV-3'!IA49+'[7]TUB-1'!IA49+'[7]TUB-2'!IA49+'[8]Barge-1'!IA49+'[8]Barge-2'!IA49+'[8]Barge-3'!IA49+'[8]Barge-4'!IA49 -> 0 | X11: ='[2]AHTS-1'!IA11+'[2]AHTS-2'!IA11+'[2]AHTS-3'!IA11+'[2]AHTS-4'!IA11+'[2]AHTS-5'!IA11+'[2]AHTS-6'!IA11+'[2]AHTS-7'!IA11+'[2]AHTS-8'!IA11+'[3]CB-1'!IA11+'[3]CB-2'!IA11+'[3]CB-3'!IA11+'[3]CB-4'!IA11+'[3]CB-5'!IA11+'[3]CB-6'!IA11+'[3]CB-7'!IA11+'[3]CB-8'!IA11+'[3]CB-9'!IA11+'[3]CB-10'!IA11+'[3]CB-11'!IA11+'[3]CB-12'!IA11+'[3]CB-13'!IA11+'[3]CB-14'!IA11+'[3]CB-15'!IA11+'[3]CB-16'!IA11+'[3]CB-17'!IA11+'[3]CB-18'!IA11+'[3]CB-19'!IA11+'[3]CB-20'!IA11+'[3]CB-21'!IA11+'[3]CB-22'!IA11+'[3]CB-23'!IA11+'[3]CB-24'!IA11+'[4]LCT-1'!IA11+'[4]LCT-2'!IA11+'[4]LCT-3'!IA11+'[4]LCT-4'!IA11+'[4]LCT-5'!IA11+'[4]LCT-6'!IA11+'[4]LCT-7'!IA11+'[4]LCT-8'!IA11+'[5]TB-1'!IA11+'[5]TB-2'!IA11+'[5]TB-3'!IA11+'[5]TB-4'!IA11+'[5]TB-5'!IA11+'[5]TB-6'!IA11+'[5]TB-7'!IA11+'[5]TB-8'!IA11+'[5]TB-9'!IA11+'[5]TB-10'!IA11+'[6]DSV-1'!IA11+'[6]DSV-2'!IA11+'[6]DSV-3'!IA11+'[7]TUB-1'!IA11+'[7]TUB-2'!IA11+'[8]Barge-1'!IA11+'[8]Barge-2'!IA11+'[8]Barge-3'!IA11+'[8]Barge-4'!IA11 -> 0 | Y11: ='[2]AHTS-1'!IA82+'[2]AHTS-2'!IA82+'[2]AHTS-3'!IA82+'[2]AHTS-4'!IA82+'[2]AHTS-5'!IA82+'[2]AHTS-6'!IA82+'[2]AHTS-7'!IA82+'[2]AHTS-8'!IA82+'[3]CB-1'!IA82+'[3]CB-2'!IA82+'[3]CB-3'!IA82+'[3]CB-4'!IA82+'[3]CB-5'!IA82+'[3]CB-6'!IA82+'[3]CB-7'!IA82+'[3]CB-8'!IA82+'[3]CB-9'!IA82+'[3]CB-10'!IA82+'[3]CB-11'!IA82+'[3]CB-12'!IA82+'[3]CB-13'!IA82+'[3]CB-14'!IA82+'[3]CB-15'!IA82+'[3]CB-16'!IA82+'[3]CB-17'!IA82+'[3]CB-18'!IA82+'[3]CB-19'!IA82+'[3]CB-20'!IA82+'[3]CB-21'!IA82+'[3]CB-22'!IA82+'[3]CB-23'!IA82+'[3]CB-24'!IA82+'[4]LCT-1'!IA82+'[4]LCT-2'!IA82+'[4]LCT-3'!IA82+'[4]LCT-4'!IA82+'[4]LCT-5'!IA82+'[4]LCT-6'!IA82+'[4]LCT-7'!IA82+'[4]LCT-8'!IA82+'[5]TB-1'!IA82+'[5]TB-2'!IA82+'[5]TB-3'!IA82+'[5]TB-4'!IA82+'[5]TB-5'!IA82+'[5]TB-6'!IA82+'[5]TB-7'!IA82+'[5]TB-8'!IA82+'[5]TB-9'!IA82+'[5]TB-10'!IA82+'[6]DSV-1'!IA82+'[6]DSV-2'!IA82+'[6]DSV-3'!IA82+'[7]TUB-1'!IA82+'[7]TUB-2'!IA82+'[8]Barge-1'!IA82+'[8]Barge-2'!IA82+'[8]Barge-3'!IA82+'[8]Barge-4'!IA82 -> 0 | Z11: ='[2]AHTS-1'!IB49+'[2]AHTS-2'!IB49+'[2]AHTS-3'!IB49+'[2]AHTS-4'!IB49+'[2]AHTS-5'!IB49+'[2]AHTS-6'!IB49+'[2]AHTS-7'!IB49+'[2]AHTS-8'!IB49+'[3]CB-1'!IB49+'[3]CB-2'!IB49+'[3]CB-3'!IB49+'[3]CB-4'!IB49+'[3]CB-5'!IB49+'[3]CB-6'!IB49+'[3]CB-7'!IB49+'[3]CB-8'!IB49+'[3]CB-9'!IB49+'[3]CB-10'!IB49+'[3]CB-11'!IB49+'[3]CB-12'!IB49+'[3]CB-13'!IB49+'[3]CB-14'!IB49+'[3]CB-15'!IB49+'[3]CB-16'!IB49+'[3]CB-17'!IB49+'[3]CB-18'!IB49+'[3]CB-19'!IB49+'[3]CB-20'!IB49+'[3]CB-21'!IB49+'[3]CB-22'!IB49+'[3]CB-23'!IB49+'[3]CB-24'!IB49+'[4]LCT-1'!IB49+'[4]LCT-2'!IB49+'[4]LCT-3'!IB49+'[4]LCT-4'!IB49+'[4]LCT-5'!IB49+'[4]LCT-6'!IB49+'[4]LCT-7'!IB49+'[4]LCT-8'!IB49+'[5]TB-1'!IB49+'[5]TB-2'!IB49+'[5]TB-3'!IB49+'[5]TB-4'!IB49+'[5]TB-5'!IB49+'[5]TB-6'!IB49+'[5]TB-7'!IB49+'[5]TB-8'!IB49+'[5]TB-9'!IB49+'[5]TB-10'!IB49+'[6]DSV-1'!IB49+'[6]DSV-2'!IB49+'[6]DSV-3'!IB49+'[7]TUB-1'!IB49+'[7]TUB-2'!IB49+'[8]Barge-1'!IB49+'[8]Barge-2'!IB49+'[8]Barge-3'!IB49+'[8]Barge-4'!IB49 -> 2.0941974e+08 | AA11: ='[2]AHTS-1'!IB11+'[2]AHTS-2'!IB11+'[2]AHTS-3'!IB11+'[2]AHTS-4'!IB11+'[2]AHTS-5'!IB11+'[2]AHTS-6'!IB11+'[2]AHTS-7'!IB11+'[2]AHTS-8'!IB11+'[3]CB-1'!IB11+'[3]CB-2'!IB11+'[3]CB-3'!IB11+'[3]CB-4'!IB11+'[3]CB-5'!IB11+'[3]CB-6'!IB11+'[3]CB-7'!IB11+'[3]CB-8'!IB11+'[3]CB-9'!IB11+'[3]CB-10'!IB11+'[3]CB-11'!IB11+'[3]CB-12'!IB11+'[3]CB-13'!IB11+'[3]CB-14'!IB11+'[3]CB-15'!IB11+'[3]CB-16'!IB11+'[3]CB-17'!IB11+'[3]CB-18'!IB11+'[3]CB-19'!IB11+'[3]CB-20'!IB11+'[3]CB-21'!IB11+'[3]CB-22'!IB11+'[3]CB-23'!IB11+'[3]CB-24'!IB11+'[4]LCT-1'!IB11+'[4]LCT-2'!IB11+'[4]LCT-3'!IB11+'[4]LCT-4'!IB11+'[4]LCT-5'!IB11+'[4]LCT-6'!IB11+'[4]LCT-7'!IB11+'[4]LCT-8'!IB11+'[5]TB-1'!IB11+'[5]TB-2'!IB11+'[5]TB-3'!IB11+'[5]TB-4'!IB11+'[5]TB-5'!IB11+'[5]TB-6'!IB11+'[5]TB-7'!IB11+'[5]TB-8'!IB11+'[5]TB-9'!IB11+'[5]TB-10'!IB11+'[6]DSV-1'!IB11+'[6]DSV-2'!IB11+'[6]DSV-3'!IB11+'[7]TUB-1'!IB11+'[7]TUB-2'!IB11+'[8]Barge-1'!IB11+'[8]Barge-2'!IB11+'[8]Barge-3'!IB11+'[8]Barge-4'!IB11 -> 1.2761667e+08 | AB11: ='[2]AHTS-1'!IB82+'[2]AHTS-2'!IB82+'[2]AHTS-3'!IB82+'[2]AHTS-4'!IB82+'[2]AHTS-5'!IB82+'[2]AHTS-6'!IB82+'[2]AHTS-7'!IB82+'[2]AHTS-8'!IB82+'[3]CB-1'!IB82+'[3]CB-2'!IB82+'[3]CB-3'!IB82+'[3]CB-4'!IB82+'[3]CB-5'!IB82+'[3]CB-6'!IB82+'[3]CB-7'!IB82+'[3]CB-8'!IB82+'[3]CB-9'!IB82+'[3]CB-10'!IB82+'[3]CB-11'!IB82+'[3]CB-12'!IB82+'[3]CB-13'!IB82+'[3]CB-14'!IB82+'[3]CB-15'!IB82+'[3]CB-16'!IB82+'[3]CB-17'!IB82+'[3]CB-18'!IB82+'[3]CB-19'!IB82+'[3]CB-20'!IB82+'[3]CB-21'!IB82+'[3]CB-22'!IB82+'[3]CB-23'!IB82+'[3]CB-24'!IB82+'[4]LCT-1'!IB82+'[4]LCT-2'!IB82+'[4]LCT-3'!IB82+'[4]LCT-4'!IB82+'[4]LCT-5'!IB82+'[4]LCT-6'!IB82+'[4]LCT-7'!IB82+'[4]LCT-8'!IB82+'[5]TB-1'!IB82+'[5]TB-2'!IB82+'[5]TB-3'!IB82+'[5]TB-4'!IB82+'[5]TB-5'!IB82+'[5]TB-6'!IB82+'[5]TB-7'!IB82+'[5]TB-8'!IB82+'[5]TB-9'!IB82+'[5]TB-10'!IB82+'[6]DSV-1'!IB82+'[6]DSV-2'!IB82+'[6]DSV-3'!IB82+'[7]TUB-1'!IB82+'[7]TUB-2'!IB82+'[8]Barge-1'!IB82+'[8]Barge-2'!IB82+'[8]Barge-3'!IB82+'[8]Barge-4'!IB82 -> 0
A12: =[1]Control!AZ12 -> 45987 | C12: ='[2]AHTS-1'!AT12+'[2]AHTS-2'!AT12+'[2]AHTS-3'!AT12+'[2]AHTS-4'!AT12+'[2]AHTS-5'!AT12+'[2]AHTS-6'!AT12+'[2]AHTS-7'!AT12+'[2]AHTS-8'!AT12+'[3]CB-1'!AT12+'[3]CB-2'!AT12+'[3]CB-3'!AT12+'[3]CB-4'!AT12+'[3]CB-5'!AT12+'[3]CB-6'!AT12+'[3]CB-7'!AT12+'[3]CB-8'!AT12+'[3]CB-9'!AT12+'[3]CB-10'!AT12+'[3]CB-11'!AT12+'[3]CB-12'!AT12+'[3]CB-13'!AT12+'[3]CB-14'!AT12+'[3]CB-15'!AT12+'[3]CB-16'!AT12+'[3]CB-17'!AT12+'[3]CB-18'!AT12+'[3]CB-19'!AT12+'[3]CB-20'!AT12+'[3]CB-21'!AT12+'[3]CB-22'!AT12+'[3]CB-23'!AT12+'[3]CB-24'!AT12+'[4]LCT-1'!AT12+'[4]LCT-2'!AT12+'[4]LCT-3'!AT12+'[4]LCT-4'!AT12+'[4]LCT-5'!AT12+'[4]LCT-6'!AT12+'[4]LCT-7'!AT12+'[4]LCT-8'!AT12+'[5]TB-1'!AT12+'[5]TB-2'!AT12+'[5]TB-3'!AT12+'[5]TB-4'!AT12+'[5]TB-5'!AT12+'[5]TB-6'!AT12+'[5]TB-7'!AT12+'[5]TB-8'!AT12+'[5]TB-9'!AT12+'[5]TB-10'!AT12+'[6]DSV-1'!AT12+'[6]DSV-2'!AT12+'[6]DSV-3'!AT12+'[7]TUB-1'!AT12+'[7]TUB-2'!AT12+'[8]Barge-1'!AT12+'[8]Barge-2'!AT12+'[8]Barge-3'!AT12+'[8]Barge-4'!AT12 -> 0 | D12: ='[2]AHTS-1'!BP12+'[2]AHTS-2'!BP12+'[2]AHTS-3'!BP12+'[2]AHTS-4'!BP12+'[2]AHTS-5'!BP12+'[2]AHTS-6'!BP12+'[2]AHTS-7'!BP12+'[2]AHTS-8'!BP12+'[3]CB-1'!BP12+'[3]CB-2'!BP12+'[3]CB-3'!BP12+'[3]CB-4'!BP12+'[3]CB-5'!BP12+'[3]CB-6'!BP12+'[3]CB-7'!BP12+'[3]CB-8'!BP12+'[3]CB-9'!BP12+'[3]CB-10'!BP12+'[3]CB-11'!BP12+'[3]CB-12'!BP12+'[3]CB-13'!BP12+'[3]CB-14'!BP12+'[3]CB-15'!BP12+'[3]CB-16'!BP12+'[3]CB-17'!BP12+'[3]CB-18'!BP12+'[3]CB-19'!BP12+'[3]CB-20'!BP12+'[3]CB-21'!BP12+'[3]CB-22'!BP12+'[3]CB-23'!BP12+'[3]CB-24'!BP12+'[4]LCT-1'!BP12+'[4]LCT-2'!BP12+'[4]LCT-3'!BP12+'[4]LCT-4'!BP12+'[4]LCT-5'!BP12+'[4]LCT-6'!BP12+'[4]LCT-7'!BP12+'[4]LCT-8'!BP12+'[5]TB-1'!BP12+'[5]TB-2'!BP12+'[5]TB-3'!BP12+'[5]TB-4'!BP12+'[5]TB-5'!BP12+'[5]TB-6'!BP12+'[5]TB-7'!BP12+'[5]TB-8'!BP12+'[5]TB-9'!BP12+'[5]TB-10'!BP12+'[6]DSV-1'!BP12+'[6]DSV-2'!BP12+'[6]DSV-3'!BP12+'[7]TUB-1'!BP12+'[7]TUB-2'!BP12+'[8]Barge-1'!BP12+'[8]Barge-2'!BP12+'[8]Barge-3'!BP12+'[8]Barge-4'!BP12 -> 0 | E12: ='[2]AHTS-1'!CL12+'[2]AHTS-2'!CL12+'[2]AHTS-3'!CL12+'[2]AHTS-4'!CL12+'[2]AHTS-5'!CL12+'[2]AHTS-6'!CL12+'[2]AHTS-7'!CL12+'[2]AHTS-8'!CL12+'[3]CB-1'!CL12+'[3]CB-2'!CL12+'[3]CB-3'!CL12+'[3]CB-4'!CL12+'[3]CB-5'!CL12+'[3]CB-6'!CL12+'[3]CB-7'!CL12+'[3]CB-8'!CL12+'[3]CB-9'!CL12+'[3]CB-10'!CL12+'[3]CB-11'!CL12+'[3]CB-12'!CL12+'[3]CB-13'!CL12+'[3]CB-14'!CL12+'[3]CB-15'!CL12+'[3]CB-16'!CL12+'[3]CB-17'!CL12+'[3]CB-18'!CL12+'[3]CB-19'!CL12+'[3]CB-20'!CL12+'[3]CB-21'!CL12+'[3]CB-22'!CL12+'[3]CB-23'!CL12+'[3]CB-24'!CL12+'[4]LCT-1'!CL12+'[4]LCT-2'!CL12+'[4]LCT-3'!CL12+'[4]LCT-4'!CL12+'[4]LCT-5'!CL12+'[4]LCT-6'!CL12+'[4]LCT-7'!CL12+'[4]LCT-8'!CL12+'[5]TB-1'!CL12+'[5]TB-2'!CL12+'[5]TB-3'!CL12+'[5]TB-4'!CL12+'[5]TB-5'!CL12+'[5]TB-6'!CL12+'[5]TB-7'!CL12+'[5]TB-8'!CL12+'[5]TB-9'!CL12+'[5]TB-10'!CL12+'[6]DSV-1'!CL12+'[6]DSV-2'!CL12+'[6]DSV-3'!CL12+'[7]TUB-1'!CL12+'[7]TUB-2'!CL12+'[8]Barge-1'!CL12+'[8]Barge-2'!CL12+'[8]Barge-3'!CL12+'[8]Barge-4'!CL12 -> 0 | F12: ='[2]AHTS-1'!AU12+'[2]AHTS-2'!AU12+'[2]AHTS-3'!AU12+'[2]AHTS-4'!AU12+'[2]AHTS-5'!AU12+'[2]AHTS-6'!AU12+'[2]AHTS-7'!AU12+'[2]AHTS-8'!AU12+'[3]CB-1'!AU12+'[3]CB-2'!AU12+'[3]CB-3'!AU12+'[3]CB-4'!AU12+'[3]CB-5'!AU12+'[3]CB-6'!AU12+'[3]CB-7'!AU12+'[3]CB-8'!AU12+'[3]CB-9'!AU12+'[3]CB-10'!AU12+'[3]CB-11'!AU12+'[3]CB-12'!AU12+'[3]CB-13'!AU12+'[3]CB-14'!AU12+'[3]CB-15'!AU12+'[3]CB-16'!AU12+'[3]CB-17'!AU12+'[3]CB-18'!AU12+'[3]CB-19'!AU12+'[3]CB-20'!AU12+'[3]CB-21'!AU12+'[3]CB-22'!AU12+'[3]CB-23'!AU12+'[3]CB-24'!AU12+'[4]LCT-1'!AU12+'[4]LCT-2'!AU12+'[4]LCT-3'!AU12+'[4]LCT-4'!AU12+'[4]LCT-5'!AU12+'[4]LCT-6'!AU12+'[4]LCT-7'!AU12+'[4]LCT-8'!AU12+'[5]TB-1'!AU12+'[5]TB-2'!AU12+'[5]TB-3'!AU12+'[5]TB-4'!AU12+'[5]TB-5'!AU12+'[5]TB-6'!AU12+'[5]TB-7'!AU12+'[5]TB-8'!AU12+'[5]TB-9'!AU12+'[5]TB-10'!AU12+'[6]DSV-1'!AU12+'[6]DSV-2'!AU12+'[6]DSV-3'!AU12+'[7]TUB-1'!AU12+'[7]TUB-2'!AU12+'[8]Barge-1'!AU12+'[8]Barge-2'!AU12+'[8]Barge-3'!AU12+'[8]Barge-4'!AU12 -> 12761.805 | G12: ='[2]AHTS-1'!BQ12+'[2]AHTS-2'!BQ12+'[2]AHTS-3'!BQ12+'[2]AHTS-4'!BQ12+'[2]AHTS-5'!BQ12+'[2]AHTS-6'!BQ12+'[2]AHTS-7'!BQ12+'[2]AHTS-8'!BQ12+'[3]CB-1'!BQ12+'[3]CB-2'!BQ12+'[3]CB-3'!BQ12+'[3]CB-4'!BQ12+'[3]CB-5'!BQ12+'[3]CB-6'!BQ12+'[3]CB-7'!BQ12+'[3]CB-8'!BQ12+'[3]CB-9'!BQ12+'[3]CB-10'!BQ12+'[3]CB-11'!BQ12+'[3]CB-12'!BQ12+'[3]CB-13'!BQ12+'[3]CB-14'!BQ12+'[3]CB-15'!BQ12+'[3]CB-16'!BQ12+'[3]CB-17'!BQ12+'[3]CB-18'!BQ12+'[3]CB-19'!BQ12+'[3]CB-20'!BQ12+'[3]CB-21'!BQ12+'[3]CB-22'!BQ12+'[3]CB-23'!BQ12+'[3]CB-24'!BQ12+'[4]LCT-1'!BQ12+'[4]LCT-2'!BQ12+'[4]LCT-3'!BQ12+'[4]LCT-4'!BQ12+'[4]LCT-5'!BQ12+'[4]LCT-6'!BQ12+'[4]LCT-7'!BQ12+'[4]LCT-8'!BQ12+'[5]TB-1'!BQ12+'[5]TB-2'!BQ12+'[5]TB-3'!BQ12+'[5]TB-4'!BQ12+'[5]TB-5'!BQ12+'[5]TB-6'!BQ12+'[5]TB-7'!BQ12+'[5]TB-8'!BQ12+'[5]TB-9'!BQ12+'[5]TB-10'!BQ12+'[6]DSV-1'!BQ12+'[6]DSV-2'!BQ12+'[6]DSV-3'!BQ12+'[7]TUB-1'!BQ12+'[7]TUB-2'!BQ12+'[8]Barge-1'!BQ12+'[8]Barge-2'!BQ12+'[8]Barge-3'!BQ12+'[8]Barge-4'!BQ12 -> 6918.1223 | H12: ='[2]AHTS-1'!CM12+'[2]AHTS-2'!CM12+'[2]AHTS-3'!CM12+'[2]AHTS-4'!CM12+'[2]AHTS-5'!CM12+'[2]AHTS-6'!CM12+'[2]AHTS-7'!CM12+'[2]AHTS-8'!CM12+'[3]CB-1'!CM12+'[3]CB-2'!CM12+'[3]CB-3'!CM12+'[3]CB-4'!CM12+'[3]CB-5'!CM12+'[3]CB-6'!CM12+'[3]CB-7'!CM12+'[3]CB-8'!CM12+'[3]CB-9'!CM12+'[3]CB-10'!CM12+'[3]CB-11'!CM12+'[3]CB-12'!CM12+'[3]CB-13'!CM12+'[3]CB-14'!CM12+'[3]CB-15'!CM12+'[3]CB-16'!CM12+'[3]CB-17'!CM12+'[3]CB-18'!CM12+'[3]CB-19'!CM12+'[3]CB-20'!CM12+'[3]CB-21'!CM12+'[3]CB-22'!CM12+'[3]CB-23'!CM12+'[3]CB-24'!CM12+'[4]LCT-1'!CM12+'[4]LCT-2'!CM12+'[4]LCT-3'!CM12+'[4]LCT-4'!CM12+'[4]LCT-5'!CM12+'[4]LCT-6'!CM12+'[4]LCT-7'!CM12+'[4]LCT-8'!CM12+'[5]TB-1'!CM12+'[5]TB-2'!CM12+'[5]TB-3'!CM12+'[5]TB-4'!CM12+'[5]TB-5'!CM12+'[5]TB-6'!CM12+'[5]TB-7'!CM12+'[5]TB-8'!CM12+'[5]TB-9'!CM12+'[5]TB-10'!CM12+'[6]DSV-1'!CM12+'[6]DSV-2'!CM12+'[6]DSV-3'!CM12+'[7]TUB-1'!CM12+'[7]TUB-2'!CM12+'[8]Barge-1'!CM12+'[8]Barge-2'!CM12+'[8]Barge-3'!CM12+'[8]Barge-4'!CM12 -> 0 | U12: =[1]Control!AZ12 -> 45987 | W12: ='[2]AHTS-1'!IA50+'[2]AHTS-2'!IA50+'[2]AHTS-3'!IA50+'[2]AHTS-4'!IA50+'[2]AHTS-5'!IA50+'[2]AHTS-6'!IA50+'[2]AHTS-7'!IA50+'[2]AHTS-8'!IA50+'[3]CB-1'!IA50+'[3]CB-2'!IA50+'[3]CB-3'!IA50+'[3]CB-4'!IA50+'[3]CB-5'!IA50+'[3]CB-6'!IA50+'[3]CB-7'!IA50+'[3]CB-8'!IA50+'[3]CB-9'!IA50+'[3]CB-10'!IA50+'[3]CB-11'!IA50+'[3]CB-12'!IA50+'[3]CB-13'!IA50+'[3]CB-14'!IA50+'[3]CB-15'!IA50+'[3]CB-16'!IA50+'[3]CB-17'!IA50+'[3]CB-18'!IA50+'[3]CB-19'!IA50+'[3]CB-20'!IA50+'[3]CB-21'!IA50+'[3]CB-22'!IA50+'[3]CB-23'!IA50+'[3]CB-24'!IA50+'[4]LCT-1'!IA50+'[4]LCT-2'!IA50+'[4]LCT-3'!IA50+'[4]LCT-4'!IA50+'[4]LCT-5'!IA50+'[4]LCT-6'!IA50+'[4]LCT-7'!IA50+'[4]LCT-8'!IA50+'[5]TB-1'!IA50+'[5]TB-2'!IA50+'[5]TB-3'!IA50+'[5]TB-4'!IA50+'[5]TB-5'!IA50+'[5]TB-6'!IA50+'[5]TB-7'!IA50+'[5]TB-8'!IA50+'[5]TB-9'!IA50+'[5]TB-10'!IA50+'[6]DSV-1'!IA50+'[6]DSV-2'!IA50+'[6]DSV-3'!IA50+'[7]TUB-1'!IA50+'[7]TUB-2'!IA50+'[8]Barge-1'!IA50+'[8]Barge-2'!IA50+'[8]Barge-3'!IA50+'[8]Barge-4'!IA50 -> 0 | X12: ='[2]AHTS-1'!IA12+'[2]AHTS-2'!IA12+'[2]AHTS-3'!IA12+'[2]AHTS-4'!IA12+'[2]AHTS-5'!IA12+'[2]AHTS-6'!IA12+'[2]AHTS-7'!IA12+'[2]AHTS-8'!IA12+'[3]CB-1'!IA12+'[3]CB-2'!IA12+'[3]CB-3'!IA12+'[3]CB-4'!IA12+'[3]CB-5'!IA12+'[3]CB-6'!IA12+'[3]CB-7'!IA12+'[3]CB-8'!IA12+'[3]CB-9'!IA12+'[3]CB-10'!IA12+'[3]CB-11'!IA12+'[3]CB-12'!IA12+'[3]CB-13'!IA12+'[3]CB-14'!IA12+'[3]CB-15'!IA12+'[3]CB-16'!IA12+'[3]CB-17'!IA12+'[3]CB-18'!IA12+'[3]CB-19'!IA12+'[3]CB-20'!IA12+'[3]CB-21'!IA12+'[3]CB-22'!IA12+'[3]CB-23'!IA12+'[3]CB-24'!IA12+'[4]LCT-1'!IA12+'[4]LCT-2'!IA12+'[4]LCT-3'!IA12+'[4]LCT-4'!IA12+'[4]LCT-5'!IA12+'[4]LCT-6'!IA12+'[4]LCT-7'!IA12+'[4]LCT-8'!IA12+'[5]TB-1'!IA12+'[5]TB-2'!IA12+'[5]TB-3'!IA12+'[5]TB-4'!IA12+'[5]TB-5'!IA12+'[5]TB-6'!IA12+'[5]TB-7'!IA12+'[5]TB-8'!IA12+'[5]TB-9'!IA12+'[5]TB-10'!IA12+'[6]DSV-1'!IA12+'[6]DSV-2'!IA12+'[6]DSV-3'!IA12+'[7]TUB-1'!IA12+'[7]TUB-2'!IA12+'[8]Barge-1'!IA12+'[8]Barge-2'!IA12+'[8]Barge-3'!IA12+'[8]Barge-4'!IA12 -> 0 | Y12: ='[2]AHTS-1'!IA83+'[2]AHTS-2'!IA83+'[2]AHTS-3'!IA83+'[2]AHTS-4'!IA83+'[2]AHTS-5'!IA83+'[2]AHTS-6'!IA83+'[2]AHTS-7'!IA83+'[2]AHTS-8'!IA83+'[3]CB-1'!IA83+'[3]CB-2'!IA83+'[3]CB-3'!IA83+'[3]CB-4'!IA83+'[3]CB-5'!IA83+'[3]CB-6'!IA83+'[3]CB-7'!IA83+'[3]CB-8'!IA83+'[3]CB-9'!IA83+'[3]CB-10'!IA83+'[3]CB-11'!IA83+'[3]CB-12'!IA83+'[3]CB-13'!IA83+'[3]CB-14'!IA83+'[3]CB-15'!IA83+'[3]CB-16'!IA83+'[3]CB-17'!IA83+'[3]CB-18'!IA83+'[3]CB-19'!IA83+'[3]CB-20'!IA83+'[3]CB-21'!IA83+'[3]CB-22'!IA83+'[3]CB-23'!IA83+'[3]CB-24'!IA83+'[4]LCT-1'!IA83+'[4]LCT-2'!IA83+'[4]LCT-3'!IA83+'[4]LCT-4'!IA83+'[4]LCT-5'!IA83+'[4]LCT-6'!IA83+'[4]LCT-7'!IA83+'[4]LCT-8'!IA83+'[5]TB-1'!IA83+'[5]TB-2'!IA83+'[5]TB-3'!IA83+'[5]TB-4'!IA83+'[5]TB-5'!IA83+'[5]TB-6'!IA83+'[5]TB-7'!IA83+'[5]TB-8'!IA83+'[5]TB-9'!IA83+'[5]TB-10'!IA83+'[6]DSV-1'!IA83+'[6]DSV-2'!IA83+'[6]DSV-3'!IA83+'[7]TUB-1'!IA83+'[7]TUB-2'!IA83+'[8]Barge-1'!IA83+'[8]Barge-2'!IA83+'[8]Barge-3'!IA83+'[8]Barge-4'!IA83 -> 0 | Z12: ='[2]AHTS-1'!IB50+'[2]AHTS-2'!IB50+'[2]AHTS-3'!IB50+'[2]AHTS-4'!IB50+'[2]AHTS-5'!IB50+'[2]AHTS-6'!IB50+'[2]AHTS-7'!IB50+'[2]AHTS-8'!IB50+'[3]CB-1'!IB50+'[3]CB-2'!IB50+'[3]CB-3'!IB50+'[3]CB-4'!IB50+'[3]CB-5'!IB50+'[3]CB-6'!IB50+'[3]CB-7'!IB50+'[3]CB-8'!IB50+'[3]CB-9'!IB50+'[3]CB-10'!IB50+'[3]CB-11'!IB50+'[3]CB-12'!IB50+'[3]CB-13'!IB50+'[3]CB-14'!IB50+'[3]CB-15'!IB50+'[3]CB-16'!IB50+'[3]CB-17'!IB50+'[3]CB-18'!IB50+'[3]CB-19'!IB50+'[3]CB-20'!IB50+'[3]CB-21'!IB50+'[3]CB-22'!IB50+'[3]CB-23'!IB50+'[3]CB-24'!IB50+'[4]LCT-1'!IB50+'[4]LCT-2'!IB50+'[4]LCT-3'!IB50+'[4]LCT-4'!IB50+'[4]LCT-5'!IB50+'[4]LCT-6'!IB50+'[4]LCT-7'!IB50+'[4]LCT-8'!IB50+'[5]TB-1'!IB50+'[5]TB-2'!IB50+'[5]TB-3'!IB50+'[5]TB-4'!IB50+'[5]TB-5'!IB50+'[5]TB-6'!IB50+'[5]TB-7'!IB50+'[5]TB-8'!IB50+'[5]TB-9'!IB50+'[5]TB-10'!IB50+'[6]DSV-1'!IB50+'[6]DSV-2'!IB50+'[6]DSV-3'!IB50+'[7]TUB-1'!IB50+'[7]TUB-2'!IB50+'[8]Barge-1'!IB50+'[8]Barge-2'!IB50+'[8]Barge-3'!IB50+'[8]Barge-4'!IB50 -> 1.9945425e+08 | AA12: ='[2]AHTS-1'!IB12+'[2]AHTS-2'!IB12+'[2]AHTS-3'!IB12+'[2]AHTS-4'!IB12+'[2]AHTS-5'!IB12+'[2]AHTS-6'!IB12+'[2]AHTS-7'!IB12+'[2]AHTS-8'!IB12+'[3]CB-1'!IB12+'[3]CB-2'!IB12+'[3]CB-3'!IB12+'[3]CB-4'!IB12+'[3]CB-5'!IB12+'[3]CB-6'!IB12+'[3]CB-7'!IB12+'[3]CB-8'!IB12+'[3]CB-9'!IB12+'[3]CB-10'!IB12+'[3]CB-11'!IB12+'[3]CB-12'!IB12+'[3]CB-13'!IB12+'[3]CB-14'!IB12+'[3]CB-15'!IB12+'[3]CB-16'!IB12+'[3]CB-17'!IB12+'[3]CB-18'!IB12+'[3]CB-19'!IB12+'[3]CB-20'!IB12+'[3]CB-21'!IB12+'[3]CB-22'!IB12+'[3]CB-23'!IB12+'[3]CB-24'!IB12+'[4]LCT-1'!IB12+'[4]LCT-2'!IB12+'[4]LCT-3'!IB12+'[4]LCT-4'!IB12+'[4]LCT-5'!IB12+'[4]LCT-6'!IB12+'[4]LCT-7'!IB12+'[4]LCT-8'!IB12+'[5]TB-1'!IB12+'[5]TB-2'!IB12+'[5]TB-3'!IB12+'[5]TB-4'!IB12+'[5]TB-5'!IB12+'[5]TB-6'!IB12+'[5]TB-7'!IB12+'[5]TB-8'!IB12+'[5]TB-9'!IB12+'[5]TB-10'!IB12+'[6]DSV-1'!IB12+'[6]DSV-2'!IB12+'[6]DSV-3'!IB12+'[7]TUB-1'!IB12+'[7]TUB-2'!IB12+'[8]Barge-1'!IB12+'[8]Barge-2'!IB12+'[8]Barge-3'!IB12+'[8]Barge-4'!IB12 -> 1.0812333e+08 | AB12: ='[2]AHTS-1'!IB83+'[2]AHTS-2'!IB83+'[2]AHTS-3'!IB83+'[2]AHTS-4'!IB83+'[2]AHTS-5'!IB83+'[2]AHTS-6'!IB83+'[2]AHTS-7'!IB83+'[2]AHTS-8'!IB83+'[3]CB-1'!IB83+'[3]CB-2'!IB83+'[3]CB-3'!IB83+'[3]CB-4'!IB83+'[3]CB-5'!IB83+'[3]CB-6'!IB83+'[3]CB-7'!IB83+'[3]CB-8'!IB83+'[3]CB-9'!IB83+'[3]CB-10'!IB83+'[3]CB-11'!IB83+'[3]CB-12'!IB83+'[3]CB-13'!IB83+'[3]CB-14'!IB83+'[3]CB-15'!IB83+'[3]CB-16'!IB83+'[3]CB-17'!IB83+'[3]CB-18'!IB83+'[3]CB-19'!IB83+'[3]CB-20'!IB83+'[3]CB-21'!IB83+'[3]CB-22'!IB83+'[3]CB-23'!IB83+'[3]CB-24'!IB83+'[4]LCT-1'!IB83+'[4]LCT-2'!IB83+'[4]LCT-3'!IB83+'[4]LCT-4'!IB83+'[4]LCT-5'!IB83+'[4]LCT-6'!IB83+'[4]LCT-7'!IB83+'[4]LCT-8'!IB83+'[5]TB-1'!IB83+'[5]TB-2'!IB83+'[5]TB-3'!IB83+'[5]TB-4'!IB83+'[5]TB-5'!IB83+'[5]TB-6'!IB83+'[5]TB-7'!IB83+'[5]TB-8'!IB83+'[5]TB-9'!IB83+'[5]TB-10'!IB83+'[6]DSV-1'!IB83+'[6]DSV-2'!IB83+'[6]DSV-3'!IB83+'[7]TUB-1'!IB83+'[7]TUB-2'!IB83+'[8]Barge-1'!IB83+'[8]Barge-2'!IB83+'[8]Barge-3'!IB83+'[8]Barge-4'!IB83 -> 0
A13: =[1]Control!AZ13 -> 45988 | C13: ='[2]AHTS-1'!AT13+'[2]AHTS-2'!AT13+'[2]AHTS-3'!AT13+'[2]AHTS-4'!AT13+'[2]AHTS-5'!AT13+'[2]AHTS-6'!AT13+'[2]AHTS-7'!AT13+'[2]AHTS-8'!AT13+'[3]CB-1'!AT13+'[3]CB-2'!AT13+'[3]CB-3'!AT13+'[3]CB-4'!AT13+'[3]CB-5'!AT13+'[3]CB-6'!AT13+'[3]CB-7'!AT13+'[3]CB-8'!AT13+'[3]CB-9'!AT13+'[3]CB-10'!AT13+'[3]CB-11'!AT13+'[3]CB-12'!AT13+'[3]CB-13'!AT13+'[3]CB-14'!AT13+'[3]CB-15'!AT13+'[3]CB-16'!AT13+'[3]CB-17'!AT13+'[3]CB-18'!AT13+'[3]CB-19'!AT13+'[3]CB-20'!AT13+'[3]CB-21'!AT13+'[3]CB-22'!AT13+'[3]CB-23'!AT13+'[3]CB-24'!AT13+'[4]LCT-1'!AT13+'[4]LCT-2'!AT13+'[4]LCT-3'!AT13+'[4]LCT-4'!AT13+'[4]LCT-5'!AT13+'[4]LCT-6'!AT13+'[4]LCT-7'!AT13+'[4]LCT-8'!AT13+'[5]TB-1'!AT13+'[5]TB-2'!AT13+'[5]TB-3'!AT13+'[5]TB-4'!AT13+'[5]TB-5'!AT13+'[5]TB-6'!AT13+'[5]TB-7'!AT13+'[5]TB-8'!AT13+'[5]TB-9'!AT13+'[5]TB-10'!AT13+'[6]DSV-1'!AT13+'[6]DSV-2'!AT13+'[6]DSV-3'!AT13+'[7]TUB-1'!AT13+'[7]TUB-2'!AT13+'[8]Barge-1'!AT13+'[8]Barge-2'!AT13+'[8]Barge-3'!AT13+'[8]Barge-4'!AT13 -> 0 | D13: ='[2]AHTS-1'!BP13+'[2]AHTS-2'!BP13+'[2]AHTS-3'!BP13+'[2]AHTS-4'!BP13+'[2]AHTS-5'!BP13+'[2]AHTS-6'!BP13+'[2]AHTS-7'!BP13+'[2]AHTS-8'!BP13+'[3]CB-1'!BP13+'[3]CB-2'!BP13+'[3]CB-3'!BP13+'[3]CB-4'!BP13+'[3]CB-5'!BP13+'[3]CB-6'!BP13+'[3]CB-7'!BP13+'[3]CB-8'!BP13+'[3]CB-9'!BP13+'[3]CB-10'!BP13+'[3]CB-11'!BP13+'[3]CB-12'!BP13+'[3]CB-13'!BP13+'[3]CB-14'!BP13+'[3]CB-15'!BP13+'[3]CB-16'!BP13+'[3]CB-17'!BP13+'[3]CB-18'!BP13+'[3]CB-19'!BP13+'[3]CB-20'!BP13+'[3]CB-21'!BP13+'[3]CB-22'!BP13+'[3]CB-23'!BP13+'[3]CB-24'!BP13+'[4]LCT-1'!BP13+'[4]LCT-2'!BP13+'[4]LCT-3'!BP13+'[4]LCT-4'!BP13+'[4]LCT-5'!BP13+'[4]LCT-6'!BP13+'[4]LCT-7'!BP13+'[4]LCT-8'!BP13+'[5]TB-1'!BP13+'[5]TB-2'!BP13+'[5]TB-3'!BP13+'[5]TB-4'!BP13+'[5]TB-5'!BP13+'[5]TB-6'!BP13+'[5]TB-7'!BP13+'[5]TB-8'!BP13+'[5]TB-9'!BP13+'[5]TB-10'!BP13+'[6]DSV-1'!BP13+'[6]DSV-2'!BP13+'[6]DSV-3'!BP13+'[7]TUB-1'!BP13+'[7]TUB-2'!BP13+'[8]Barge-1'!BP13+'[8]Barge-2'!BP13+'[8]Barge-3'!BP13+'[8]Barge-4'!BP13 -> 0 | E13: ='[2]AHTS-1'!CL13+'[2]AHTS-2'!CL13+'[2]AHTS-3'!CL13+'[2]AHTS-4'!CL13+'[2]AHTS-5'!CL13+'[2]AHTS-6'!CL13+'[2]AHTS-7'!CL13+'[2]AHTS-8'!CL13+'[3]CB-1'!CL13+'[3]CB-2'!CL13+'[3]CB-3'!CL13+'[3]CB-4'!CL13+'[3]CB-5'!CL13+'[3]CB-6'!CL13+'[3]CB-7'!CL13+'[3]CB-8'!CL13+'[3]CB-9'!CL13+'[3]CB-10'!CL13+'[3]CB-11'!CL13+'[3]CB-12'!CL13+'[3]CB-13'!CL13+'[3]CB-14'!CL13+'[3]CB-15'!CL13+'[3]CB-16'!CL13+'[3]CB-17'!CL13+'[3]CB-18'!CL13+'[3]CB-19'!CL13+'[3]CB-20'!CL13+'[3]CB-21'!CL13+'[3]CB-22'!CL13+'[3]CB-23'!CL13+'[3]CB-24'!CL13+'[4]LCT-1'!CL13+'[4]LCT-2'!CL13+'[4]LCT-3'!CL13+'[4]LCT-4'!CL13+'[4]LCT-5'!CL13+'[4]LCT-6'!CL13+'[4]LCT-7'!CL13+'[4]LCT-8'!CL13+'[5]TB-1'!CL13+'[5]TB-2'!CL13+'[5]TB-3'!CL13+'[5]TB-4'!CL13+'[5]TB-5'!CL13+'[5]TB-6'!CL13+'[5]TB-7'!CL13+'[5]TB-8'!CL13+'[5]TB-9'!CL13+'[5]TB-10'!CL13+'[6]DSV-1'!CL13+'[6]DSV-2'!CL13+'[6]DSV-3'!CL13+'[7]TUB-1'!CL13+'[7]TUB-2'!CL13+'[8]Barge-1'!CL13+'[8]Barge-2'!CL13+'[8]Barge-3'!CL13+'[8]Barge-4'!CL13 -> 0 | F13: ='[2]AHTS-1'!AU13+'[2]AHTS-2'!AU13+'[2]AHTS-3'!AU13+'[2]AHTS-4'!AU13+'[2]AHTS-5'!AU13+'[2]AHTS-6'!AU13+'[2]AHTS-7'!AU13+'[2]AHTS-8'!AU13+'[3]CB-1'!AU13+'[3]CB-2'!AU13+'[3]CB-3'!AU13+'[3]CB-4'!AU13+'[3]CB-5'!AU13+'[3]CB-6'!AU13+'[3]CB-7'!AU13+'[3]CB-8'!AU13+'[3]CB-9'!AU13+'[3]CB-10'!AU13+'[3]CB-11'!AU13+'[3]CB-12'!AU13+'[3]CB-13'!AU13+'[3]CB-14'!AU13+'[3]CB-15'!AU13+'[3]CB-16'!AU13+'[3]CB-17'!AU13+'[3]CB-18'!AU13+'[3]CB-19'!AU13+'[3]CB-20'!AU13+'[3]CB-21'!AU13+'[3]CB-22'!AU13+'[3]CB-23'!AU13+'[3]CB-24'!AU13+'[4]LCT-1'!AU13+'[4]LCT-2'!AU13+'[4]LCT-3'!AU13+'[4]LCT-4'!AU13+'[4]LCT-5'!AU13+'[4]LCT-6'!AU13+'[4]LCT-7'!AU13+'[4]LCT-8'!AU13+'[5]TB-1'!AU13+'[5]TB-2'!AU13+'[5]TB-3'!AU13+'[5]TB-4'!AU13+'[5]TB-5'!AU13+'[5]TB-6'!AU13+'[5]TB-7'!AU13+'[5]TB-8'!AU13+'[5]TB-9'!AU13+'[5]TB-10'!AU13+'[6]DSV-1'!AU13+'[6]DSV-2'!AU13+'[6]DSV-3'!AU13+'[7]TUB-1'!AU13+'[7]TUB-2'!AU13+'[8]Barge-1'!AU13+'[8]Barge-2'!AU13+'[8]Barge-3'!AU13+'[8]Barge-4'!AU13 -> 8942.8468 | G13: ='[2]AHTS-1'!BQ13+'[2]AHTS-2'!BQ13+'[2]AHTS-3'!BQ13+'[2]AHTS-4'!BQ13+'[2]AHTS-5'!BQ13+'[2]AHTS-6'!BQ13+'[2]AHTS-7'!BQ13+'[2]AHTS-8'!BQ13+'[3]CB-1'!BQ13+'[3]CB-2'!BQ13+'[3]CB-3'!BQ13+'[3]CB-4'!BQ13+'[3]CB-5'!BQ13+'[3]CB-6'!BQ13+'[3]CB-7'!BQ13+'[3]CB-8'!BQ13+'[3]CB-9'!BQ13+'[3]CB-10'!BQ13+'[3]CB-11'!BQ13+'[3]CB-12'!BQ13+'[3]CB-13'!BQ13+'[3]CB-14'!BQ13+'[3]CB-15'!BQ13+'[3]CB-16'!BQ13+'[3]CB-17'!BQ13+'[3]CB-18'!BQ13+'[3]CB-19'!BQ13+'[3]CB-20'!BQ13+'[3]CB-21'!BQ13+'[3]CB-22'!BQ13+'[3]CB-23'!BQ13+'[3]CB-24'!BQ13+'[4]LCT-1'!BQ13+'[4]LCT-2'!BQ13+'[4]LCT-3'!BQ13+'[4]LCT-4'!BQ13+'[4]LCT-5'!BQ13+'[4]LCT-6'!BQ13+'[4]LCT-7'!BQ13+'[4]LCT-8'!BQ13+'[5]TB-1'!BQ13+'[5]TB-2'!BQ13+'[5]TB-3'!BQ13+'[5]TB-4'!BQ13+'[5]TB-5'!BQ13+'[5]TB-6'!BQ13+'[5]TB-7'!BQ13+'[5]TB-8'!BQ13+'[5]TB-9'!BQ13+'[5]TB-10'!BQ13+'[6]DSV-1'!BQ13+'[6]DSV-2'!BQ13+'[6]DSV-3'!BQ13+'[7]TUB-1'!BQ13+'[7]TUB-2'!BQ13+'[8]Barge-1'!BQ13+'[8]Barge-2'!BQ13+'[8]Barge-3'!BQ13+'[8]Barge-4'!BQ13 -> 6600.3814 | H13: ='[2]AHTS-1'!CM13+'[2]AHTS-2'!CM13+'[2]AHTS-3'!CM13+'[2]AHTS-4'!CM13+'[2]AHTS-5'!CM13+'[2]AHTS-6'!CM13+'[2]AHTS-7'!CM13+'[2]AHTS-8'!CM13+'[3]CB-1'!CM13+'[3]CB-2'!CM13+'[3]CB-3'!CM13+'[3]CB-4'!CM13+'[3]CB-5'!CM13+'[3]CB-6'!CM13+'[3]CB-7'!CM13+'[3]CB-8'!CM13+'[3]CB-9'!CM13+'[3]CB-10'!CM13+'[3]CB-11'!CM13+'[3]CB-12'!CM13+'[3]CB-13'!CM13+'[3]CB-14'!CM13+'[3]CB-15'!CM13+'[3]CB-16'!CM13+'[3]CB-17'!CM13+'[3]CB-18'!CM13+'[3]CB-19'!CM13+'[3]CB-20'!CM13+'[3]CB-21'!CM13+'[3]CB-22'!CM13+'[3]CB-23'!CM13+'[3]CB-24'!CM13+'[4]LCT-1'!CM13+'[4]LCT-2'!CM13+'[4]LCT-3'!CM13+'[4]LCT-4'!CM13+'[4]LCT-5'!CM13+'[4]LCT-6'!CM13+'[4]LCT-7'!CM13+'[4]LCT-8'!CM13+'[5]TB-1'!CM13+'[5]TB-2'!CM13+'[5]TB-3'!CM13+'[5]TB-4'!CM13+'[5]TB-5'!CM13+'[5]TB-6'!CM13+'[5]TB-7'!CM13+'[5]TB-8'!CM13+'[5]TB-9'!CM13+'[5]TB-10'!CM13+'[6]DSV-1'!CM13+'[6]DSV-2'!CM13+'[6]DSV-3'!CM13+'[7]TUB-1'!CM13+'[7]TUB-2'!CM13+'[8]Barge-1'!CM13+'[8]Barge-2'!CM13+'[8]Barge-3'!CM13+'[8]Barge-4'!CM13 -> 0 | U13: =[1]Control!AZ13 -> 45988 | W13: ='[2]AHTS-1'!IA51+'[2]AHTS-2'!IA51+'[2]AHTS-3'!IA51+'[2]AHTS-4'!IA51+'[2]AHTS-5'!IA51+'[2]AHTS-6'!IA51+'[2]AHTS-7'!IA51+'[2]AHTS-8'!IA51+'[3]CB-1'!IA51+'[3]CB-2'!IA51+'[3]CB-3'!IA51+'[3]CB-4'!IA51+'[3]CB-5'!IA51+'[3]CB-6'!IA51+'[3]CB-7'!IA51+'[3]CB-8'!IA51+'[3]CB-9'!IA51+'[3]CB-10'!IA51+'[3]CB-11'!IA51+'[3]CB-12'!IA51+'[3]CB-13'!IA51+'[3]CB-14'!IA51+'[3]CB-15'!IA51+'[3]CB-16'!IA51+'[3]CB-17'!IA51+'[3]CB-18'!IA51+'[3]CB-19'!IA51+'[3]CB-20'!IA51+'[3]CB-21'!IA51+'[3]CB-22'!IA51+'[3]CB-23'!IA51+'[3]CB-24'!IA51+'[4]LCT-1'!IA51+'[4]LCT-2'!IA51+'[4]LCT-3'!IA51+'[4]LCT-4'!IA51+'[4]LCT-5'!IA51+'[4]LCT-6'!IA51+'[4]LCT-7'!IA51+'[4]LCT-8'!IA51+'[5]TB-1'!IA51+'[5]TB-2'!IA51+'[5]TB-3'!IA51+'[5]TB-4'!IA51+'[5]TB-5'!IA51+'[5]TB-6'!IA51+'[5]TB-7'!IA51+'[5]TB-8'!IA51+'[5]TB-9'!IA51+'[5]TB-10'!IA51+'[6]DSV-1'!IA51+'[6]DSV-2'!IA51+'[6]DSV-3'!IA51+'[7]TUB-1'!IA51+'[7]TUB-2'!IA51+'[8]Barge-1'!IA51+'[8]Barge-2'!IA51+'[8]Barge-3'!IA51+'[8]Barge-4'!IA51 -> 0 | X13: ='[2]AHTS-1'!IA13+'[2]AHTS-2'!IA13+'[2]AHTS-3'!IA13+'[2]AHTS-4'!IA13+'[2]AHTS-5'!IA13+'[2]AHTS-6'!IA13+'[2]AHTS-7'!IA13+'[2]AHTS-8'!IA13+'[3]CB-1'!IA13+'[3]CB-2'!IA13+'[3]CB-3'!IA13+'[3]CB-4'!IA13+'[3]CB-5'!IA13+'[3]CB-6'!IA13+'[3]CB-7'!IA13+'[3]CB-8'!IA13+'[3]CB-9'!IA13+'[3]CB-10'!IA13+'[3]CB-11'!IA13+'[3]CB-12'!IA13+'[3]CB-13'!IA13+'[3]CB-14'!IA13+'[3]CB-15'!IA13+'[3]CB-16'!IA13+'[3]CB-17'!IA13+'[3]CB-18'!IA13+'[3]CB-19'!IA13+'[3]CB-20'!IA13+'[3]CB-21'!IA13+'[3]CB-22'!IA13+'[3]CB-23'!IA13+'[3]CB-24'!IA13+'[4]LCT-1'!IA13+'[4]LCT-2'!IA13+'[4]LCT-3'!IA13+'[4]LCT-4'!IA13+'[4]LCT-5'!IA13+'[4]LCT-6'!IA13+'[4]LCT-7'!IA13+'[4]LCT-8'!IA13+'[5]TB-1'!IA13+'[5]TB-2'!IA13+'[5]TB-3'!IA13+'[5]TB-4'!IA13+'[5]TB-5'!IA13+'[5]TB-6'!IA13+'[5]TB-7'!IA13+'[5]TB-8'!IA13+'[5]TB-9'!IA13+'[5]TB-10'!IA13+'[6]DSV-1'!IA13+'[6]DSV-2'!IA13+'[6]DSV-3'!IA13+'[7]TUB-1'!IA13+'[7]TUB-2'!IA13+'[8]Barge-1'!IA13+'[8]Barge-2'!IA13+'[8]Barge-3'!IA13+'[8]Barge-4'!IA13 -> 0 | Y13: ='[2]AHTS-1'!IA84+'[2]AHTS-2'!IA84+'[2]AHTS-3'!IA84+'[2]AHTS-4'!IA84+'[2]AHTS-5'!IA84+'[2]AHTS-6'!IA84+'[2]AHTS-7'!IA84+'[2]AHTS-8'!IA84+'[3]CB-1'!IA84+'[3]CB-2'!IA84+'[3]CB-3'!IA84+'[3]CB-4'!IA84+'[3]CB-5'!IA84+'[3]CB-6'!IA84+'[3]CB-7'!IA84+'[3]CB-8'!IA84+'[3]CB-9'!IA84+'[3]CB-10'!IA84+'[3]CB-11'!IA84+'[3]CB-12'!IA84+'[3]CB-13'!IA84+'[3]CB-14'!IA84+'[3]CB-15'!IA84+'[3]CB-16'!IA84+'[3]CB-17'!IA84+'[3]CB-18'!IA84+'[3]CB-19'!IA84+'[3]CB-20'!IA84+'[3]CB-21'!IA84+'[3]CB-22'!IA84+'[3]CB-23'!IA84+'[3]CB-24'!IA84+'[4]LCT-1'!IA84+'[4]LCT-2'!IA84+'[4]LCT-3'!IA84+'[4]LCT-4'!IA84+'[4]LCT-5'!IA84+'[4]LCT-6'!IA84+'[4]LCT-7'!IA84+'[4]LCT-8'!IA84+'[5]TB-1'!IA84+'[5]TB-2'!IA84+'[5]TB-3'!IA84+'[5]TB-4'!IA84+'[5]TB-5'!IA84+'[5]TB-6'!IA84+'[5]TB-7'!IA84+'[5]TB-8'!IA84+'[5]TB-9'!IA84+'[5]TB-10'!IA84+'[6]DSV-1'!IA84+'[6]DSV-2'!IA84+'[6]DSV-3'!IA84+'[7]TUB-1'!IA84+'[7]TUB-2'!IA84+'[8]Barge-1'!IA84+'[8]Barge-2'!IA84+'[8]Barge-3'!IA84+'[8]Barge-4'!IA84 -> 0 | Z13: ='[2]AHTS-1'!IB51+'[2]AHTS-2'!IB51+'[2]AHTS-3'!IB51+'[2]AHTS-4'!IB51+'[2]AHTS-5'!IB51+'[2]AHTS-6'!IB51+'[2]AHTS-7'!IB51+'[2]AHTS-8'!IB51+'[3]CB-1'!IB51+'[3]CB-2'!IB51+'[3]CB-3'!IB51+'[3]CB-4'!IB51+'[3]CB-5'!IB51+'[3]CB-6'!IB51+'[3]CB-7'!IB51+'[3]CB-8'!IB51+'[3]CB-9'!IB51+'[3]CB-10'!IB51+'[3]CB-11'!IB51+'[3]CB-12'!IB51+'[3]CB-13'!IB51+'[3]CB-14'!IB51+'[3]CB-15'!IB51+'[3]CB-16'!IB51+'[3]CB-17'!IB51+'[3]CB-18'!IB51+'[3]CB-19'!IB51+'[3]CB-20'!IB51+'[3]CB-21'!IB51+'[3]CB-22'!IB51+'[3]CB-23'!IB51+'[3]CB-24'!IB51+'[4]LCT-1'!IB51+'[4]LCT-2'!IB51+'[4]LCT-3'!IB51+'[4]LCT-4'!IB51+'[4]LCT-5'!IB51+'[4]LCT-6'!IB51+'[4]LCT-7'!IB51+'[4]LCT-8'!IB51+'[5]TB-1'!IB51+'[5]TB-2'!IB51+'[5]TB-3'!IB51+'[5]TB-4'!IB51+'[5]TB-5'!IB51+'[5]TB-6'!IB51+'[5]TB-7'!IB51+'[5]TB-8'!IB51+'[5]TB-9'!IB51+'[5]TB-10'!IB51+'[6]DSV-1'!IB51+'[6]DSV-2'!IB51+'[6]DSV-3'!IB51+'[7]TUB-1'!IB51+'[7]TUB-2'!IB51+'[8]Barge-1'!IB51+'[8]Barge-2'!IB51+'[8]Barge-3'!IB51+'[8]Barge-4'!IB51 -> 1.3976775e+08 | AA13: ='[2]AHTS-1'!IB13+'[2]AHTS-2'!IB13+'[2]AHTS-3'!IB13+'[2]AHTS-4'!IB13+'[2]AHTS-5'!IB13+'[2]AHTS-6'!IB13+'[2]AHTS-7'!IB13+'[2]AHTS-8'!IB13+'[3]CB-1'!IB13+'[3]CB-2'!IB13+'[3]CB-3'!IB13+'[3]CB-4'!IB13+'[3]CB-5'!IB13+'[3]CB-6'!IB13+'[3]CB-7'!IB13+'[3]CB-8'!IB13+'[3]CB-9'!IB13+'[3]CB-10'!IB13+'[3]CB-11'!IB13+'[3]CB-12'!IB13+'[3]CB-13'!IB13+'[3]CB-14'!IB13+'[3]CB-15'!IB13+'[3]CB-16'!IB13+'[3]CB-17'!IB13+'[3]CB-18'!IB13+'[3]CB-19'!IB13+'[3]CB-20'!IB13+'[3]CB-21'!IB13+'[3]CB-22'!IB13+'[3]CB-23'!IB13+'[3]CB-24'!IB13+'[4]LCT-1'!IB13+'[4]LCT-2'!IB13+'[4]LCT-3'!IB13+'[4]LCT-4'!IB13+'[4]LCT-5'!IB13+'[4]LCT-6'!IB13+'[4]LCT-7'!IB13+'[4]LCT-8'!IB13+'[5]TB-1'!IB13+'[5]TB-2'!IB13+'[5]TB-3'!IB13+'[5]TB-4'!IB13+'[5]TB-5'!IB13+'[5]TB-6'!IB13+'[5]TB-7'!IB13+'[5]TB-8'!IB13+'[5]TB-9'!IB13+'[5]TB-10'!IB13+'[6]DSV-1'!IB13+'[6]DSV-2'!IB13+'[6]DSV-3'!IB13+'[7]TUB-1'!IB13+'[7]TUB-2'!IB13+'[8]Barge-1'!IB13+'[8]Barge-2'!IB13+'[8]Barge-3'!IB13+'[8]Barge-4'!IB13 -> 1.0315736e+08 | AB13: ='[2]AHTS-1'!IB84+'[2]AHTS-2'!IB84+'[2]AHTS-3'!IB84+'[2]AHTS-4'!IB84+'[2]AHTS-5'!IB84+'[2]AHTS-6'!IB84+'[2]AHTS-7'!IB84+'[2]AHTS-8'!IB84+'[3]CB-1'!IB84+'[3]CB-2'!IB84+'[3]CB-3'!IB84+'[3]CB-4'!IB84+'[3]CB-5'!IB84+'[3]CB-6'!IB84+'[3]CB-7'!IB84+'[3]CB-8'!IB84+'[3]CB-9'!IB84+'[3]CB-10'!IB84+'[3]CB-11'!IB84+'[3]CB-12'!IB84+'[3]CB-13'!IB84+'[3]CB-14'!IB84+'[3]CB-15'!IB84+'[3]CB-16'!IB84+'[3]CB-17'!IB84+'[3]CB-18'!IB84+'[3]CB-19'!IB84+'[3]CB-20'!IB84+'[3]CB-21'!IB84+'[3]CB-22'!IB84+'[3]CB-23'!IB84+'[3]CB-24'!IB84+'[4]LCT-1'!IB84+'[4]LCT-2'!IB84+'[4]LCT-3'!IB84+'[4]LCT-4'!IB84+'[4]LCT-5'!IB84+'[4]LCT-6'!IB84+'[4]LCT-7'!IB84+'[4]LCT-8'!IB84+'[5]TB-1'!IB84+'[5]TB-2'!IB84+'[5]TB-3'!IB84+'[5]TB-4'!IB84+'[5]TB-5'!IB84+'[5]TB-6'!IB84+'[5]TB-7'!IB84+'[5]TB-8'!IB84+'[5]TB-9'!IB84+'[5]TB-10'!IB84+'[6]DSV-1'!IB84+'[6]DSV-2'!IB84+'[6]DSV-3'!IB84+'[7]TUB-1'!IB84+'[7]TUB-2'!IB84+'[8]Barge-1'!IB84+'[8]Barge-2'!IB84+'[8]Barge-3'!IB84+'[8]Barge-4'!IB84 -> 0
A14: =[1]Control!AZ14 -> 45989 | C14: ='[2]AHTS-1'!AT14+'[2]AHTS-2'!AT14+'[2]AHTS-3'!AT14+'[2]AHTS-4'!AT14+'[2]AHTS-5'!AT14+'[2]AHTS-6'!AT14+'[2]AHTS-7'!AT14+'[2]AHTS-8'!AT14+'[3]CB-1'!AT14+'[3]CB-2'!AT14+'[3]CB-3'!AT14+'[3]CB-4'!AT14+'[3]CB-5'!AT14+'[3]CB-6'!AT14+'[3]CB-7'!AT14+'[3]CB-8'!AT14+'[3]CB-9'!AT14+'[3]CB-10'!AT14+'[3]CB-11'!AT14+'[3]CB-12'!AT14+'[3]CB-13'!AT14+'[3]CB-14'!AT14+'[3]CB-15'!AT14+'[3]CB-16'!AT14+'[3]CB-17'!AT14+'[3]CB-18'!AT14+'[3]CB-19'!AT14+'[3]CB-20'!AT14+'[3]CB-21'!AT14+'[3]CB-22'!AT14+'[3]CB-23'!AT14+'[3]CB-24'!AT14+'[4]LCT-1'!AT14+'[4]LCT-2'!AT14+'[4]LCT-3'!AT14+'[4]LCT-4'!AT14+'[4]LCT-5'!AT14+'[4]LCT-6'!AT14+'[4]LCT-7'!AT14+'[4]LCT-8'!AT14+'[5]TB-1'!AT14+'[5]TB-2'!AT14+'[5]TB-3'!AT14+'[5]TB-4'!AT14+'[5]TB-5'!AT14+'[5]TB-6'!AT14+'[5]TB-7'!AT14+'[5]TB-8'!AT14+'[5]TB-9'!AT14+'[5]TB-10'!AT14+'[6]DSV-1'!AT14+'[6]DSV-2'!AT14+'[6]DSV-3'!AT14+'[7]TUB-1'!AT14+'[7]TUB-2'!AT14+'[8]Barge-1'!AT14+'[8]Barge-2'!AT14+'[8]Barge-3'!AT14+'[8]Barge-4'!AT14 -> 0 | D14: ='[2]AHTS-1'!BP14+'[2]AHTS-2'!BP14+'[2]AHTS-3'!BP14+'[2]AHTS-4'!BP14+'[2]AHTS-5'!BP14+'[2]AHTS-6'!BP14+'[2]AHTS-7'!BP14+'[2]AHTS-8'!BP14+'[3]CB-1'!BP14+'[3]CB-2'!BP14+'[3]CB-3'!BP14+'[3]CB-4'!BP14+'[3]CB-5'!BP14+'[3]CB-6'!BP14+'[3]CB-7'!BP14+'[3]CB-8'!BP14+'[3]CB-9'!BP14+'[3]CB-10'!BP14+'[3]CB-11'!BP14+'[3]CB-12'!BP14+'[3]CB-13'!BP14+'[3]CB-14'!BP14+'[3]CB-15'!BP14+'[3]CB-16'!BP14+'[3]CB-17'!BP14+'[3]CB-18'!BP14+'[3]CB-19'!BP14+'[3]CB-20'!BP14+'[3]CB-21'!BP14+'[3]CB-22'!BP14+'[3]CB-23'!BP14+'[3]CB-24'!BP14+'[4]LCT-1'!BP14+'[4]LCT-2'!BP14+'[4]LCT-3'!BP14+'[4]LCT-4'!BP14+'[4]LCT-5'!BP14+'[4]LCT-6'!BP14+'[4]LCT-7'!BP14+'[4]LCT-8'!BP14+'[5]TB-1'!BP14+'[5]TB-2'!BP14+'[5]TB-3'!BP14+'[5]TB-4'!BP14+'[5]TB-5'!BP14+'[5]TB-6'!BP14+'[5]TB-7'!BP14+'[5]TB-8'!BP14+'[5]TB-9'!BP14+'[5]TB-10'!BP14+'[6]DSV-1'!BP14+'[6]DSV-2'!BP14+'[6]DSV-3'!BP14+'[7]TUB-1'!BP14+'[7]TUB-2'!BP14+'[8]Barge-1'!BP14+'[8]Barge-2'!BP14+'[8]Barge-3'!BP14+'[8]Barge-4'!BP14 -> 0 | E14: ='[2]AHTS-1'!CL14+'[2]AHTS-2'!CL14+'[2]AHTS-3'!CL14+'[2]AHTS-4'!CL14+'[2]AHTS-5'!CL14+'[2]AHTS-6'!CL14+'[2]AHTS-7'!CL14+'[2]AHTS-8'!CL14+'[3]CB-1'!CL14+'[3]CB-2'!CL14+'[3]CB-3'!CL14+'[3]CB-4'!CL14+'[3]CB-5'!CL14+'[3]CB-6'!CL14+'[3]CB-7'!CL14+'[3]CB-8'!CL14+'[3]CB-9'!CL14+'[3]CB-10'!CL14+'[3]CB-11'!CL14+'[3]CB-12'!CL14+'[3]CB-13'!CL14+'[3]CB-14'!CL14+'[3]CB-15'!CL14+'[3]CB-16'!CL14+'[3]CB-17'!CL14+'[3]CB-18'!CL14+'[3]CB-19'!CL14+'[3]CB-20'!CL14+'[3]CB-21'!CL14+'[3]CB-22'!CL14+'[3]CB-23'!CL14+'[3]CB-24'!CL14+'[4]LCT-1'!CL14+'[4]LCT-2'!CL14+'[4]LCT-3'!CL14+'[4]LCT-4'!CL14+'[4]LCT-5'!CL14+'[4]LCT-6'!CL14+'[4]LCT-7'!CL14+'[4]LCT-8'!CL14+'[5]TB-1'!CL14+'[5]TB-2'!CL14+'[5]TB-3'!CL14+'[5]TB-4'!CL14+'[5]TB-5'!CL14+'[5]TB-6'!CL14+'[5]TB-7'!CL14+'[5]TB-8'!CL14+'[5]TB-9'!CL14+'[5]TB-10'!CL14+'[6]DSV-1'!CL14+'[6]DSV-2'!CL14+'[6]DSV-3'!CL14+'[7]TUB-1'!CL14+'[7]TUB-2'!CL14+'[8]Barge-1'!CL14+'[8]Barge-2'!CL14+'[8]Barge-3'!CL14+'[8]Barge-4'!CL14 -> 0 | F14: ='[2]AHTS-1'!AU14+'[2]AHTS-2'!AU14+'[2]AHTS-3'!AU14+'[2]AHTS-4'!AU14+'[2]AHTS-5'!AU14+'[2]AHTS-6'!AU14+'[2]AHTS-7'!AU14+'[2]AHTS-8'!AU14+'[3]CB-1'!AU14+'[3]CB-2'!AU14+'[3]CB-3'!AU14+'[3]CB-4'!AU14+'[3]CB-5'!AU14+'[3]CB-6'!AU14+'[3]CB-7'!AU14+'[3]CB-8'!AU14+'[3]CB-9'!AU14+'[3]CB-10'!AU14+'[3]CB-11'!AU14+'[3]CB-12'!AU14+'[3]CB-13'!AU14+'[3]CB-14'!AU14+'[3]CB-15'!AU14+'[3]CB-16'!AU14+'[3]CB-17'!AU14+'[3]CB-18'!AU14+'[3]CB-19'!AU14+'[3]CB-20'!AU14+'[3]CB-21'!AU14+'[3]CB-22'!AU14+'[3]CB-23'!AU14+'[3]CB-24'!AU14+'[4]LCT-1'!AU14+'[4]LCT-2'!AU14+'[4]LCT-3'!AU14+'[4]LCT-4'!AU14+'[4]LCT-5'!AU14+'[4]LCT-6'!AU14+'[4]LCT-7'!AU14+'[4]LCT-8'!AU14+'[5]TB-1'!AU14+'[5]TB-2'!AU14+'[5]TB-3'!AU14+'[5]TB-4'!AU14+'[5]TB-5'!AU14+'[5]TB-6'!AU14+'[5]TB-7'!AU14+'[5]TB-8'!AU14+'[5]TB-9'!AU14+'[5]TB-10'!AU14+'[6]DSV-1'!AU14+'[6]DSV-2'!AU14+'[6]DSV-3'!AU14+'[7]TUB-1'!AU14+'[7]TUB-2'!AU14+'[8]Barge-1'!AU14+'[8]Barge-2'!AU14+'[8]Barge-3'!AU14+'[8]Barge-4'!AU14 -> 4811.8098 | G14: ='[2]AHTS-1'!BQ14+'[2]AHTS-2'!BQ14+'[2]AHTS-3'!BQ14+'[2]AHTS-4'!BQ14+'[2]AHTS-5'!BQ14+'[2]AHTS-6'!BQ14+'[2]AHTS-7'!BQ14+'[2]AHTS-8'!BQ14+'[3]CB-1'!BQ14+'[3]CB-2'!BQ14+'[3]CB-3'!BQ14+'[3]CB-4'!BQ14+'[3]CB-5'!BQ14+'[3]CB-6'!BQ14+'[3]CB-7'!BQ14+'[3]CB-8'!BQ14+'[3]CB-9'!BQ14+'[3]CB-10'!BQ14+'[3]CB-11'!BQ14+'[3]CB-12'!BQ14+'[3]CB-13'!BQ14+'[3]CB-14'!BQ14+'[3]CB-15'!BQ14+'[3]CB-16'!BQ14+'[3]CB-17'!BQ14+'[3]CB-18'!BQ14+'[3]CB-19'!BQ14+'[3]CB-20'!BQ14+'[3]CB-21'!BQ14+'[3]CB-22'!BQ14+'[3]CB-23'!BQ14+'[3]CB-24'!BQ14+'[4]LCT-1'!BQ14+'[4]LCT-2'!BQ14+'[4]LCT-3'!BQ14+'[4]LCT-4'!BQ14+'[4]LCT-5'!BQ14+'[4]LCT-6'!BQ14+'[4]LCT-7'!BQ14+'[4]LCT-8'!BQ14+'[5]TB-1'!BQ14+'[5]TB-2'!BQ14+'[5]TB-3'!BQ14+'[5]TB-4'!BQ14+'[5]TB-5'!BQ14+'[5]TB-6'!BQ14+'[5]TB-7'!BQ14+'[5]TB-8'!BQ14+'[5]TB-9'!BQ14+'[5]TB-10'!BQ14+'[6]DSV-1'!BQ14+'[6]DSV-2'!BQ14+'[6]DSV-3'!BQ14+'[7]TUB-1'!BQ14+'[7]TUB-2'!BQ14+'[8]Barge-1'!BQ14+'[8]Barge-2'!BQ14+'[8]Barge-3'!BQ14+'[8]Barge-4'!BQ14 -> 3901.6307 | H14: ='[2]AHTS-1'!CM14+'[2]AHTS-2'!CM14+'[2]AHTS-3'!CM14+'[2]AHTS-4'!CM14+'[2]AHTS-5'!CM14+'[2]AHTS-6'!CM14+'[2]AHTS-7'!CM14+'[2]AHTS-8'!CM14+'[3]CB-1'!CM14+'[3]CB-2'!CM14+'[3]CB-3'!CM14+'[3]CB-4'!CM14+'[3]CB-5'!CM14+'[3]CB-6'!CM14+'[3]CB-7'!CM14+'[3]CB-8'!CM14+'[3]CB-9'!CM14+'[3]CB-10'!CM14+'[3]CB-11'!CM14+'[3]CB-12'!CM14+'[3]CB-13'!CM14+'[3]CB-14'!CM14+'[3]CB-15'!CM14+'[3]CB-16'!CM14+'[3]CB-17'!CM14+'[3]CB-18'!CM14+'[3]CB-19'!CM14+'[3]CB-20'!CM14+'[3]CB-21'!CM14+'[3]CB-22'!CM14+'[3]CB-23'!CM14+'[3]CB-24'!CM14+'[4]LCT-1'!CM14+'[4]LCT-2'!CM14+'[4]LCT-3'!CM14+'[4]LCT-4'!CM14+'[4]LCT-5'!CM14+'[4]LCT-6'!CM14+'[4]LCT-7'!CM14+'[4]LCT-8'!CM14+'[5]TB-1'!CM14+'[5]TB-2'!CM14+'[5]TB-3'!CM14+'[5]TB-4'!CM14+'[5]TB-5'!CM14+'[5]TB-6'!CM14+'[5]TB-7'!CM14+'[5]TB-8'!CM14+'[5]TB-9'!CM14+'[5]TB-10'!CM14+'[6]DSV-1'!CM14+'[6]DSV-2'!CM14+'[6]DSV-3'!CM14+'[7]TUB-1'!CM14+'[7]TUB-2'!CM14+'[8]Barge-1'!CM14+'[8]Barge-2'!CM14+'[8]Barge-3'!CM14+'[8]Barge-4'!CM14 -> 0 | U14: =[1]Control!AZ14 -> 45989 | W14: ='[2]AHTS-1'!IA52+'[2]AHTS-2'!IA52+'[2]AHTS-3'!IA52+'[2]AHTS-4'!IA52+'[2]AHTS-5'!IA52+'[2]AHTS-6'!IA52+'[2]AHTS-7'!IA52+'[2]AHTS-8'!IA52+'[3]CB-1'!IA52+'[3]CB-2'!IA52+'[3]CB-3'!IA52+'[3]CB-4'!IA52+'[3]CB-5'!IA52+'[3]CB-6'!IA52+'[3]CB-7'!IA52+'[3]CB-8'!IA52+'[3]CB-9'!IA52+'[3]CB-10'!IA52+'[3]CB-11'!IA52+'[3]CB-12'!IA52+'[3]CB-13'!IA52+'[3]CB-14'!IA52+'[3]CB-15'!IA52+'[3]CB-16'!IA52+'[3]CB-17'!IA52+'[3]CB-18'!IA52+'[3]CB-19'!IA52+'[3]CB-20'!IA52+'[3]CB-21'!IA52+'[3]CB-22'!IA52+'[3]CB-23'!IA52+'[3]CB-24'!IA52+'[4]LCT-1'!IA52+'[4]LCT-2'!IA52+'[4]LCT-3'!IA52+'[4]LCT-4'!IA52+'[4]LCT-5'!IA52+'[4]LCT-6'!IA52+'[4]LCT-7'!IA52+'[4]LCT-8'!IA52+'[5]TB-1'!IA52+'[5]TB-2'!IA52+'[5]TB-3'!IA52+'[5]TB-4'!IA52+'[5]TB-5'!IA52+'[5]TB-6'!IA52+'[5]TB-7'!IA52+'[5]TB-8'!IA52+'[5]TB-9'!IA52+'[5]TB-10'!IA52+'[6]DSV-1'!IA52+'[6]DSV-2'!IA52+'[6]DSV-3'!IA52+'[7]TUB-1'!IA52+'[7]TUB-2'!IA52+'[8]Barge-1'!IA52+'[8]Barge-2'!IA52+'[8]Barge-3'!IA52+'[8]Barge-4'!IA52 -> 0 | X14: ='[2]AHTS-1'!IA14+'[2]AHTS-2'!IA14+'[2]AHTS-3'!IA14+'[2]AHTS-4'!IA14+'[2]AHTS-5'!IA14+'[2]AHTS-6'!IA14+'[2]AHTS-7'!IA14+'[2]AHTS-8'!IA14+'[3]CB-1'!IA14+'[3]CB-2'!IA14+'[3]CB-3'!IA14+'[3]CB-4'!IA14+'[3]CB-5'!IA14+'[3]CB-6'!IA14+'[3]CB-7'!IA14+'[3]CB-8'!IA14+'[3]CB-9'!IA14+'[3]CB-10'!IA14+'[3]CB-11'!IA14+'[3]CB-12'!IA14+'[3]CB-13'!IA14+'[3]CB-14'!IA14+'[3]CB-15'!IA14+'[3]CB-16'!IA14+'[3]CB-17'!IA14+'[3]CB-18'!IA14+'[3]CB-19'!IA14+'[3]CB-20'!IA14+'[3]CB-21'!IA14+'[3]CB-22'!IA14+'[3]CB-23'!IA14+'[3]CB-24'!IA14+'[4]LCT-1'!IA14+'[4]LCT-2'!IA14+'[4]LCT-3'!IA14+'[4]LCT-4'!IA14+'[4]LCT-5'!IA14+'[4]LCT-6'!IA14+'[4]LCT-7'!IA14+'[4]LCT-8'!IA14+'[5]TB-1'!IA14+'[5]TB-2'!IA14+'[5]TB-3'!IA14+'[5]TB-4'!IA14+'[5]TB-5'!IA14+'[5]TB-6'!IA14+'[5]TB-7'!IA14+'[5]TB-8'!IA14+'[5]TB-9'!IA14+'[5]TB-10'!IA14+'[6]DSV-1'!IA14+'[6]DSV-2'!IA14+'[6]DSV-3'!IA14+'[7]TUB-1'!IA14+'[7]TUB-2'!IA14+'[8]Barge-1'!IA14+'[8]Barge-2'!IA14+'[8]Barge-3'!IA14+'[8]Barge-4'!IA14 -> 0 | Y14: ='[2]AHTS-1'!IA85+'[2]AHTS-2'!IA85+'[2]AHTS-3'!IA85+'[2]AHTS-4'!IA85+'[2]AHTS-5'!IA85+'[2]AHTS-6'!IA85+'[2]AHTS-7'!IA85+'[2]AHTS-8'!IA85+'[3]CB-1'!IA85+'[3]CB-2'!IA85+'[3]CB-3'!IA85+'[3]CB-4'!IA85+'[3]CB-5'!IA85+'[3]CB-6'!IA85+'[3]CB-7'!IA85+'[3]CB-8'!IA85+'[3]CB-9'!IA85+'[3]CB-10'!IA85+'[3]CB-11'!IA85+'[3]CB-12'!IA85+'[3]CB-13'!IA85+'[3]CB-14'!IA85+'[3]CB-15'!IA85+'[3]CB-16'!IA85+'[3]CB-17'!IA85+'[3]CB-18'!IA85+'[3]CB-19'!IA85+'[3]CB-20'!IA85+'[3]CB-21'!IA85+'[3]CB-22'!IA85+'[3]CB-23'!IA85+'[3]CB-24'!IA85+'[4]LCT-1'!IA85+'[4]LCT-2'!IA85+'[4]LCT-3'!IA85+'[4]LCT-4'!IA85+'[4]LCT-5'!IA85+'[4]LCT-6'!IA85+'[4]LCT-7'!IA85+'[4]LCT-8'!IA85+'[5]TB-1'!IA85+'[5]TB-2'!IA85+'[5]TB-3'!IA85+'[5]TB-4'!IA85+'[5]TB-5'!IA85+'[5]TB-6'!IA85+'[5]TB-7'!IA85+'[5]TB-8'!IA85+'[5]TB-9'!IA85+'[5]TB-10'!IA85+'[6]DSV-1'!IA85+'[6]DSV-2'!IA85+'[6]DSV-3'!IA85+'[7]TUB-1'!IA85+'[7]TUB-2'!IA85+'[8]Barge-1'!IA85+'[8]Barge-2'!IA85+'[8]Barge-3'!IA85+'[8]Barge-4'!IA85 -> 0 | Z14: ='[2]AHTS-1'!IB52+'[2]AHTS-2'!IB52+'[2]AHTS-3'!IB52+'[2]AHTS-4'!IB52+'[2]AHTS-5'!IB52+'[2]AHTS-6'!IB52+'[2]AHTS-7'!IB52+'[2]AHTS-8'!IB52+'[3]CB-1'!IB52+'[3]CB-2'!IB52+'[3]CB-3'!IB52+'[3]CB-4'!IB52+'[3]CB-5'!IB52+'[3]CB-6'!IB52+'[3]CB-7'!IB52+'[3]CB-8'!IB52+'[3]CB-9'!IB52+'[3]CB-10'!IB52+'[3]CB-11'!IB52+'[3]CB-12'!IB52+'[3]CB-13'!IB52+'[3]CB-14'!IB52+'[3]CB-15'!IB52+'[3]CB-16'!IB52+'[3]CB-17'!IB52+'[3]CB-18'!IB52+'[3]CB-19'!IB52+'[3]CB-20'!IB52+'[3]CB-21'!IB52+'[3]CB-22'!IB52+'[3]CB-23'!IB52+'[3]CB-24'!IB52+'[4]LCT-1'!IB52+'[4]LCT-2'!IB52+'[4]LCT-3'!IB52+'[4]LCT-4'!IB52+'[4]LCT-5'!IB52+'[4]LCT-6'!IB52+'[4]LCT-7'!IB52+'[4]LCT-8'!IB52+'[5]TB-1'!IB52+'[5]TB-2'!IB52+'[5]TB-3'!IB52+'[5]TB-4'!IB52+'[5]TB-5'!IB52+'[5]TB-6'!IB52+'[5]TB-7'!IB52+'[5]TB-8'!IB52+'[5]TB-9'!IB52+'[5]TB-10'!IB52+'[6]DSV-1'!IB52+'[6]DSV-2'!IB52+'[6]DSV-3'!IB52+'[7]TUB-1'!IB52+'[7]TUB-2'!IB52+'[8]Barge-1'!IB52+'[8]Barge-2'!IB52+'[8]Barge-3'!IB52+'[8]Barge-4'!IB52 -> 75684956 | AA14: ='[2]AHTS-1'!IB14+'[2]AHTS-2'!IB14+'[2]AHTS-3'!IB14+'[2]AHTS-4'!IB14+'[2]AHTS-5'!IB14+'[2]AHTS-6'!IB14+'[2]AHTS-7'!IB14+'[2]AHTS-8'!IB14+'[3]CB-1'!IB14+'[3]CB-2'!IB14+'[3]CB-3'!IB14+'[3]CB-4'!IB14+'[3]CB-5'!IB14+'[3]CB-6'!IB14+'[3]CB-7'!IB14+'[3]CB-8'!IB14+'[3]CB-9'!IB14+'[3]CB-10'!IB14+'[3]CB-11'!IB14+'[3]CB-12'!IB14+'[3]CB-13'!IB14+'[3]CB-14'!IB14+'[3]CB-15'!IB14+'[3]CB-16'!IB14+'[3]CB-17'!IB14+'[3]CB-18'!IB14+'[3]CB-19'!IB14+'[3]CB-20'!IB14+'[3]CB-21'!IB14+'[3]CB-22'!IB14+'[3]CB-23'!IB14+'[3]CB-24'!IB14+'[4]LCT-1'!IB14+'[4]LCT-2'!IB14+'[4]LCT-3'!IB14+'[4]LCT-4'!IB14+'[4]LCT-5'!IB14+'[4]LCT-6'!IB14+'[4]LCT-7'!IB14+'[4]LCT-8'!IB14+'[5]TB-1'!IB14+'[5]TB-2'!IB14+'[5]TB-3'!IB14+'[5]TB-4'!IB14+'[5]TB-5'!IB14+'[5]TB-6'!IB14+'[5]TB-7'!IB14+'[5]TB-8'!IB14+'[5]TB-9'!IB14+'[5]TB-10'!IB14+'[6]DSV-1'!IB14+'[6]DSV-2'!IB14+'[6]DSV-3'!IB14+'[7]TUB-1'!IB14+'[7]TUB-2'!IB14+'[8]Barge-1'!IB14+'[8]Barge-2'!IB14+'[8]Barge-3'!IB14+'[8]Barge-4'!IB14 -> 61368750 | AB14: ='[2]AHTS-1'!IB85+'[2]AHTS-2'!IB85+'[2]AHTS-3'!IB85+'[2]AHTS-4'!IB85+'[2]AHTS-5'!IB85+'[2]AHTS-6'!IB85+'[2]AHTS-7'!IB85+'[2]AHTS-8'!IB85+'[3]CB-1'!IB85+'[3]CB-2'!IB85+'[3]CB-3'!IB85+'[3]CB-4'!IB85+'[3]CB-5'!IB85+'[3]CB-6'!IB85+'[3]CB-7'!IB85+'[3]CB-8'!IB85+'[3]CB-9'!IB85+'[3]CB-10'!IB85+'[3]CB-11'!IB85+'[3]CB-12'!IB85+'[3]CB-13'!IB85+'[3]CB-14'!IB85+'[3]CB-15'!IB85+'[3]CB-16'!IB85+'[3]CB-17'!IB85+'[3]CB-18'!IB85+'[3]CB-19'!IB85+'[3]CB-20'!IB85+'[3]CB-21'!IB85+'[3]CB-22'!IB85+'[3]CB-23'!IB85+'[3]CB-24'!IB85+'[4]LCT-1'!IB85+'[4]LCT-2'!IB85+'[4]LCT-3'!IB85+'[4]LCT-4'!IB85+'[4]LCT-5'!IB85+'[4]LCT-6'!IB85+'[4]LCT-7'!IB85+'[4]LCT-8'!IB85+'[5]TB-1'!IB85+'[5]TB-2'!IB85+'[5]TB-3'!IB85+'[5]TB-4'!IB85+'[5]TB-5'!IB85+'[5]TB-6'!IB85+'[5]TB-7'!IB85+'[5]TB-8'!IB85+'[5]TB-9'!IB85+'[5]TB-10'!IB85+'[6]DSV-1'!IB85+'[6]DSV-2'!IB85+'[6]DSV-3'!IB85+'[7]TUB-1'!IB85+'[7]TUB-2'!IB85+'[8]Barge-1'!IB85+'[8]Barge-2'!IB85+'[8]Barge-3'!IB85+'[8]Barge-4'!IB85 -> 0
