Workbook
Name IDS: "Rectangle 3"

Sheet Ops
L5: =[1]Control!AU10 -> 25 Nov - 24 Dec 2025 | AG5: =L5 -> 25 Nov - 24 Dec 2025
C7: FUEL COST | E7: CHARTER RATE | G7: MOB / DEMOB | I7: TOTAL COST | J7: PCT | L7: BOAT HOURS | M7: PCT | X7: FUEL COST | Z7: CHARTER RATE | AB7: MOB / DEMOB | AD7: TOTAL COST | AE7: PCT | AG7: BOAT HOURS | AH7: PCT
L8: Logistics Cost Sharing | AG8: Logistics Cost Sharing
A9: =Distribute!C9 -> - | C9: =Distribute!C42 -> 0 | E9: =Distribute!D42 -> 0 | G9: =Distribute!E42 -> 0 | I9: =SUM(C9,E9,G9) -> 0 | J9: =(I9/I23)*100% -> 0 | L9: ='[2]AHTS-1'!GG42+'[2]AHTS-2'!GG42+'[2]AHTS-3'!GG42+'[2]AHTS-4'!GG42+'[2]AHTS-5'!GG42+'[2]AHTS-6'!GG42+'[2]AHTS-7'!GG42+'[2]AHTS-8'!GG42+'[3]CB-1'!GG42+'[3]CB-2'!GG42+'[3]CB-3'!GG42+'[3]CB-4'!GG42+'[3]CB-5'!GG42+'[3]CB-6'!GG42+'[3]CB-7'!GG42+'[3]CB-8'!GG42+'[3]CB-9'!GG42+'[3]CB-10'!GG42+'[3]CB-11'!GG42+'[3]CB-12'!GG42+'[3]CB-13'!GG42+'[3]CB-14'!GG42+'[3]CB-15'!GG42+'[3]CB-16'!GG42+'[3]CB-17'!GG42+'[3]CB-18'!GG42+'[3]CB-19'!GG42+'[3]CB-20'!GG42+'[3]CB-21'!GG42+'[3]CB-22'!GG42+'[3]CB-23'!GG42+'[3]CB-24'!GG42+'[4]LCT-1'!GG42+'[4]LCT-2'!GG42+'[4]LCT-3'!GG42+'[4]LCT-4'!GG42+'[4]LCT-5'!GG42+'[4]LCT-6'!GG42+'[4]LCT-7'!GG42+'[4]LCT-8'!GG42+'[5]TB-1'!GG42+'[5]TB-2'!GG42+'[5]TB-3'!GG42+'[5]TB-4'!GG42+'[5]TB-5'!GG42+'[5]TB-6'!GG42+'[5]TB-7'!GG42+'[5]TB-8'!GG42+'[5]TB-9'!GG42+'[5]TB-10'!GG42+'[6]DSV-1'!GG42+'[6]DSV-2'!GG42+'[6]DSV-3'!GG42+'[7]TUB-1'!GG42+'[7]TUB-2'!GG42+'[8]Barge-1'!GG42+'[8]Barge-2'!GG42+'[8]Barge-3'!GG42+'[8]Barge-4'!GG42 -> 0 | M9: =(L9/L23)*100% -> 0 | V9: =A9 -> - | X9: =Distribute!AC42 -> 0 | Z9: =Distribute!AD42 -> 0 | AB9: =Distribute!AE42 -> 0 | AD9: =SUM(X9,Z9,AB9) -> 0 | AE9: =(AD9/AD23)*100% -> 0 | AG9: ='[2]AHTS-1'!GG42+'[2]AHTS-2'!GG42+'[2]AHTS-3'!GG42+'[2]AHTS-4'!GG42+'[2]AHTS-5'!GG42+'[2]AHTS-6'!GG42+'[2]AHTS-7'!GG42+'[2]AHTS-8'!GG42+'[3]CB-1'!GG42+'[3]CB-2'!GG42+'[3]CB-3'!GG42+'[3]CB-4'!GG42+'[3]CB-5'!GG42+'[3]CB-6'!GG42+'[3]CB-7'!GG42+'[3]CB-8'!GG42+'[3]CB-9'!GG42+'[3]CB-10'!GG42+'[3]CB-11'!GG42+'[3]CB-12'!GG42+'[3]CB-13'!GG42+'[3]CB-14'!GG42+'[3]CB-15'!GG42+'[3]CB-16'!GG42+'[3]CB-17'!GG42+'[3]CB-18'!GG42+'[3]CB-19'!GG42+'[3]CB-20'!GG42+'[3]CB-21'!GG42+'[3]CB-22'!GG42+'[3]CB-23'!GG42+'[3]CB-24'!GG42+'[4]LCT-1'!GG42+'[4]LCT-2'!GG42+'[4]LCT-3'!GG42+'[4]LCT-4'!GG42+'[4]LCT-5'!GG42+'[4]LCT-6'!GG42+'[4]LCT-7'!GG42+'[4]LCT-8'!GG42+'[5]TB-1'!GG42+'[5]TB-2'!GG42+'[5]TB-3'!GG42+'[5]TB-4'!GG42+'[5]TB-5'!GG42+'[5]TB-6'!GG42+'[5]TB-7'!GG42+'[5]TB-8'!GG42+'[5]TB-9'!GG42+'[5]TB-10'!GG42+'[6]DSV-1'!GG42+'[6]DSV-2'!GG42+'[6]DSV-3'!GG42+'[7]TUB-1'!GG42+'[7]TUB-2'!GG42+'[8]Barge-1'!GG42+'[8]Barge-2'!GG42+'[8]Barge-3'!GG42 -> 0 | AH9: =(AG9/AG23)*100% -> 0
A11: =Distribute!F9 -> P_NORTH ATTAKA | C11: =Distribute!F42 -> 48454.072 | E11: =Distribute!G42 -> 51427.768 | G11: =Distribute!H42 -> 0 | I11: =SUM(C11,E11,G11) -> 99881.84 | J11: =(I11/I23)*100% -> 0.12054832 | L11: ='[2]AHTS-1'!GH42+'[2]AHTS-2'!GH42+'[2]AHTS-3'!GH42+'[2]AHTS-4'!GH42+'[2]AHTS-5'!GH42+'[2]AHTS-6'!GH42+'[2]AHTS-7'!GH42+'[2]AHTS-8'!GH42+'[3]CB-1'!GH42+'[3]CB-2'!GH42+'[3]CB-3'!GH42+'[3]CB-4'!GH42+'[3]CB-5'!GH42+'[3]CB-6'!GH42+'[3]CB-7'!GH42+'[3]CB-8'!GH42+'[3]CB-9'!GH42+'[3]CB-10'!GH42+'[3]CB-11'!GH42+'[3]CB-12'!GH42+'[3]CB-13'!GH42+'[3]CB-14'!GH42+'[3]CB-15'!GH42+'[3]CB-16'!GH42+'[3]CB-17'!GH42+'[3]CB-18'!GH42+'[3]CB-19'!GH42+'[3]CB-20'!GH42+'[3]CB-21'!GH42+'[3]CB-22'!GH42+'[3]CB-23'!GH42+'[3]CB-24'!GH42+'[4]LCT-1'!GH42+'[4]LCT-2'!GH42+'[4]LCT-3'!GH42+'[4]LCT-4'!GH42+'[4]LCT-5'!GH42+'[4]LCT-6'!GH42+'[4]LCT-7'!GH42+'[4]LCT-8'!GH42+'[5]TB-1'!GH42+'[5]TB-2'!GH42+'[5]TB-3'!GH42+'[5]TB-4'!GH42+'[5]TB-5'!GH42+'[5]TB-6'!GH42+'[5]TB-7'!GH42+'[5]TB-8'!GH42+'[5]TB-9'!GH42+'[5]TB-10'!GH42+'[6]DSV-1'!GH42+'[6]DSV-2'!GH42+'[6]DSV-3'!GH42+'[7]TUB-1'!GH42+'[7]TUB-2'!GH42+'[8]Barge-1'!GH42+'[8]Barge-2'!GH42+'[8]Barge-3'!GH42+'[8]Barge-4'!GH42 -> 1032.4 | M11: =(L11/L23)*100% -> 0.14800231 | V11: =A11 -> P_NORTH ATTAKA | X11: =Distribute!AF42 -> 7.6413732e+08 | Z11: =Distribute!AG42 -> 8.1096194e+08 | AB11: =Distribute!AH42 -> 0 | AD11: =SUM(X11,Z11,AB11) -> 1.5750993e+09 | AE11: =(AD11/AD23)*100% -> 0.1204877 | AG11: ='[2]AHTS-1'!GH42+'[2]AHTS-2'!GH42+'[2]AHTS-3'!GH42+'[2]AHTS-4'!GH42+'[2]AHTS-5'!GH42+'[2]AHTS-6'!GH42+'[2]AHTS-7'!GH42+'[2]AHTS-8'!GH42+'[3]CB-1'!GH42+'[3]CB-2'!GH42+'[3]CB-3'!GH42+'[3]CB-4'!GH42+'[3]CB-5'!GH42+'[3]CB-6'!GH42+'[3]CB-7'!GH42+'[3]CB-8'!GH42+'[3]CB-9'!GH42+'[3]CB-10'!GH42+'[3]CB-11'!GH42+'[3]CB-12'!GH42+'[3]CB-13'!GH42+'[3]CB-14'!GH42+'[3]CB-15'!GH42+'[3]CB-16'!GH42+'[3]CB-17'!GH42+'[3]CB-18'!GH42+'[3]CB-19'!GH42+'[3]CB-20'!GH42+'[3]CB-21'!GH42+'[3]CB-22'!GH42+'[3]CB-23'!GH42+'[3]CB-24'!GH42+'[4]LCT-1'!GH42+'[4]LCT-2'!GH42+'[4]LCT-3'!GH42+'[4]LCT-4'!GH42+'[4]LCT-5'!GH42+'[4]LCT-6'!GH42+'[4]LCT-7'!GH42+'[4]LCT-8'!GH42+'[5]TB-1'!GH42+'[5]TB-2'!GH42+'[5]TB-3'!GH42+'[5]TB-4'!GH42+'[5]TB-5'!GH42+'[5]TB-6'!GH42+'[5]TB-7'!GH42+'[5]TB-8'!GH42+'[5]TB-9'!GH42+'[5]TB-10'!GH42+'[6]DSV-1'!GH42+'[6]DSV-2'!GH42+'[6]DSV-3'!GH42+'[7]TUB-1'!GH42+'[7]TUB-2'!GH42+'[8]Barge-1'!GH42+'[8]Barge-2'!GH42+'[8]Barge-3'!GH42 -> 1032.4 | AH11: =(AG11/AG23)*100% -> 0.14800231
A13: =Distribute!I9 -> P_NORTH NIB | C13: =Distribute!I42 -> 98673.625 | E13: =Distribute!J42 -> 79360.342 | G13: =Distribute!K42 -> 0 | I13: =SUM(C13,E13,G13) -> 178033.97 | J13: =(I13/I23)*100% -> 0.21487084 | L13: ='[2]AHTS-1'!GI42+'[2]AHTS-2'!GI42+'[2]AHTS-3'!GI42+'[2]AHTS-4'!GI42+'[2]AHTS-5'!GI42+'[2]AHTS-6'!GI42+'[2]AHTS-7'!GI42+'[2]AHTS-8'!GI42+'[3]CB-1'!GI42+'[3]CB-2'!GI42+'[3]CB-3'!GI42+'[3]CB-4'!GI42+'[3]CB-5'!GI42+'[3]CB-6'!GI42+'[3]CB-7'!GI42+'[3]CB-8'!GI42+'[3]CB-9'!GI42+'[3]CB-10'!GI42+'[3]CB-11'!GI42+'[3]CB-12'!GI42+'[3]CB-13'!GI42+'[3]CB-14'!GI42+'[3]CB-15'!GI42+'[3]CB-16'!GI42+'[3]CB-17'!GI42+'[3]CB-18'!GI42+'[3]CB-19'!GI42+'[3]CB-20'!GI42+'[3]CB-21'!GI42+'[3]CB-22'!GI42+'[3]CB-23'!GI42+'[3]CB-24'!GI42+'[4]LCT-1'!GI42+'[4]LCT-2'!GI42+'[4]LCT-3'!GI42+'[4]LCT-4'!GI42+'[4]LCT-5'!GI42+'[4]LCT-6'!GI42+'[4]LCT-7'!GI42+'[4]LCT-8'!GI42+'[5]TB-1'!GI42+'[5]TB-2'!GI42+'[5]TB-3'!GI42+'[5]TB-4'!GI42+'[5]TB-5'!GI42+'[5]TB-6'!GI42+'[5]TB-7'!GI42+'[5]TB-8'!GI42+'[5]TB-9'!GI42+'[5]TB-10'!GI42+'[6]DSV-1'!GI42+'[6]DSV-2'!GI42+'[6]DSV-3'!GI42+'[7]TUB-1'!GI42+'[7]TUB-2'!GI42+'[8]Barge-1'!GI42+'[8]Barge-2'!GI42+'[8]Barge-3'!GI42+'[8]Barge-4'!GI42 -> 935.26667 | M13: =(L13/L23)*100% -> 0.13407752 | V13: =A13 -> P_NORTH NIB | X13: =Distribute!AI42 -> 1.5582003e+09 | Z13: =Distribute!AJ42 -> 1.2533624e+09 | AB13: =Distribute!AK42 -> 0 | AD13: =SUM(X13,Z13,AB13) -> 2.8115627e+09 | AE13: =(AD13/AD23)*100% -> 0.21507134 | AG13: ='[2]AHTS-1'!GI42+'[2]AHTS-2'!GI42+'[2]AHTS-3'!GI42+'[2]AHTS-4'!GI42+'[2]AHTS-5'!GI42+'[2]AHTS-6'!GI42+'[2]AHTS-7'!GI42+'[2]AHTS-8'!GI42+'[3]CB-1'!GI42+'[3]CB-2'!GI42+'[3]CB-3'!GI42+'[3]CB-4'!GI42+'[3]CB-5'!GI42+'[3]CB-6'!GI42+'[3]CB-7'!GI42+'[3]CB-8'!GI42+'[3]CB-9'!GI42+'[3]CB-10'!GI42+'[3]CB-11'!GI42+'[3]CB-12'!GI42+'[3]CB-13'!GI42+'[3]CB-14'!GI42+'[3]CB-15'!GI42+'[3]CB-16'!GI42+'[3]CB-17'!GI42+'[3]CB-18'!GI42+'[3]CB-19'!GI42+'[3]CB-20'!GI42+'[3]CB-21'!GI42+'[3]CB-22'!GI42+'[3]CB-23'!GI42+'[3]CB-24'!GI42+'[4]LCT-1'!GI42+'[4]LCT-2'!GI42+'[4]LCT-3'!GI42+'[4]LCT-4'!GI42+'[4]LCT-5'!GI42+'[4]LCT-6'!GI42+'[4]LCT-7'!GI42+'[4]LCT-8'!GI42+'[5]TB-1'!GI42+'[5]TB-2'!GI42+'[5]TB-3'!GI42+'[5]TB-4'!GI42+'[5]TB-5'!GI42+'[5]TB-6'!GI42+'[5]TB-7'!GI42+'[5]TB-8'!GI42+'[5]TB-9'!GI42+'[5]TB-10'!GI42+'[6]DSV-1'!GI42+'[6]DSV-2'!GI42+'[6]DSV-3'!GI42+'[7]TUB-1'!GI42+'[7]TUB-2'!GI42+'[8]Barge-1'!GI42+'[8]Barge-2'!GI42+'[8]Barge-3'!GI42 -> 935.26667 | AH13: =(AG13/AG23)*100% -> 0.13407752
A15: =Distribute!L9 -> P_NORTH SANTAN TERMINAL | C15: =Distribute!L42 -> 112234.89 | E15: =Distribute!M42 -> 118656.29 | G15: =Distribute!N42 -> 0 | I15: =SUM(C15,E15,G15) -> 230891.18 | J15: =(I15/I23)*100% -> 0.2786647 | L15: ='[2]AHTS-1'!GJ42+'[2]AHTS-2'!GJ42+'[2]AHTS-3'!GJ42+'[2]AHTS-4'!GJ42+'[2]AHTS-5'!GJ42+'[2]AHTS-6'!GJ42+'[2]AHTS-7'!GJ42+'[2]AHTS-8'!GJ42+'[3]CB-1'!GJ42+'[3]CB-2'!GJ42+'[3]CB-3'!GJ42+'[3]CB-4'!GJ42+'[3]CB-5'!GJ42+'[3]CB-6'!GJ42+'[3]CB-7'!GJ42+'[3]CB-8'!GJ42+'[3]CB-9'!GJ42+'[3]CB-10'!GJ42+'[3]CB-11'!GJ42+'[3]CB-12'!GJ42+'[3]CB-13'!GJ42+'[3]CB-14'!GJ42+'[3]CB-15'!GJ42+'[3]CB-16'!GJ42+'[3]CB-17'!GJ42+'[3]CB-18'!GJ42+'[3]CB-19'!GJ42+'[3]CB-20'!GJ42+'[3]CB-21'!GJ42+'[3]CB-22'!GJ42+'[3]CB-23'!GJ42+'[3]CB-24'!GJ42+'[4]LCT-1'!GJ42+'[4]LCT-2'!GJ42+'[4]LCT-3'!GJ42+'[4]LCT-4'!GJ42+'[4]LCT-5'!GJ42+'[4]LCT-6'!GJ42+'[4]LCT-7'!GJ42+'[4]LCT-8'!GJ42+'[5]TB-1'!GJ42+'[5]TB-2'!GJ42+'[5]TB-3'!GJ42+'[5]TB-4'!GJ42+'[5]TB-5'!GJ42+'[5]TB-6'!GJ42+'[5]TB-7'!GJ42+'[5]TB-8'!GJ42+'[5]TB-9'!GJ42+'[5]TB-10'!GJ42+'[6]DSV-1'!GJ42+'[6]DSV-2'!GJ42+'[6]DSV-3'!GJ42+'[7]TUB-1'!GJ42+'[7]TUB-2'!GJ42+'[8]Barge-1'!GJ42+'[8]Barge-2'!GJ42+'[8]Barge-3'!GJ42+'[8]Barge-4'!GJ42 -> 1562.5667 | M15: =(L15/L23)*100% -> 0.2240057 | V15: =A15 -> P_NORTH SANTAN TERMINAL | X15: =Distribute!AL42 -> 1.7709971e+09 | Z15: =Distribute!AM42 -> 1.8725665e+09 | AB15: =Distribute!AN42 -> 0 | AD15: =SUM(X15,Z15,AB15) -> 3.6435636e+09 | AE15: =(AD15/AD23)*100% -> 0.2787155 | AG15: ='[2]AHTS-1'!GJ42+'[2]AHTS-2'!GJ42+'[2]AHTS-3'!GJ42+'[2]AHTS-4'!GJ42+'[2]AHTS-5'!GJ42+'[2]AHTS-6'!GJ42+'[2]AHTS-7'!GJ42+'[2]AHTS-8'!GJ42+'[3]CB-1'!GJ42+'[3]CB-2'!GJ42+'[3]CB-3'!GJ42+'[3]CB-4'!GJ42+'[3]CB-5'!GJ42+'[3]CB-6'!GJ42+'[3]CB-7'!GJ42+'[3]CB-8'!GJ42+'[3]CB-9'!GJ42+'[3]CB-10'!GJ42+'[3]CB-11'!GJ42+'[3]CB-12'!GJ42+'[3]CB-13'!GJ42+'[3]CB-14'!GJ42+'[3]CB-15'!GJ42+'[3]CB-16'!GJ42+'[3]CB-17'!GJ42+'[3]CB-18'!GJ42+'[3]CB-19'!GJ42+'[3]CB-20'!GJ42+'[3]CB-21'!GJ42+'[3]CB-22'!GJ42+'[3]CB-23'!GJ42+'[3]CB-24'!GJ42+'[4]LCT-1'!GJ42+'[4]LCT-2'!GJ42+'[4]LCT-3'!GJ42+'[4]LCT-4'!GJ42+'[4]LCT-5'!GJ42+'[4]LCT-6'!GJ42+'[4]LCT-7'!GJ42+'[4]LCT-8'!GJ42+'[5]TB-1'!GJ42+'[5]TB-2'!GJ42+'[5]TB-3'!GJ42+'[5]TB-4'!GJ42+'[5]TB-5'!GJ42+'[5]TB-6'!GJ42+'[5]TB-7'!GJ42+'[5]TB-8'!GJ42+'[5]TB-9'!GJ42+'[5]TB-10'!GJ42+'[6]DSV-1'!GJ42+'[6]DSV-2'!GJ42+'[6]DSV-3'!GJ42+'[7]TUB-1'!GJ42+'[7]TUB-2'!GJ42+'[8]Barge-1'!GJ42+'[8]Barge-2'!GJ42+'[8]Barge-3'!GJ42 -> 1562.5667 | AH15: =(AG15/AG23)*100% -> 0.2240057
A17: =Distribute!O9 -> P_NORTH SECURITY PATROL | C17: =Distribute!O42 -> 1302.6383 | E17: =Distribute!P42 -> 8357.905 | G17: =Distribute!Q42 -> 0 | I17: =SUM(C17,E17,G17) -> 9660.5434 | J17: =(I17/I23)*100% -> 0.011659399 | L17: ='[2]AHTS-1'!GK42+'[2]AHTS-2'!GK42+'[2]AHTS-3'!GK42+'[2]AHTS-4'!GK42+'[2]AHTS-5'!GK42+'[2]AHTS-6'!GK42+'[2]AHTS-7'!GK42+'[2]AHTS-8'!GK42+'[3]CB-1'!GK42+'[3]CB-2'!GK42+'[3]CB-3'!GK42+'[3]CB-4'!GK42+'[3]CB-5'!GK42+'[3]CB-6'!GK42+'[3]CB-7'!GK42+'[3]CB-8'!GK42+'[3]CB-9'!GK42+'[3]CB-10'!GK42+'[3]CB-11'!GK42+'[3]CB-12'!GK42+'[3]CB-13'!GK42+'[3]CB-14'!GK42+'[3]CB-15'!GK42+'[3]CB-16'!GK42+'[3]CB-17'!GK42+'[3]CB-18'!GK42+'[3]CB-19'!GK42+'[3]CB-20'!GK42+'[3]CB-21'!GK42+'[3]CB-22'!GK42+'[3]CB-23'!GK42+'[3]CB-24'!GK42+'[4]LCT-1'!GK42+'[4]LCT-2'!GK42+'[4]LCT-3'!GK42+'[4]LCT-4'!GK42+'[4]LCT-5'!GK42+'[4]LCT-6'!GK42+'[4]LCT-7'!GK42+'[4]LCT-8'!GK42+'[5]TB-1'!GK42+'[5]TB-2'!GK42+'[5]TB-3'!GK42+'[5]TB-4'!GK42+'[5]TB-5'!GK42+'[5]TB-6'!GK42+'[5]TB-7'!GK42+'[5]TB-8'!GK42+'[5]TB-9'!GK42+'[5]TB-10'!GK42+'[6]DSV-1'!GK42+'[6]DSV-2'!GK42+'[6]DSV-3'!GK42+'[7]TUB-1'!GK42+'[7]TUB-2'!GK42+'[8]Barge-1'!GK42+'[8]Barge-2'!GK42+'[8]Barge-3'!GK42+'[8]Barge-4'!GK42 -> 243.33333 | M17: =(L17/L23)*100% -> 0.034883665 | V17: =A17 -> P_NORTH SECURITY PATROL | X17: =Distribute!AO42 -> 20541903 | Z17: =Distribute!AP42 -> 1.3180556e+08 | AB17: =Distribute!AQ42 -> 0 | AD17: =SUM(X17,Z17,AB17) -> 1.5234746e+08 | AE17: =(AD17/AD23)*100% -> 0.011653865 | AG17: ='[2]AHTS-1'!GK42+'[2]AHTS-2'!GK42+'[2]AHTS-3'!GK42+'[2]AHTS-4'!GK42+'[2]AHTS-5'!GK42+'[2]AHTS-6'!GK42+'[2]AHTS-7'!GK42+'[2]AHTS-8'!GK42+'[3]CB-1'!GK42+'[3]CB-2'!GK42+'[3]CB-3'!GK42+'[3]CB-4'!GK42+'[3]CB-5'!GK42+'[3]CB-6'!GK42+'[3]CB-7'!GK42+'[3]CB-8'!GK42+'[3]CB-9'!GK42+'[3]CB-10'!GK42+'[3]CB-11'!GK42+'[3]CB-12'!GK42+'[3]CB-13'!GK42+'[3]CB-14'!GK42+'[3]CB-15'!GK42+'[3]CB-16'!GK42+'[3]CB-17'!GK42+'[3]CB-18'!GK42+'[3]CB-19'!GK42+'[3]CB-20'!GK42+'[3]CB-21'!GK42+'[3]CB-22'!GK42+'[3]CB-23'!GK42+'[3]CB-24'!GK42+'[4]LCT-1'!GK42+'[4]LCT-2'!GK42+'[4]LCT-3'!GK42+'[4]LCT-4'!GK42+'[4]LCT-5'!GK42+'[4]LCT-6'!GK42+'[4]LCT-7'!GK42+'[4]LCT-8'!GK42+'[5]TB-1'!GK42+'[5]TB-2'!GK42+'[5]TB-3'!GK42+'[5]TB-4'!GK42+'[5]TB-5'!GK42+'[5]TB-6'!GK42+'[5]TB-7'!GK42+'[5]TB-8'!GK42+'[5]TB-9'!GK42+'[5]TB-10'!GK42+'[6]DSV-1'!GK42+'[6]DSV-2'!GK42+'[6]DSV-3'!GK42+'[7]TUB-1'!GK42+'[7]TUB-2'!GK42+'[8]Barge-1'!GK42+'[8]Barge-2'!GK42+'[8]Barge-3'!GK42 -> 243.33333 | AH17: =(AG17/AG23)*100% -> 0.034883665
A19: =Distribute!R9 -> P_SOUTH | C19: =Distribute!R42 -> 141824.9 | E19: =Distribute!S42 -> 168270.28 | G19: =Distribute!T42 -> 0 | I19: =SUM(C19,E19,G19) -> 310095.17 | J19: =(I19/I23)*100% -> 0.37425674 | L19: ='[2]AHTS-1'!GL42+'[2]AHTS-2'!GL42+'[2]AHTS-3'!GL42+'[2]AHTS-4'!GL42+'[2]AHTS-5'!GL42+'[2]AHTS-6'!GL42+'[2]AHTS-7'!GL42+'[2]AHTS-8'!GL42+'[3]CB-1'!GL42+'[3]CB-2'!GL42+'[3]CB-3'!GL42+'[3]CB-4'!GL42+'[3]CB-5'!GL42+'[3]CB-6'!GL42+'[3]CB-7'!GL42+'[3]CB-8'!GL42+'[3]CB-9'!GL42+'[3]CB-10'!GL42+'[3]CB-11'!GL42+'[3]CB-12'!GL42+'[3]CB-13'!GL42+'[3]CB-14'!GL42+'[3]CB-15'!GL42+'[3]CB-16'!GL42+'[3]CB-17'!GL42+'[3]CB-18'!GL42+'[3]CB-19'!GL42+'[3]CB-20'!GL42+'[3]CB-21'!GL42+'[3]CB-22'!GL42+'[3]CB-23'!GL42+'[3]CB-24'!GL42+'[4]LCT-1'!GL42+'[4]LCT-2'!GL42+'[4]LCT-3'!GL42+'[4]LCT-4'!GL42+'[4]LCT-5'!GL42+'[4]LCT-6'!GL42+'[4]LCT-7'!GL42+'[4]LCT-8'!GL42+'[5]TB-1'!GL42+'[5]TB-2'!GL42+'[5]TB-3'!GL42+'[5]TB-4'!GL42+'[5]TB-5'!GL42+'[5]TB-6'!GL42+'[5]TB-7'!GL42+'[5]TB-8'!GL42+'[5]TB-9'!GL42+'[5]TB-10'!GL42+'[6]DSV-1'!GL42+'[6]DSV-2'!GL42+'[6]DSV-3'!GL42+'[7]TUB-1'!GL42+'[7]TUB-2'!GL42+'[8]Barge-1'!GL42+'[8]Barge-2'!GL42+'[8]Barge-3'!GL42+'[8]Barge-4'!GL42 -> 3202 | M19: =(L19/L23)*100% -> 0.45903081 | V19: =A19 -> P_SOUTH | X19: =Distribute!AR42 -> 2.2364251e+09 | Z19: =Distribute!AS42 -> 2653700000 | AB19: =Distribute!AT42 -> 0 | AD19: =SUM(X19,Z19,AB19) -> 4.8901251e+09 | AE19: =(AD19/AD23)*100% -> 0.3740716 | AG19: ='[2]AHTS-1'!GL42+'[2]AHTS-2'!GL42+'[2]AHTS-3'!GL42+'[2]AHTS-4'!GL42+'[2]AHTS-5'!GL42+'[2]AHTS-6'!GL42+'[2]AHTS-7'!GL42+'[2]AHTS-8'!GL42+'[3]CB-1'!GL42+'[3]CB-2'!GL42+'[3]CB-3'!GL42+'[3]CB-4'!GL42+'[3]CB-5'!GL42+'[3]CB-6'!GL42+'[3]CB-7'!GL42+'[3]CB-8'!GL42+'[3]CB-9'!GL42+'[3]CB-10'!GL42+'[3]CB-11'!GL42+'[3]CB-12'!GL42+'[3]CB-13'!GL42+'[3]CB-14'!GL42+'[3]CB-15'!GL42+'[3]CB-16'!GL42+'[3]CB-17'!GL42+'[3]CB-18'!GL42+'[3]CB-19'!GL42+'[3]CB-20'!GL42+'[3]CB-21'!GL42+'[3]CB-22'!GL42+'[3]CB-23'!GL42+'[3]CB-24'!GL42+'[4]LCT-1'!GL42+'[4]LCT-2'!GL42+'[4]LCT-3'!GL42+'[4]LCT-4'!GL42+'[4]LCT-5'!GL42+'[4]LCT-6'!GL42+'[4]LCT-7'!GL42+'[4]LCT-8'!GL42+'[5]TB-1'!GL42+'[5]TB-2'!GL42+'[5]TB-3'!GL42+'[5]TB-4'!GL42+'[5]TB-5'!GL42+'[5]TB-6'!GL42+'[5]TB-7'!GL42+'[5]TB-8'!GL42+'[5]TB-9'!GL42+'[5]TB-10'!GL42+'[6]DSV-1'!GL42+'[6]DSV-2'!GL42+'[6]DSV-3'!GL42+'[7]TUB-1'!GL42+'[7]TUB-2'!GL42+'[8]Barge-1'!GL42+'[8]Barge-2'!GL42+'[8]Barge-3'!GL42 -> 3202 | AH19: =(AG19/AG23)*100% -> 0.45903081
A21: =Distribute!U9 -> P_SOUTH SECURITY PATROL | C21: =Distribute!U42 -> 0 | E21: =Distribute!V42 -> 0 | G21: =Distribute!W42 -> 0 | I21: =SUM(C21,E21,G21) -> 0 | J21: =(I21/I23)*100% -> 0 | L21: ='[2]AHTS-1'!GM42+'[2]AHTS-2'!GM42+'[2]AHTS-3'!GM42+'[2]AHTS-4'!GM42+'[2]AHTS-5'!GM42+'[2]AHTS-6'!GM42+'[2]AHTS-7'!GM42+'[2]AHTS-8'!GM42+'[3]CB-1'!GM42+'[3]CB-2'!GM42+'[3]CB-3'!GM42+'[3]CB-4'!GM42+'[3]CB-5'!GM42+'[3]CB-6'!GM42+'[3]CB-7'!GM42+'[3]CB-8'!GM42+'[3]CB-9'!GM42+'[3]CB-10'!GM42+'[3]CB-11'!GM42+'[3]CB-12'!GM42+'[3]CB-13'!GM42+'[3]CB-14'!GM42+'[3]CB-15'!GM42+'[3]CB-16'!GM42+'[3]CB-17'!GM42+'[3]CB-18'!GM42+'[3]CB-19'!GM42+'[3]CB-20'!GM42+'[3]CB-21'!GM42+'[3]CB-22'!GM42+'[3]CB-23'!GM42+'[3]CB-24'!GM42+'[4]LCT-1'!GM42+'[4]LCT-2'!GM42+'[4]LCT-3'!GM42+'[4]LCT-4'!GM42+'[4]LCT-5'!GM42+'[4]LCT-6'!GM42+'[4]LCT-7'!GM42+'[4]LCT-8'!GM42+'[5]TB-1'!GM42+'[5]TB-2'!GM42+'[5]TB-3'!GM42+'[5]TB-4'!GM42+'[5]TB-5'!GM42+'[5]TB-6'!GM42+'[5]TB-7'!GM42+'[5]TB-8'!GM42+'[5]TB-9'!GM42+'[5]TB-10'!GM42+'[6]DSV-1'!GM42+'[6]DSV-2'!GM42+'[6]DSV-3'!GM42+'[7]TUB-1'!GM42+'[7]TUB-2'!GM42+'[8]Barge-1'!GM42+'[8]Barge-2'!GM42+'[8]Barge-3'!GM42+'[8]Barge-4'!GM42 -> 0 | M21: =(L21/L23)*100% -> 0 | V21: =A21 -> P_SOUTH SECURITY PATROL | X21: =Distribute!AU42 -> 0 | Z21: =Distribute!AV42 -> 0 | AB21: =Distribute!AW42 -> 0 | AD21: =SUM(X21,Z21,AB21) -> 0 | AE21: =(AD21/AD23)*100% -> 0 | AG21: ='[2]AHTS-1'!GM42+'[2]AHTS-2'!GM42+'[2]AHTS-3'!GM42+'[2]AHTS-4'!GM42+'[2]AHTS-5'!GM42+'[2]AHTS-6'!GM42+'[2]AHTS-7'!GM42+'[2]AHTS-8'!GM42+'[3]CB-1'!GM42+'[3]CB-2'!GM42+'[3]CB-3'!GM42+'[3]CB-4'!GM42+'[3]CB-5'!GM42+'[3]CB-6'!GM42+'[3]CB-7'!GM42+'[3]CB-8'!GM42+'[3]CB-9'!GM42+'[3]CB-10'!GM42+'[3]CB-11'!GM42+'[3]CB-12'!GM42+'[3]CB-13'!GM42+'[3]CB-14'!GM42+'[3]CB-15'!GM42+'[3]CB-16'!GM42+'[3]CB-17'!GM42+'[3]CB-18'!GM42+'[3]CB-19'!GM42+'[3]CB-20'!GM42+'[3]CB-21'!GM42+'[3]CB-22'!GM42+'[3]CB-23'!GM42+'[3]CB-24'!GM42+'[4]LCT-1'!GM42+'[4]LCT-2'!GM42+'[4]LCT-3'!GM42+'[4]LCT-4'!GM42+'[4]LCT-5'!GM42+'[4]LCT-6'!GM42+'[4]LCT-7'!GM42+'[4]LCT-8'!GM42+'[5]TB-1'!GM42+'[5]TB-2'!GM42+'[5]TB-3'!GM42+'[5]TB-4'!GM42+'[5]TB-5'!GM42+'[5]TB-6'!GM42+'[5]TB-7'!GM42+'[5]TB-8'!GM42+'[5]TB-9'!GM42+'[5]TB-10'!GM42+'[6]DSV-1'!GM42+'[6]DSV-2'!GM42+'[6]DSV-3'!GM42+'[7]TUB-1'!GM42+'[7]TUB-2'!GM42+'[8]Barge-1'!GM42+'[8]Barge-2'!GM42+'[8]Barge-3'!GM42 -> 0 | AH21: =(AG21/AG23)*100% -> 0
A23: TOTAL COST | C23: =SUM(C9:C21) -> 402490.12 | E23: =SUM(E9:E21) -> 426072.58 | G23: =SUM(G9:G21) -> 0 | I23: =SUM(I9:I21) -> 828562.7 | J23: =SUM(J9,J11,J13,J15,J17,J19,J21) -> 1 | L23: =SUM(L9,L11,L13,L15,L17,L19,L21) -> 6975.5667 | M23: =SUM(M9,M11,M13,M15,M17,M19,M21) -> 1 | V23: TOTAL COST | X23: =SUM(X9:X21) -> 6.3503017e+09 | Z23: =SUM(Z9:Z21) -> 6.7223964e+09 | AB23: =SUM(AB9:AB21) -> 0 | AD23: =SUM(AD9:AD21) -> 1.3072698e+10 | AE23: =SUM(AE9,AE11,AE13,AE15,AE17,AE19,AE21) -> 1 | AG23: =SUM(AG9,AG11,AG13,AG15,AG17,AG19,AG21) -> 6975.5667 | AH23: =SUM(AH9,AH11,AH13,AH15,AH17,AH19,AH21) -> 1
D26: Summary | I26: Daily Boat Cost Distribution to each Operations Area | O26: Operations Boat Cost Analysis | Y26: Summary | AD26: Daily Boat Cost Distribution to each Operations Area | AJ26: Operations Boat Cost Analysis
A46: =L5 -> 25 Nov - 24 Dec 2025 | C46: Fuel (liter)
A47: =A9 -> - | C47: =Distribute!C82 -> 0
A48: =A11 -> P_NORTH ATTAKA | C48: =Distribute!F82 -> 47315.004
A49: =A13 -> P_NORTH NIB | C49: =Distribute!I82 -> 96482.992
A50: =A15 -> P_NORTH SANTAN TERMINAL | C50: =Distribute!L82 -> 109659.26
A51: =A17 -> P_NORTH SECURITY PATROL | C51: =Distribute!O82 -> 1271.9444
A52: =A19 -> P_SOUTH | C52: =Distribute!R82 -> 138478.33
A53: =A21 -> P_SOUTH SECURITY PATROL | C53: =Distribute!U82 -> 0
A54: TOTAL (liter) | C54: =SUM(C47:C53) -> 393207.53

Sheet Distribute
D8: 1 | G8: 2 | J8: 3 | M8: 4 | P8: 5 | S8: 6 | V8: 7 | AD8: 1 | AG8: 2 | AJ8: 3 | AM8: 4 | AP8: 5 | AS8: 6 | AV8: 7
C9: =[1]Control!$HE$10 -> - | F9: =[1]Control!$HF$10 -> P_NORTH ATTAKA | I9: =[1]Control!$HG$10 -> P_NORTH NIB | L9: =[1]Control!$HH$10 -> P_NORTH SANTAN TERMINAL | O9: =[1]Control!$HI$10 -> P_NORTH SECURITY PATROL | R9: =[1]Control!$HJ$10 -> P_SOUTH | U9: =[1]Control!$HK$10 -> P_SOUTH SECURITY PATROL | AC9: =[1]Control!$HE$10 -> - | AF9: =[1]Control!$HF$10 -> P_NORTH ATTAKA | AI9: =[1]Control!$HG$10 -> P_NORTH NIB | AL9: =[1]Control!$HH$10 -> P_NORTH SANTAN TERMINAL | AO9: =[1]Control!$HI$10 -> P_NORTH SECURITY PATROL | AR9: =[1]Control!$HJ$10 -> P_SOUTH | AU9: =[1]Control!$HK$10 -> P_SOUTH SECURITY PATROL
A10: DATE | C10: FUEL | D10: DAYRATE | E10: MOB / DEMOB | F10: FUEL | G10: DAYRATE | H10: MOB / DEMOB | I10: FUEL | J10: DAYRATE | K10: MOB / DEMOB | L10: FUEL | M10: DAYRATE | N10: MOB / DEMOB | O10: FUEL | P10: DAYRATE | Q10: MOB / DEMOB | R10: FUEL | S10: DAYRATE | T10: MOB / DEMOB | U10: FUEL | V10: DAYRATE | W10: MOB / DEMOB | AA10: DATE | AC10: FUEL | AD10: DAYRATE | AE10: MOB / DEMOB | AF10: FUEL | AG10: DAYRATE | AH10: MOB / DEMOB | AI10: FUEL | AJ10: DAYRATE | AK10: MOB / DEMOB | AL10: FUEL | AM10: DAYRATE | AN10: MOB / DEMOB | AO10: FUEL | AP10: DAYRATE | AQ10: MOB / DEMOB | AR10: FUEL | AS10: DAYRATE | AT10: MOB / DEMOB | AU10: FUEL | AV10: DAYRATE | AW10: MOB / DEMOB
