Workbook
Name IDS: "Rectangle 3"

Sheet Summary
A3: MARINE | C3: 2023 YTD
C4: Biaya Sewa Kapal (IDR) | D4: Biaya BBM Kapal (IDR) | E4: Konsumsi BBM Kapal (liter) | F4: Jasa Pendukung Marine (IDR)
B5: Anggaran
B6: Aktual | C6: ='Marine YTD 2023'!Q35 -> 0 | D6: ='Marine YTD 2023'!O35 -> 0 | E6: ='Marine YTD 2023'!M35 -> 0
C7: Vessel Charter Hire (USD) | D7: Vesel Fuel Cost (USD) | E7: Vessel Fuel Consumption (liter) | F7: Other Marine Services (USD)
B8: Budget | E8: =E5 -> 0 | F8: =F5/15600 -> 0
B9: Actual | C9: ='Marine YTD 2023'!G35 -> 0 | D9: ='Marine YTD 2023'!E35 -> 0 | E9: =E6 -> 0
B10: % | C10: =C9/C8 -> #DIV/0! | D10: =D9/D8 -> #DIV/0! | E10: =E9/E8 -> #DIV/0! | F10: =F9/F8 -> #DIV/0!
B11: % all exclude liter | C11: =(C9+D9+F9)/(C8+D8+F8) -> #DIV/0!
A15: MOORING | C15: 2023 YTD
C16: Biaya Sewa Kapal (IDR) | D16: Biaya BBM Kapal (IDR) | E16: Konsumsi BBM Kapal (liter)
B17: Anggaran
B18: Aktual | C18: ='Mooring YTD 2023'!R35 -> 0 | D18: ='Mooring YTD 2023'!P35 -> 0 | E18: ='Mooring YTD 2023'!N35 -> 0
C19: Vessel Charter Hire (USD) | D19: Vesel Fuel Cost (USD) | E19: Vessel Fuel Consumption (liter)
B20: Budget | E20: =E17 -> 0
B21: Actual | C21: ='Mooring YTD 2023'!G35 -> 0 | D21: ='Mooring YTD 2023'!E35 -> 0 | E21: =E18 -> 0
B22: % | C22: =C21/C20 -> #DIV/0! | D22: =D21/D20 -> #DIV/0! | E22: =E21/E20 -> #DIV/0!
B23: % all exclude liter | C23: =(C21+D21+F21)/(C20+D20+F20) -> #DIV/0!
A27: SECURITY PATROL | C27: 2023 YTD
C28: Biaya Sewa Kapal (IDR) | D28: Biaya BBM Kapal (IDR) | E28: Konsumsi BBM Kapal (liter)
B29: Anggaran
B30: Aktual | C30: ='Security Patrol YTD 2023'!R35 -> 0 | D30: ='Security Patrol YTD 2023'!P35 -> 0 | E30: ='Security Patrol'!N35 -> 0
C31: Vessel Charter Hire (USD) | D31: Vesel Fuel Cost (USD) | E31: Vessel Fuel Consumption (liter)
B32: Budget | E32: =E29 -> 0
B33: Actual | C33: ='Security Patrol YTD 2023'!G35 -> 0 | D33: ='Security Patrol YTD 2023'!E35 -> 0 | E33: =E30 -> 0
B34: % | C34: =C33/C32 -> #DIV/0! | D34: =D33/D32 -> #DIV/0! | E34: =E33/E32 -> #DIV/0!
B35: % all exclude liter | C35: =(C33+D33+F33)/(C32+D32+F32) -> #DIV/0!

Sheet Marine YTD 2023
C2: OPERATION (PRODUCTION SOUTH, NORTH, ATTAKA, NIB AND LOGISTICS) | M2: OPERATION (PRODUCTION SOUTH, NORTH, ATTAKA, NIB AND LOGISTICS)
A3: DATE | C3: Actual Vessel Fuel (Liters) | D3: Budget Vessel Fuel (Liters) | E3: Actual Vessel Fuel (USD) | F3: Budget Vessel Fuel (USD) | G3: Actual Vessel Charter (USD) | H3: Budget Vessel Charter (USD) | K3: DATE | M3: Actual Vessel Fuel (Liters) | N3: Budget Vessel Fuel (Liters) | O3: Actual Vessel Fuel (IDR) | P3: Budget Vessel Fuel (IDR) | Q3: Actual Vessel Charter (IDR) | R3: Budget Vessel Charter (IDR)
A4: 44920 | K4: =A4 -> 44920
A5: 44921 | K5: =A5 -> 44921
A6: 44922 | K6: =A6 -> 44922
A7: 44923 | K7: =A7 -> 44923
A8: 44924 | K8: =A8 -> 44924
A9: 44925 | K9: =A9 -> 44925
A10: 44926 | K10: =A10 -> 44926
A11: 44927 | K11: =A11 -> 44927
A12: 44928 | K12: =A12 -> 44928
A13: 44929 | K13: =A13 -> 44929
A14: 44930 | K14: =A14 -> 44930
A15: 44931 | K15: =A15 -> 44931
... A34: 44950 | K34: =A34 -> 44950
A35: SUM | C35: =SUM(C4:C34) -> 0 | D35: =SUM(D4:D34) -> 0 | E35: =SUM(E4:E34) -> 0 | F35: =SUM(F4:F34) -> 0 | G35: =SUM(G4:G34) -> 0 | H35: =SUM(H4:H34) -> 0 | K35: Jumlah | M35: =SUM(M4:M34) -> 0 | N35: =SUM(N4:N34) -> 0 | O35: =SUM(O4:O34) -> 0 | P35: =SUM(P4:P34) -> 0 | Q35: =SUM(Q4:Q34) -> 0 | R35: =SUM(R4:R34) -> 0
A36: This Month Daily AVG | C36: =AVERAGE(C4:C34) -> #DIV/0! | D36: =AVERAGE(D4:D34) -> #DIV/0! | E36: =AVERAGE(E4:E34) -> #DIV/0! | F36: =AVERAGE(F4:F34) -> #DIV/0! | G36: =AVERAGE(G4:G34) -> #DIV/0! | H36: =AVERAGE(H4:H34) -> #DIV/0! | K36: Rata-rata perhari | M36: =AVERAGE(M4:M34) -> #DIV/0! | N36: =AVERAGE(N4:N34) -> #DIV/0! | O36: =AVERAGE(O4:O34) -> #DIV/0! | P36: =AVERAGE(P4:P34) -> #DIV/0! | Q36: =AVERAGE(Q4:Q34) -> #DIV/0! | R36: =AVERAGE(R4:R34) -> #DIV/0!
C37: BBM (ltr) | E37: BBM (USD) | G37: CHARTER (USD) | M37: BBM (ltr) | O37: BBM (IDR) | Q37: CHARTER (IDR)
A38: Difference | C38: =D35-C35 -> 0 | E38: =F35-E35 -> 0 | G38: =H35-G35 -> 0 | K38: Selisih | M38: =N35-M35 -> 0 | O38: =P35-O35 -> 0 | Q38: =R35-Q35 -> 0

Sheet Mooring YTD 2023
C2: P_NORTH SANTAN TERMINAL | N2: P_NORTH SANTAN TERMINAL
A3: DATE | C3: Actual Vessel Fuel (Ltr) | D3: Budget Vessel Fuel (Ltr) | E3: Actual Vessel Fuel (USD) | F3: Budget Vessel Fuel (USD) | G3: Actual Vessel Charter (USD) | H3: Budget Vessel Charter (USD) | L3: DATE | N3: Actual Vessel Fuel (Ltr) | O3: Budget Vessel Fuel (Ltr) | P3: Actual Vessel Fuel (IDR) | Q3: Budget Vessel Fuel (IDR) | R3: Actual Vessel Charter (IDR) | S3: Budget Vessel Charter (IDR)
A4: 44920 | L4: =A4 -> 44920
A5: 44921 | L5: =A5 -> 44921
A6: 44922 | L6: =A6 -> 44922
A7: 44923 | L7: =A7 -> 44923
A8: 44924 | L8: =A8 -> 44924
A9: 44925 | L9: =A9 -> 44925
A10: 44926 | L10: =A10 -> 44926
A11: 44927 | L11: =A11 -> 44927
A12: 44928 | L12: =A12 -> 44928
A13: 44929 | L13: =A13 -> 44929
A14: 44930 | L14: =A14 -> 44930
A15: 44931 | L15: =A15 -> 44931
... A34: 44950 | L34: =A34 -> 44950
A35: SUM | C35: =SUM(C4:C34) -> 0 | D35: =SUM(D4:D34) -> 0 | E35: =SUM(E4:E34) -> 0 | F35: =SUM(F4:F34) -> 0 | G35: =SUM(G4:G34) -> 0 | H35: =SUM(H4:H34) -> 0 | L35: Jumlah | M35: =SUM(M4:M34) -> 0 | N35: =SUM(N4:N34) -> 0 | O35: =SUM(O4:O34) -> 0 | P35: =SUM(P4:P34) -> 0 | Q35: =SUM(Q4:Q34) -> 0 | R35: =SUM(R4:R34) -> 0 | S35: =SUM(S4:S34) -> 0
A36: This Month Daily AVG | C36: =AVERAGE(C4:C34) -> #DIV/0! | D36: =AVERAGE(D4:D34) -> #DIV/0! | E36: =AVERAGE(E4:E34) -> #DIV/0! | F36: =AVERAGE(F4:F34) -> #DIV/0! | G36: =AVERAGE(G4:G34) -> #DIV/0! | H36: =AVERAGE(H4:H34) -> #DIV/0! | L36: Rata-rata perhari | N36: =AVERAGE(N4:N34) -> #DIV/0! | O36: =AVERAGE(O4:O34) -> #DIV/0! | P36: =AVERAGE(P4:P34) -> #DIV/0! | Q36: =AVERAGE(Q4:Q34) -> #DIV/0! | R36: =AVERAGE(R4:R34) -> #DIV/0! | S36: =AVERAGE(S4:S34) -> #DIV/0!
C37: BBM (ltr) | E37: BBM (USD) | G37: Charter (USD) | N37: BBM (ltr) | P37: BBM (IDR) | R37: Charter (IDR)
A38: Difference | C38: =D35-C35 -> 0 | E38: =F35-E35 -> 0 | G38: =H35-G35 -> 0 | L38: Selisih | N38: =O35-N35 -> 0 | P38: =Q35-P35 -> 0 | R38: =S35-R35 -> 0

Sheet Security Patrol YTD 2023
C2: P_NORTH AND P_SOUTH SECURITY PATROL | N2: P_NORTH AND P_SOUTH SECURITY PATROL
A3: DATE | C3: Actual Vessel Fuel (Ltr) | D3: Budget Vessel Fuel (Ltr) | E3: Actual Vessel Fuel (USD) | F3: Budget Vessel Fuel (USD) | G3: Actual Vessel Charter (USD) | H3: Budget Vessel Charter (USD) | L3: DATE | N3: Actual Vessel Fuel (Ltr) | O3: Budget Vessel Fuel (Ltr) | P3: Actual Vessel Fuel (IDR) | Q3: Budget Vessel Fuel (IDR) | R3: Actual Vessel Charter (IDR) | S3: Budget Vessel Charter (IDR)
A4: 44920 | L4: =A4 -> 44920
A5: 44921 | L5: =A5 -> 44921
A6: 44922 | L6: =A6 -> 44922
A7: 44923 | L7: =A7 -> 44923
A8: 44924 | L8: =A8 -> 44924
A9: 44925 | L9: =A9 -> 44925
A10: 44926 | L10: =A10 -> 44926
A11: 44927 | L11: =A11 -> 44927
A12: 44928 | L12: =A12 -> 44928
A13: 44929 | L13: =A13 -> 44929
A14: 44930 | L14: =A14 -> 44930
A15: 44931 | L15: =A15 -> 44931
... A34: 44950 | L34: =A34 -> 44950
A35: SUM | C35: =SUM(C4:C34) -> 0 | D35: =SUM(D4:D34) -> 0 | E35: =SUM(E4:E34) -> 0 | F35: =SUM(F4:F34) -> 0 | G35: =SUM(G4:G34) -> 0 | H35: =SUM(H4:H34) -> 0 | L35: Jumlah | M35: =SUM(M4:M34) -> 0 | N35: =SUM(N4:N34) -> 0 | O35: =SUM(O4:O34) -> 0 | P35: =SUM(P4:P34) -> 0 | Q35: =SUM(Q4:Q34) -> 0 | R35: =SUM(R4:R34) -> 0 | S35: =SUM(S4:S34) -> 0
A36: This Month Daily AVG | C36: =AVERAGE(C4:C34) -> #DIV/0! | D36: =AVERAGE(D4:D34) -> #DIV/0! | E36: =AVERAGE(E4:E34) -> #DIV/0! | F36: =AVERAGE(F4:F34) -> #DIV/0! | G36: =AVERAGE(G4:G34) -> #DIV/0! | H36: =AVERAGE(H4:H34) -> #DIV/0! | L36: Rata-rata perhari | N36: =AVERAGE(N4:N34) -> #DIV/0! | O36: =AVERAGE(O4:O34) -> #DIV/0! | P36: =AVERAGE(P4:P34) -> #DIV/0! | Q36: =AVERAGE(Q4:Q34) -> #DIV/0! | R36: =AVERAGE(R4:R34) -> #DIV/0! | S36: =AVERAGE(S4:S34) -> #DIV/0!
C37: BBM (ltr) | E37: BBM (USD) | G37: Charter (USD) | N37: BBM (ltr) | P37: BBM (IDR) | R37: Charter (IDR)
A38: Difference | C38: =D35-C35 -> 0 | E38: =F35-E35 -> 0 | G38: =H35-G35 -> 0 | L38: Selisih | N38: =O35-N35 -> 0 | P38: =Q35-P35 -> 0 | R38: =S35-R35 -> 0

Sheet Actual Sewa & BBM
D3: Biaya Sewa dan Biaya BBM Kapal
D5: Periode : 2023
H7: Today:
A8: Anggaran Sewa - in IDR | K8: =TODAY() -> 45986
A9: Area | B9: 44927 | C9: 44958 | D9: 44986 | E9: 45017 | F9: 45047 | G9: 45078 | H9: 45108 | I9: 45139 | J9: 45170 | K9: 45200 | L9: 45231 | M9: 45261 | N9: TOTAL
A10: Drilling
A11: Prod. North Attaka
A12: Prod. North NIB
A13: Prod. North Santan
A14: Security Patrol-North
A15: Security Patrol-South
A16: Prod. South
A17: FE&C
A18: Logistics MLS
A19: TOTAL | B19: =SUM(B10:B18) -> 0 | C19: =SUM(C10:C18) -> 0 | D19: =SUM(D10:D18) -> 0 | F19: =SUM(F10:F18) -> 0 | G19: =SUM(G10:G18) -> 0 | H19: =SUM(H10:H18) -> 0 | I19: =SUM(I10:I18) -> 0 | J19: =SUM(J10:J18) -> 0 | K19: =SUM(K10:K18) -> 0 | L19: =SUM(L10:L18) -> 0 | M19: =SUM(M10:M18) -> 0 | N19: =SUM(N10:N18) -> 0
A21: Anggaran BBM - in IDR
A22: Area | B22: 44927 | C22: 44958 | D22: 44986 | E22: 45017 | F22: 45047 | G22: 45078 | H22: 45108 | I22: 45139 | J22: 45170 | K22: 45200 | L22: 45231 | M22: 45261 | N22: TOTAL
A23: Drilling
A24: Prod. North Attaka
A25: Prod. North NIB
A26: Prod. North Santan
A27: Security Patrol-North
A28: Security Patrol-South
A29: Prod. South
A30: FE&C
A31: Logistics MLS
A32: TOTAL | G32: =SUM(G23:G31) -> 0 | H32: =SUM(H23:H31) -> 0 | I32: =SUM(I23:I31) -> 0 | J32: =SUM(J23:J31) -> 0 | K32: =SUM(K23:K31) -> 0 | L32: =SUM(L23:L31) -> 0 | M32: =SUM(M23:M31) -> 0 | N32: =SUM(N23:N31) -> 0
A35: Anggaran Sewa - in USD
A36: Area | B36: 44927 | C36: 44958 | D36: 44986 | E36: 45017 | F36: 45047 | G36: 45078 | H36: 45108 | I36: 45139 | J36: 45170 | K36: 45200 | L36: 45231 | M36: 45261 | N36: TOTAL
A37: Drilling | B37: =SUM('Actual Cost per type'!E67:E79) -> 0
A38: Prod. North Attaka | B38: ='Actual Cost per type'!E87 -> 0
A39: Prod. North NIB | B39: ='Actual Cost per type'!E88 -> 0
A40: Prod. North Santan | B40: ='Actual Cost per type'!E89 -> 0
A41: Security Patrol-North | B41: ='Actual Cost per type'!E90 -> 0
A42: Security Patrol-South | B42: ='Actual Cost per type'!E92 -> 0
A43: Prod. South | B43: ='Actual Cost per type'!E91 -> 0
A44: FE&C | B44: =SUM('Actual Cost per type'!E82:E83) -> 0
A45: Logistics MLS | B45: ='Actual Cost per type'!E94 -> 0
A46: TOTAL | G46: =SUM(G37:G45) -> 0 | H46: =SUM(H37:H45) -> 0 | I46: =SUM(I37:I45) -> 0 | J46: =SUM(J37:J45) -> 0 | K46: =SUM(K37:K45) -> 0 | L46: =SUM(L37:L45) -> 0 | M46: =SUM(M37:M45) -> 0 | N46: =SUM(N37:N45) -> 0
A48: Anggaran BBM - in USD
...

Sheet Marine
C2: OPERATION (PRODUCTION SOUTH, NORTH, ATTAKA, NIB AND LOGISTICS) | M2: OPERATION (PRODUCTION SOUTH, NORTH, ATTAKA, NIB AND LOGISTICS)
A3: DATE | C3: Actual Vessel Fuel (Liters) | D3: Budget Vessel Fuel (Liters) | E3: Actual Vessel Fuel (USD) | F3: Budget Vessel Fuel (USD) | G3: Actual Vessel Charter (USD) | H3: Budget Vessel Charter (USD) | K3: DATE | M3: Actual Vessel Fuel (Liters) | N3: Budget Vessel Fuel (Liters) | O3: Actual Vessel Fuel (IDR) | P3: Budget Vessel Fuel (IDR) | Q3: Actual Vessel Charter (IDR) | R3: Budget Vessel Charter (IDR)
A4: =[1]Control!$AX$11 -> 45986 | C4: =[2]Distribute!F51+[2]Distribute!I51+[2]Distribute!R51+[3]Sheet1!C11 -> 0 | D4: 23022.806 | E4: =[2]Distribute!F11+[2]Distribute!I11+[2]Distribute!R11+[3]Sheet1!D11 -> 0 | F4: 12432.315 | G4: =[2]Distribute!G11+[2]Distribute!J11+[2]Distribute!S11+[3]Sheet1!E11 -> 0 | H4: 14597.984 | K4: =A4 -> 45986 | M4: =[2]Distribute!F51+[2]Distribute!I51+[2]Distribute!R51+[3]Sheet1!H11 -> 0 | N4: =D4 -> 23022.806 | O4: =[2]Distribute!AF11+[2]Distribute!AI11+[2]Distribute!AR11+[3]Sheet1!I11 -> 0 | P4: 1.9394412e+08 | Q4: =[2]Distribute!AG11+[2]Distribute!AJ11+[2]Distribute!AS11+[3]Sheet1!J11 -> 0 | R4: 2.2772854e+08
A5: =[1]Control!AX12 -> 45987 | C5: =[2]Distribute!F52+[2]Distribute!I52+[2]Distribute!R52+[3]Sheet1!C12 -> 0 | D5: 23022.806 | E5: =[2]Distribute!F12+[2]Distribute!I12+[2]Distribute!R12+[3]Sheet1!D12 -> 0 | F5: 12432.315 | G5: =[2]Distribute!G12+[2]Distribute!J12+[2]Distribute!S12+[3]Sheet1!E12 -> 0 | H5: 14597.984 | K5: =A5 -> 45987 | M5: =[2]Distribute!F52+[2]Distribute!I52+[2]Distribute!R52+[3]Sheet1!H12 -> 0 | N5: =D5 -> 23022.806 | O5: =[2]Distribute!AF12+[2]Distribute!AI12+[2]Distribute!AR12+[3]Sheet1!I12 -> 0 | P5: 1.9394412e+08 | Q5: =[2]Distribute!AG12+[2]Distribute!AJ12+[2]Distribute!AS12+[3]Sheet1!J12 -> 0 | R5: 2.2772854e+08
A6: =[1]Control!AX13 -> 45988 | C6: =[2]Distribute!F53+[2]Distribute!I53+[2]Distribute!R53+[3]Sheet1!C13 -> 0 | D6: 23022.806 | E6: =[2]Distribute!F13+[2]Distribute!I13+[2]Distribute!R13+[3]Sheet1!D13 -> 0 | F6: 12432.315 | G6: =[2]Distribute!G13+[2]Distribute!J13+[2]Distribute!S13+[3]Sheet1!E13 -> 0 | H6: 14597.984 | K6: =A6 -> 45988 | M6: =[2]Distribute!F53+[2]Distribute!I53+[2]Distribute!R53+[3]Sheet1!H13 -> 0 | N6: =D6 -> 23022.806 | O6: =[2]Distribute!AF13+[2]Distribute!AI13+[2]Distribute!AR13+[3]Sheet1!I13 -> 0 | P6: 1.9394412e+08 | Q6: =[2]Distribute!AG13+[2]Distribute!AJ13+[2]Distribute!AS13+[3]Sheet1!J13 -> 0 | R6: 2.2772854e+08
A7: =[1]Control!AX14 -> 45989 | C7: =[2]Distribute!F54+[2]Distribute!I54+[2]Distribute!R54+[3]Sheet1!C14 -> 0 | D7: 23022.806 | E7: =[2]Distribute!F14+[2]Distribute!I14+[2]Distribute!R14+[3]Sheet1!D14 -> 0 | F7: 12432.315 | G7: =[2]Distribute!G14+[2]Distribute!J14+[2]Distribute!S14+[3]Sheet1!E14 -> 0 | H7: 14597.984 | K7: =A7 -> 45989 | M7: =[2]Distribute!F54+[2]Distribute!I54+[2]Distribute!R54+[3]Sheet1!H14 -> 0 | N7: =D7 -> 23022.806 | O7: =[2]Distribute!AF14+[2]Distribute!AI14+[2]Distribute!AR14+[3]Sheet1!I14 -> 0 | P7: 1.9394412e+08 | Q7: =[2]Distribute!AG14+[2]Distribute!AJ14+[2]Distribute!AS14+[3]Sheet1!J14 -> 0 | R7: 2.2772854e+08
A8: =[1]Control!AX15 -> 45990 | C8: =[2]Distribute!F55+[2]Distribute!I55+[2]Distribute!R55+[3]Sheet1!C15 -> 0 | D8: 23022.806 | E8: =[2]Distribute!F15+[2]Distribute!I15+[2]Distribute!R15+[3]Sheet1!D15 -> 0 | F8: 12432.315 | G8: =[2]Distribute!G15+[2]Distribute!J15+[2]Distribute!S15+[3]Sheet1!E15 -> 0 | H8: 14597.984 | K8: =A8 -> 45990 | M8: =[2]Distribute!F55+[2]Distribute!I55+[2]Distribute!R55+[3]Sheet1!H15 -> 0 | N8: =D8 -> 23022.806 | O8: =[2]Distribute!AF15+[2]Distribute!AI15+[2]Distribute!AR15+[3]Sheet1!I15 -> 0 | P8: 1.9394412e+08 | Q8: =[2]Distribute!AG15+[2]Distribute!AJ15+[2]Distribute!AS15+[3]Sheet1!J15 -> 0 | R8: 2.2772854e+08
A9: =[1]Control!AX16 -> 45991 | C9: =[2]Distribute!F56+[2]Distribute!I56+[2]Distribute!R56+[3]Sheet1!C16 -> 0 | D9: 23022.806 | E9: =[2]Distribute!F16+[2]Distribute!I16+[2]Distribute!R16+[3]Sheet1!D16 -> 0 | F9: 12432.315 | G9: =[2]Distribute!G16+[2]Distribute!J16+[2]Distribute!S16+[3]Sheet1!E16 -> 0 | H9: 14597.984 | K9: =A9 -> 45991 | M9: =[2]Distribute!F56+[2]Distribute!I56+[2]Distribute!R56+[3]Sheet1!H16 -> 0 | N9: =D9 -> 23022.806 | O9: =[2]Distribute!AF16+[2]Distribute!AI16+[2]Distribute!AR16+[3]Sheet1!I16 -> 0 | P9: 1.9394412e+08 | Q9: =[2]Distribute!AG16+[2]Distribute!AJ16+[2]Distribute!AS16+[3]Sheet1!J16 -> 0 | R9: 2.2772854e+08
A10: =[1]Control!AX17 -> 45992 | C10: =[2]Distribute!F57+[2]Distribute!I57+[2]Distribute!R57+[3]Sheet1!C17 -> 0 | D10: 23022.806 | E10: =[2]Distribute!F17+[2]Distribute!I17+[2]Distribute!R17+[3]Sheet1!D17 -> 0 | F10: 12432.315 | G10: =[2]Distribute!G17+[2]Distribute!J17+[2]Distribute!S17+[3]Sheet1!E17 -> 0 | H10: 14597.984 | K10: =A10 -> 45992 | M10: =[2]Distribute!F57+[2]Distribute!I57+[2]Distribute!R57+[3]Sheet1!H17 -> 0 | N10: =D10 -> 23022.806 | O10: =[2]Distribute!AF17+[2]Distribute!AI17+[2]Distribute!AR17+[3]Sheet1!I17 -> 0 | P10: 1.9394412e+08 | Q10: =[2]Distribute!AG17+[2]Distribute!AJ17+[2]Distribute!AS17+[3]Sheet1!J17 -> 0 | R10: 2.2772854e+08
A11: =[1]Control!AX18 -> 45993 | C11: =[2]Distribute!F58+[2]Distribute!I58+[2]Distribute!R58+[3]Sheet1!C18 -> 0 | D11: 23022.806 | E11: =[2]Distribute!F18+[2]Distribute!I18+[2]Distribute!R18+[3]Sheet1!D18 -> 0 | F11: 12432.315 | G11: =[2]Distribute!G18+[2]Distribute!J18+[2]Distribute!S18+[3]Sheet1!E18 -> 0 | H11: 14597.984 | K11: =A11 -> 45993 | M11: =[2]Distribute!F58+[2]Distribute!I58+[2]Distribute!R58+[3]Sheet1!H18 -> 0 | N11: =D11 -> 23022.806 | O11: =[2]Distribute!AF18+[2]Distribute!AI18+[2]Distribute!AR18+[3]Sheet1!I18 -> 0 | P11: 1.9394412e+08 | Q11: =[2]Distribute!AG18+[2]Distribute!AJ18+[2]Distribute!AS18+[3]Sheet1!J18 -> 0 | R11: 2.2772854e+08
A12: =[1]Control!AX19 -> 45994 | C12: =[2]Distribute!F59+[2]Distribute!I59+[2]Distribute!R59+[3]Sheet1!C19 -> 0 | D12: 23022.806 | E12: =[2]Distribute!F19+[2]Distribute!I19+[2]Distribute!R19+[3]Sheet1!D19 -> 0 | F12: 12432.315 | G12: =[2]Distribute!G19+[2]Distribute!J19+[2]Distribute!S19+[3]Sheet1!E19 -> 0 | H12: 14597.984 | K12: =A12 -> 45994 | M12: =[2]Distribute!F59+[2]Distribute!I59+[2]Distribute!R59+[3]Sheet1!H19 -> 0 | N12: =D12 -> 23022.806 | O12: =[2]Distribute!AF19+[2]Distribute!AI19+[2]Distribute!AR19+[3]Sheet1!I19 -> 0 | P12: 1.9394412e+08 | Q12: =[2]Distribute!AG19+[2]Distribute!AJ19+[2]Distribute!AS19+[3]Sheet1!J19 -> 0 | R12: 2.2772854e+08
A13: =[1]Control!AX20 -> 45995 | C13: =[2]Distribute!F60+[2]Distribute!I60+[2]Distribute!R60+[3]Sheet1!C20 -> 0 | D13: 23022.806 | E13: =[2]Distribute!F20+[2]Distribute!I20+[2]Distribute!R20+[3]Sheet1!D20 -> 0 | F13: 12432.315 | G13: =[2]Distribute!G20+[2]Distribute!J20+[2]Distribute!S20+[3]Sheet1!E20 -> 0 | H13: 14597.984 | K13: =A13 -> 45995 | M13: =[2]Distribute!F60+[2]Distribute!I60+[2]Distribute!R60+[3]Sheet1!H20 -> 0 | N13: =D13 -> 23022.806 | O13: =[2]Distribute!AF20+[2]Distribute!AI20+[2]Distribute!AR20+[3]Sheet1!I20 -> 0 | P13: 1.9394412e+08 | Q13: =[2]Distribute!AG20+[2]Distribute!AJ20+[2]Distribute!AS20+[3]Sheet1!J20 -> 0 | R13: 2.2772854e+08
A14: =[1]Control!AX21 -> 45996 | C14: =[2]Distribute!F61+[2]Distribute!I61+[2]Distribute!R61+[3]Sheet1!C21 -> 0 | D14: 23022.806 | E14: =[2]Distribute!F21+[2]Distribute!I21+[2]Distribute!R21+[3]Sheet1!D21 -> 0 | F14: 12432.315 | G14: =[2]Distribute!G21+[2]Distribute!J21+[2]Distribute!S21+[3]Sheet1!E21 -> 0 | H14: 14597.984 | K14: =A14 -> 45996 | M14: =[2]Distribute!F61+[2]Distribute!I61+[2]Distribute!R61+[3]Sheet1!H21 -> 0 | N14: =D14 -> 23022.806 | O14: =[2]Distribute!AF21+[2]Distribute!AI21+[2]Distribute!AR21+[3]Sheet1!I21 -> 0 | P14: 1.9394412e+08 | Q14: =[2]Distribute!AG21+[2]Distribute!AJ21+[2]Distribute!AS21+[3]Sheet1!J21 -> 0 | R14: 2.2772854e+08
A15: =[1]Control!AX22 -> 45997 | C15: =[2]Distribute!F62+[2]Distribute!I62+[2]Distribute!R62+[3]Sheet1!C22 -> 0 | D15: 23022.806 | E15: =[2]Distribute!F22+[2]Distribute!I22+[2]Distribute!R22+[3]Sheet1!D22 -> 0 | F15: 12432.315 | G15: =[2]Distribute!G22+[2]Distribute!J22+[2]Distribute!S22+[3]Sheet1!E22 -> 0 | H15: 14597.984 | K15: =A15 -> 45997 | M15: =[2]Distribute!F62+[2]Distribute!I62+[2]Distribute!R62+[3]Sheet1!H22 -> 0 | N15: =D15 -> 23022.806 | O15: =[2]Distribute!AF22+[2]Distribute!AI22+[2]Distribute!AR22+[3]Sheet1!I22 -> 0 | P15: 1.9394412e+08 | Q15: =[2]Distribute!AG22+[2]Distribute!AJ22+[2]Distribute!AS22+[3]Sheet1!J22 -> 0 | R15: 2.2772854e+08
A16: =[1]Control!AX23 -> 45998 | C16: =[2]Distribute!F63+[2]Distribute!I63+[2]Distribute!R63+[3]Sheet1!C23 -> 0 | D16: 23022.806 | E16: =[2]Distribute!F23+[2]Distribute!I23+[2]Distribute!R23+[3]Sheet1!D23 -> 0 | F16: 12432.315 | G16: =[2]Distribute!G23+[2]Distribute!J23+[2]Distribute!S23+[3]Sheet1!E23 -> 0 | H16: 14597.984 | K16: =A16 -> 45998 | M16: =[2]Distribute!F63+[2]Distribute!I63+[2]Distribute!R63+[3]Sheet1!H23 -> 0 | N16: =D16 -> 23022.806 | O16: =[2]Distribute!AF23+[2]Distribute!AI23+[2]Distribute!AR23+[3]Sheet1!I23 -> 0 | P16: 1.9394412e+08 | Q16: =[2]Distribute!AG23+[2]Distribute!AJ23+[2]Distribute!AS23+[3]Sheet1!J23 -> 0 | R16: 2.2772854e+08
... A33: =[1]Control!AX40 -> 46015 | C33: =[2]Distribute!F80+[2]Distribute!I80+[2]Distribute!R80+[3]Sheet1!C40 -> 0 | D33: 23022.806 | E33: =[2]Distribute!F40+[2]Distribute!I40+[2]Distribute!R40+[3]Sheet1!D40 -> 0 | F33: 12432.315 | G33: =[2]Distribute!G40+[2]Distribute!J40+[2]Distribute!S40+[3]Sheet1!E40 -> 0 | H33: 14597.984 | K33: =A33 -> 46015 | M33: =[2]Distribute!F80+[2]Distribute!I80+[2]Distribute!R80+[3]Sheet1!H40 -> 0 | N33: =D33 -> 23022.806 | O33: =[2]Distribute!AF40+[2]Distribute!AI40+[2]Distribute!AR40+[3]Sheet1!I40 -> 0 | P33: 1.9394412e+08 | Q33: =[2]Distribute!AG40+[2]Distribute!AJ40+[2]Distribute!AS40+[3]Sheet1!J40 -> 0 | R33: 2.2772854e+08
A34: =[1]Control!AX41 -> - | C34: =[2]Distribute!F81+[2]Distribute!I81+[2]Distribute!R81+[3]Sheet1!C41 -> 0 | E34: =[2]Distribute!F41+[2]Distribute!I41+[2]Distribute!R41+[3]Sheet1!D41 -> 0 | G34: =[2]Distribute!G41+[2]Distribute!J41+[2]Distribute!S41+[3]Sheet1!E41 -> 0 | K34: =A34 -> - | M34: =[2]Distribute!F81+[2]Distribute!I81+[2]Distribute!R81+[3]Sheet1!H41 -> 0 | O34: =[2]Distribute!AF41+[2]Distribute!AI41+[2]Distribute!AR41+[3]Sheet1!I41 -> 0 | Q34: =[2]Distribute!AG41+[2]Distribute!AJ41+[2]Distribute!AS41+[3]Sheet1!J41 -> 0
A35: SUM | C35: =SUM(C4:C34) -> 0 | D35: =SUM(D4:D34) -> 690684.17 | E35: =SUM(E4:E34) -> 0 | F35: =SUM(F4:F34) -> 372969.45 | G35: =SUM(G4:G34) -> 0 | H35: =SUM(H4:H34) -> 437939.51 | K35: Jumlah | M35: =SUM(M4:M34) -> 0 | N35: =SUM(N4:N34) -> 690684.17 | O35: =SUM(O4:O34) -> 0 | P35: =SUM(P4:P34) -> 5.8183235e+09 | Q35: =SUM(Q4:Q34) -> 0 | R35: =SUM(R4:R34) -> 6.8318563e+09
A36: This Month Daily AVG | C36: =AVERAGE(C4:C34) -> 0 | D36: =AVERAGE(D4:D34) -> 23022.806 | E36: =AVERAGE(E4:E34) -> 0 | F36: =AVERAGE(F4:F34) -> 12432.315 | G36: =AVERAGE(G4:G34) -> 0 | H36: =AVERAGE(H4:H34) -> 14597.984 | K36: Rata-rata perhari | M36: =AVERAGE(M4:M34) -> 0 | N36: =AVERAGE(N4:N34) -> 23022.806 | O36: =AVERAGE(O4:O34) -> 0 | P36: =AVERAGE(P4:P34) -> 1.9394412e+08 | Q36: =AVERAGE(Q4:Q34) -> 0 | R36: =AVERAGE(R4:R34) -> 2.2772854e+08
C37: BBM (ltr) | E37: BBM (USD) | G37: CHARTER (USD) | M37: BBM (ltr) | O37: BBM (IDR) | Q37: CHARTER (IDR)
A38: Difference | C38: =D35-C35 -> 690684.17 | E38: =F35-E35 -> 372969.45 | G38: =H35-G35 -> 437939.51 | K38: Selisih | M38: =N35-M35 -> 690684.17 | O38: =P35-O35 -> 5.8183235e+09 | Q38: =R35-Q35 -> 6.8318563e+09

Sheet Mooring
C2: P_NORTH SANTAN TERMINAL | N2: P_NORTH SANTAN TERMINAL
A3: DATE | C3: Actual Vessel Fuel (Ltr) | D3: Budget Vessel Fuel (Ltr) | E3: Actual Vessel Fuel (USD) | F3: Budget Vessel Fuel (USD) | G3: Actual Vessel Charter (USD) | H3: Budget Vessel Charter (USD) | L3: DATE | N3: Actual Vessel Fuel (Ltr) | O3: Budget Vessel Fuel (Ltr) | P3: Actual Vessel Fuel (IDR) | Q3: Budget Vessel Fuel (IDR) | R3: Actual Vessel Charter (IDR) | S3: Budget Vessel Charter (IDR)
A4: =[1]Control!$AX$11 -> 45986 | C4: =[2]Distribute!L51 -> 0 | D4: 3995.0178 | E4: =[2]Distribute!L11 -> 0 | F4: 2157.3096 | G4: =[2]Distribute!M11 -> 0 | H4: 1722.811 | L4: =A4 -> 45986 | N4: =[2]Distribute!L51 -> 0 | O4: 3995.0178 | P4: =[2]Distribute!AL11 -> 0 | Q4: 33654030 | R4: =[2]Distribute!AM11 -> 0 | S4: 26875851
A5: =[1]Control!AX12 -> 45987 | C5: =[2]Distribute!L52 -> 0 | D5: 3995.0178 | E5: =[2]Distribute!L12 -> 0 | F5: 2157.3096 | G5: =[2]Distribute!M12 -> 0 | H5: 1722.811 | L5: =A5 -> 45987 | N5: =[2]Distribute!L52 -> 0 | O5: 3995.0178 | P5: =[2]Distribute!AL12 -> 0 | Q5: 33654030 | R5: =[2]Distribute!AM12 -> 0 | S5: 26875851
A6: =[1]Control!AX13 -> 45988 | C6: =[2]Distribute!L53 -> 0 | D6: 3995.0178 | E6: =[2]Distribute!L13 -> 0 | F6: 2157.3096 | G6: =[2]Distribute!M13 -> 0 | H6: 1722.811 | L6: =A6 -> 45988 | N6: =[2]Distribute!L53 -> 0 | O6: 3995.0178 | P6: =[2]Distribute!AL13 -> 0 | Q6: 33654030 | R6: =[2]Distribute!AM13 -> 0 | S6: 26875851
A7: =[1]Control!AX14 -> 45989 | C7: =[2]Distribute!L54 -> 0 | D7: 3995.0178 | E7: =[2]Distribute!L14 -> 0 | F7: 2157.3096 | G7: =[2]Distribute!M14 -> 0 | H7: 1722.811 | L7: =A7 -> 45989 | N7: =[2]Distribute!L54 -> 0 | O7: 3995.0178 | P7: =[2]Distribute!AL14 -> 0 | Q7: 33654030 | R7: =[2]Distribute!AM14 -> 0 | S7: 26875851
A8: =[1]Control!AX15 -> 45990 | C8: =[2]Distribute!L55 -> 0 | D8: 3995.0178 | E8: =[2]Distribute!L15 -> 0 | F8: 2157.3096 | G8: =[2]Distribute!M15 -> 0 | H8: 1722.811 | L8: =A8 -> 45990 | N8: =[2]Distribute!L55 -> 0 | O8: 3995.0178 | P8: =[2]Distribute!AL15 -> 0 | Q8: 33654030 | R8: =[2]Distribute!AM15 -> 0 | S8: 26875851
A9: =[1]Control!AX16 -> 45991 | C9: =[2]Distribute!L56 -> 0 | D9: 3995.0178 | E9: =[2]Distribute!L16 -> 0 | F9: 2157.3096 | G9: =[2]Distribute!M16 -> 0 | H9: 1722.811 | L9: =A9 -> 45991 | N9: =[2]Distribute!L56 -> 0 | O9: 3995.0178 | P9: =[2]Distribute!AL16 -> 0 | Q9: 33654030 | R9: =[2]Distribute!AM16 -> 0 | S9: 26875851
A10: =[1]Control!AX17 -> 45992 | C10: =[2]Distribute!L57 -> 0 | D10: 3995.0178 | E10: =[2]Distribute!L17 -> 0 | F10: 2157.3096 | G10: =[2]Distribute!M17 -> 0 | H10: 1722.811 | L10: =A10 -> 45992 | N10: =[2]Distribute!L57 -> 0 | O10: 3995.0178 | P10: =[2]Distribute!AL17 -> 0 | Q10: 33654030 | R10: =[2]Distribute!AM17 -> 0 | S10: 26875851
A11: =[1]Control!AX18 -> 45993 | C11: =[2]Distribute!L58 -> 0 | D11: 3995.0178 | E11: =[2]Distribute!L18 -> 0 | F11: 2157.3096 | G11: =[2]Distribute!M18 -> 0 | H11: 1722.811 | L11: =A11 -> 45993 | N11: =[2]Distribute!L58 -> 0 | O11: 3995.0178 | P11: =[2]Distribute!AL18 -> 0 | Q11: 33654030 | R11: =[2]Distribute!AM18 -> 0 | S11: 26875851
A12: =[1]Control!AX19 -> 45994 | C12: =[2]Distribute!L59 -> 0 | D12: 3995.0178 | E12: =[2]Distribute!L19 -> 0 | F12: 2157.3096 | G12: =[2]Distribute!M19 -> 0 | H12: 1722.811 | L12: =A12 -> 45994 | N12: =[2]Distribute!L59 -> 0 | O12: 3995.0178 | P12: =[2]Distribute!AL19 -> 0 | Q12: 33654030 | R12: =[2]Distribute!AM19 -> 0 | S12: 26875851
A13: =[1]Control!AX20 -> 45995 | C13: =[2]Distribute!L60 -> 0 | D13: 3995.0178 | E13: =[2]Distribute!L20 -> 0 | F13: 2157.3096 | G13: =[2]Distribute!M20 -> 0 | H13: 1722.811 | L13: =A13 -> 45995 | N13: =[2]Distribute!L60 -> 0 | O13: 3995.0178 | P13: =[2]Distribute!AL20 -> 0 | Q13: 33654030 | R13: =[2]Distribute!AM20 -> 0 | S13: 26875851
A14: =[1]Control!AX21 -> 45996 | C14: =[2]Distribute!L61 -> 0 | D14: 3995.0178 | E14: =[2]Distribute!L21 -> 0 | F14: 2157.3096 | G14: =[2]Distribute!M21 -> 0 | H14: 1722.811 | L14: =A14 -> 45996 | N14: =[2]Distribute!L61 -> 0 | O14: 3995.0178 | P14: =[2]Distribute!AL21 -> 0 | Q14: 33654030 | R14: =[2]Distribute!AM21 -> 0 | S14: 26875851
A15: =[1]Control!AX22 -> 45997 | C15: =[2]Distribute!L62 -> 0 | D15: 3995.0178 | E15: =[2]Distribute!L22 -> 0 | F15: 2157.3096 | G15: =[2]Distribute!M22 -> 0 | H15: 1722.811 | L15: =A15 -> 45997 | N15: =[2]Distribute!L62 -> 0 | O15: 3995.0178 | P15: =[2]Distribute!AL22 -> 0 | Q15: 33654030 | R15: =[2]Distribute!AM22 -> 0 | S15: 26875851
A16: =[1]Control!AX23 -> 45998 | C16: =[2]Distribute!L63 -> 0 | D16: 3995.0178 | E16: =[2]Distribute!L23 -> 0 | F16: 2157.3096 | G16: =[2]Distribute!M23 -> 0 | H16: 1722.811 | L16: =A16 -> 45998 | N16: =[2]Distribute!L63 -> 0 | O16: 3995.0178 | P16: =[2]Distribute!AL23 -> 0 | Q16: 33654030 | R16: =[2]Distribute!AM23 -> 0 | S16: 26875851
... A33: =[1]Control!AX40 -> 46015 | C33: =[2]Distribute!L80 -> 0 | D33: 3995.0178 | E33: =[2]Distribute!L40 -> 0 | F33: 2157.3096 | G33: =[2]Distribute!M40 -> 0 | H33: 1722.811 | L33: =A33 -> 46015 | N33: =[2]Distribute!L80 -> 0 | O33: 3995.0178 | P33: =[2]Distribute!AL40 -> 0 | Q33: 33654030 | R33: =[2]Distribute!AM40 -> 0 | S33: 26875851
A34: =[1]Control!AX41 -> - | C34: =[2]Distribute!L81 -> 0 | E34: =[2]Distribute!L41 -> 0 | G34: =[2]Distribute!M41 -> 0 | L34: =A34 -> - | N34: =[2]Distribute!L81 -> 0 | P34: =[2]Distribute!AL41 -> 0 | R34: =[2]Distribute!AM41 -> 0
A35: SUM | C35: =SUM(C4:C34) -> 0 | D35: =SUM(D4:D34) -> 119850.53 | E35: =SUM(E4:E34) -> 0 | F35: =SUM(F4:F34) -> 64719.288 | G35: =SUM(G4:G34) -> 0 | H35: =SUM(H4:H34) -> 51684.329 | L35: Jumlah | N35: =SUM(N4:N34) -> 0 | O35: =SUM(O4:O34) -> 119850.53 | P35: =SUM(P4:P34) -> 0 | Q35: =SUM(Q4:Q34) -> 1.0096209e+09 | R35: =SUM(R4:R34) -> 0 | S35: =SUM(S4:S34) -> 8.0627553e+08
A36: This Month Daily AVG | C36: =AVERAGE(C4:C34) -> 0 | D36: =AVERAGE(D4:D34) -> 3995.0178 | E36: =AVERAGE(E4:E34) -> 0 | F36: =AVERAGE(F4:F34) -> 2157.3096 | G36: =AVERAGE(G4:G34) -> 0 | H36: =AVERAGE(H4:H34) -> 1722.811 | L36: Rata-rata perhari | N36: =AVERAGE(N4:N34) -> 0 | O36: =AVERAGE(O4:O34) -> 3995.0178 | P36: =AVERAGE(P4:P34) -> 0 | Q36: =AVERAGE(Q4:Q34) -> 33654030 | R36: =AVERAGE(R4:R34) -> 0 | S36: =AVERAGE(S4:S34) -> 26875851
C37: BBM (ltr) | E37: BBM (USD) | G37: Charter (USD) | N37: BBM (ltr) | P37: BBM (IDR) | R37: Charter (IDR)
A38: Difference | C38: =D35-C35 -> 119850.53 | E38: =F35-E35 -> 64719.288 | G38: =H35-G35 -> 51684.329 | L38: Selisih | N38: =O35-N35 -> 119850.53 | P38: =Q35-P35 -> 1.0096209e+09 | R38: =S35-R35 -> 8.0627553e+08

Sheet Security Patrol
C2: P_NORTH AND P_SOUTH SECURITY PATROL | N2: P_NORTH AND P_SOUTH SECURITY PATROL
A3: DATE | C3: Actual Vessel Fuel (Ltr) | D3: Budget Vessel Fuel (Ltr) | E3: Actual Vessel Fuel (USD) | F3: Budget Vessel Fuel (USD) | G3: Actual Vessel Charter (USD) | H3: Budget Vessel Charter (USD) | L3: DATE | N3: Actual Vessel Fuel (Ltr) | O3: Budget Vessel Fuel (Ltr) | P3: Actual Vessel Fuel (IDR) | Q3: Budget Vessel Fuel (IDR) | R3: Actual Vessel Charter (IDR) | S3: Budget Vessel Charter (IDR)
A4: =[1]Control!$AX$11 -> 45986 | C4: =[2]Distribute!O51+[2]Distribute!U51 -> 0 | D4: 1880.0051 | E4: =[2]Distribute!O11+[2]Distribute!U11 -> 0 | F4: 1015.2027 | G4: =[2]Distribute!P11+[2]Distribute!V11 -> 0 | H4: 1015.2027 | L4: =A4 -> 45986 | N4: =[2]Distribute!O51+[2]Distribute!U51 -> 0 | O4: 1880.0051 | P4: =[2]Distribute!AO11+[2]Distribute!AU11 -> 0 | Q4: 15837163 | R4: =[2]Distribute!AP11+[2]Distribute!AV11 -> 0 | S4: 15837163
A5: =[1]Control!AX12 -> 45987 | C5: =[2]Distribute!O52+[2]Distribute!U52 -> 0 | D5: 1880.0051 | E5: =[2]Distribute!O12+[2]Distribute!U12 -> 0 | F5: 1015.2027 | G5: =[2]Distribute!P12+[2]Distribute!V12 -> 0 | H5: 1015.2027 | L5: =A5 -> 45987 | N5: =[2]Distribute!O52+[2]Distribute!U52 -> 0 | O5: 1880.0051 | P5: =[2]Distribute!AO12+[2]Distribute!AU12 -> 0 | Q5: 15837163 | R5: =[2]Distribute!AP12+[2]Distribute!AV12 -> 0 | S5: 15837163
A6: =[1]Control!AX13 -> 45988 | C6: =[2]Distribute!O53+[2]Distribute!U53 -> 0 | D6: 1880.0051 | E6: =[2]Distribute!O13+[2]Distribute!U13 -> 0 | F6: 1015.2027 | G6: =[2]Distribute!P13+[2]Distribute!V13 -> 0 | H6: 1015.2027 | L6: =A6 -> 45988 | N6: =[2]Distribute!O53+[2]Distribute!U53 -> 0 | O6: 1880.0051 | P6: =[2]Distribute!AO13+[2]Distribute!AU13 -> 0 | Q6: 15837163 | R6: =[2]Distribute!AP13+[2]Distribute!AV13 -> 0 | S6: 15837163
A7: =[1]Control!AX14 -> 45989 | C7: =[2]Distribute!O54+[2]Distribute!U54 -> 0 | D7: 1880.0051 | E7: =[2]Distribute!O14+[2]Distribute!U14 -> 0 | F7: 1015.2027 | G7: =[2]Distribute!P14+[2]Distribute!V14 -> 0 | H7: 1015.2027 | L7: =A7 -> 45989 | N7: =[2]Distribute!O54+[2]Distribute!U54 -> 0 | O7: 1880.0051 | P7: =[2]Distribute!AO14+[2]Distribute!AU14 -> 0 | Q7: 15837163 | R7: =[2]Distribute!AP14+[2]Distribute!AV14 -> 0 | S7: 15837163
A8: =[1]Control!AX15 -> 45990 | C8: =[2]Distribute!O55+[2]Distribute!U55 -> 0 | D8: 1880.0051 | E8: =[2]Distribute!O15+[2]Distribute!U15 -> 0 | F8: 1015.2027 | G8: =[2]Distribute!P15+[2]Distribute!V15 -> 0 | H8: 1015.2027 | L8: =A8 -> 45990 | N8: =[2]Distribute!O55+[2]Distribute!U55 -> 0 | O8: 1880.0051 | P8: =[2]Distribute!AO15+[2]Distribute!AU15 -> 0 | Q8: 15837163 | R8: =[2]Distribute!AP15+[2]Distribute!AV15 -> 0 | S8: 15837163
A9: =[1]Control!AX16 -> 45991 | C9: =[2]Distribute!O56+[2]Distribute!U56 -> 0 | D9: 1880.0051 | E9: =[2]Distribute!O16+[2]Distribute!U16 -> 0 | F9: 1015.2027 | G9: =[2]Distribute!P16+[2]Distribute!V16 -> 0 | H9: 1015.2027 | L9: =A9 -> 45991 | N9: =[2]Distribute!O56+[2]Distribute!U56 -> 0 | O9: 1880.0051 | P9: =[2]Distribute!AO16+[2]Distribute!AU16 -> 0 | Q9: 15837163 | R9: =[2]Distribute!AP16+[2]Distribute!AV16 -> 0 | S9: 15837163
A10: =[1]Control!AX17 -> 45992 | C10: =[2]Distribute!O57+[2]Distribute!U57 -> 0 | D10: 1880.0051 | E10: =[2]Distribute!O17+[2]Distribute!U17 -> 0 | F10: 1015.2027 | G10: =[2]Distribute!P17+[2]Distribute!V17 -> 0 | H10: 1015.2027 | L10: =A10 -> 45992 | N10: =[2]Distribute!O57+[2]Distribute!U57 -> 0 | O10: 1880.0051 | P10: =[2]Distribute!AO17+[2]Distribute!AU17 -> 0 | Q10: 15837163 | R10: =[2]Distribute!AP17+[2]Distribute!AV17 -> 0 | S10: 15837163
A11: =[1]Control!AX18 -> 45993 | C11: =[2]Distribute!O58+[2]Distribute!U58 -> 0 | D11: 1880.0051 | E11: =[2]Distribute!O18+[2]Distribute!U18 -> 0 | F11: 1015.2027 | G11: =[2]Distribute!P18+[2]Distribute!V18 -> 0 | H11: 1015.2027 | L11: =A11 -> 45993 | N11: =[2]Distribute!O58+[2]Distribute!U58 -> 0 | O11: 1880.0051 | P11: =[2]Distribute!AO18+[2]Distribute!AU18 -> 0 | Q11: 15837163 | R11: =[2]Distribute!AP18+[2]Distribute!AV18 -> 0 | S11: 15837163
A12: =[1]Control!AX19 -> 45994 | C12: =[2]Distribute!O59+[2]Distribute!U59 -> 0 | D12: 1880.0051 | E12: =[2]Distribute!O19+[2]Distribute!U19 -> 0 | F12: 1015.2027 | G12: =[2]Distribute!P19+[2]Distribute!V19 -> 0 | H12: 1015.2027 | L12: =A12 -> 45994 | N12: =[2]Distribute!O59+[2]Distribute!U59 -> 0 | O12: 1880.0051 | P12: =[2]Distribute!AO19+[2]Distribute!AU19 -> 0 | Q12: 15837163 | R12: =[2]Distribute!AP19+[2]Distribute!AV19 -> 0 | S12: 15837163
A13: =[1]Control!AX20 -> 45995 | C13: =[2]Distribute!O60+[2]Distribute!U60 -> 0 | D13: 1880.0051 | E13: =[2]Distribute!O20+[2]Distribute!U20 -> 0 | F13: 1015.2027 | G13: =[2]Distribute!P20+[2]Distribute!V20 -> 0 | H13: 1015.2027 | L13: =A13 -> 45995 | N13: =[2]Distribute!O60+[2]Distribute!U60 -> 0 | O13: 1880.0051 | P13: =[2]Distribute!AO20+[2]Distribute!AU20 -> 0 | Q13: 15837163 | R13: =[2]Distribute!AP20+[2]Distribute!AV20 -> 0 | S13: 15837163
A14: =[1]Control!AX21 -> 45996 | C14: =[2]Distribute!O61+[2]Distribute!U61 -> 0 | D14: 1880.0051 | E14: =[2]Distribute!O21+[2]Distribute!U21 -> 0 | F14: 1015.2027 | G14: =[2]Distribute!P21+[2]Distribute!V21 -> 0 | H14: 1015.2027 | L14: =A14 -> 45996 | N14: =[2]Distribute!O61+[2]Distribute!U61 -> 0 | O14: 1880.0051 | P14: =[2]Distribute!AO21+[2]Distribute!AU21 -> 0 | Q14: 15837163 | R14: =[2]Distribute!AP21+[2]Distribute!AV21 -> 0 | S14: 15837163
A15: =[1]Control!AX22 -> 45997 | C15: =[2]Distribute!O62+[2]Distribute!U62 -> 0 | D15: 1880.0051 | E15: =[2]Distribute!O22+[2]Distribute!U22 -> 0 | F15: 1015.2027 | G15: =[2]Distribute!P22+[2]Distribute!V22 -> 0 | H15: 1015.2027 | L15: =A15 -> 45997 | N15: =[2]Distribute!O62+[2]Distribute!U62 -> 0 | O15: 1880.0051 | P15: =[2]Distribute!AO22+[2]Distribute!AU22 -> 0 | Q15: 15837163 | R15: =[2]Distribute!AP22+[2]Distribute!AV22 -> 0 | S15: 15837163
A16: =[1]Control!AX23 -> 45998 | C16: =[2]Distribute!O63+[2]Distribute!U63 -> 0 | D16: 1880.0051 | E16: =[2]Distribute!O23+[2]Distribute!U23 -> 0 | F16: 1015.2027 | G16: =[2]Distribute!P23+[2]Distribute!V23 -> 0 | H16: 1015.2027 | L16: =A16 -> 45998 | N16: =[2]Distribute!O63+[2]Distribute!U63 -> 0 | O16: 1880.0051 | P16: =[2]Distribute!AO23+[2]Distribute!AU23 -> 0 | Q16: 15837163 | R16: =[2]Distribute!AP23+[2]Distribute!AV23 -> 0 | S16: 15837163
... A33: =[1]Control!AX40 -> 46015 | C33: =[2]Distribute!O80+[2]Distribute!U80 -> 0 | D33: 1880.0051 | E33: =[2]Distribute!O40+[2]Distribute!U40 -> 0 | F33: 1015.2027 | G33: =[2]Distribute!P40+[2]Distribute!V40 -> 0 | H33: 1015.2027 | L33: =A33 -> 46015 | N33: =[2]Distribute!O80+[2]Distribute!U80 -> 0 | O33: 1880.0051 | P33: =[2]Distribute!AO40+[2]Distribute!AU40 -> 0 | Q33: 15837163 | R33: =[2]Distribute!AP40+[2]Distribute!AV40 -> 0 | S33: 15837163
A34: =[1]Control!AX41 -> - | C34: =[2]Distribute!O81+[2]Distribute!U81 -> 0 | E34: =[2]Distribute!O41+[2]Distribute!U41 -> 0 | G34: =[2]Distribute!P41+[2]Distribute!V41 -> 0 | L34: =A34 -> - | N34: =[2]Distribute!O81+[2]Distribute!U81 -> 0 | P34: =[2]Distribute!AO41+[2]Distribute!AU41 -> 0 | R34: =[2]Distribute!AP41+[2]Distribute!AV41 -> 0
A35: SUM | C35: =SUM(C4:C34) -> 0 | D35: =SUM(D4:D34) -> 56400.152 | E35: =SUM(E4:E34) -> 0 | F35: =SUM(F4:F34) -> 30456.082 | G35: =SUM(G4:G34) -> 0 | H35: =SUM(H4:H34) -> 30456.082 | L35: Jumlah | N35: =SUM(N4:N34) -> 0 | O35: =SUM(O4:O34) -> 56400.152 | P35: =SUM(P4:P34) -> 0 | Q35: =SUM(Q4:Q34) -> 4.7511488e+08 | R35: =SUM(R4:R34) -> 0 | S35: =SUM(S4:S34) -> 4.7511488e+08
A36: This Month Daily AVG | C36: =AVERAGE(C4:C34) -> 0 | D36: =AVERAGE(D4:D34) -> 1880.0051 | E36: =AVERAGE(E4:E34) -> 0 | F36: =AVERAGE(F4:F34) -> 1015.2027 | G36: =AVERAGE(G4:G34) -> 0 | H36: =AVERAGE(H4:H34) -> 1015.2027 | L36: Rata-rata perhari | N36: =AVERAGE(N4:N34) -> 0 | O36: =AVERAGE(O4:O34) -> 1880.0051 | P36: =AVERAGE(P4:P34) -> 0 | Q36: =AVERAGE(Q4:Q34) -> 15837163 | R36: =AVERAGE(R4:R34) -> 0 | S36: =AVERAGE(S4:S34) -> 15837163
C37: BBM (ltr) | E37: BBM (USD) | G37: Charter (USD) | N37: BBM (ltr) | P37: BBM (IDR) | R37: Charter (IDR)
A38: Difference | C38: =D35-C35 -> 56400.152 | E38: =F35-E35 -> 30456.082 | G38: =H35-G35 -> 30456.082 | L38: Selisih | N38: =O35-N35 -> 56400.152 | P38: =Q35-P35 -> 4.7511488e+08 | R38: =S35-R35 -> 4.7511488e+08

Sheet Actual Cost per type
A2: No | B2: Nama Kapal | C2: Biaya BBM - Liter | Y2: Biaya BBM - USD | AU2: Biaya SEWA - USD
C3: ='[4]AHTS-1'!AG48 -> RUN EXPLOSIVE | D3: ='[4]AHTS-1'!AH48 -> ASSET | E3: ='[4]AHTS-1'!AI48 -> TIRTA RAJAWALI | F3: ='[4]AHTS-1'!AJ48 -> S: SLICKLINE UNIT | G3: ='[4]AHTS-1'!AK48 -> N: SLICKLINE (1) | H3: ='[4]AHTS-1'!AL48 -> LAIN-LAIN | I3: ='[4]AHTS-1'!AM48 -> SOIL BORING | J3: ='[4]AHTS-1'!AN48 -> N: SLICKLINE (2) | ... X3: ='[4]AHTS-1'!BB48 -> P_SOUTH SECURITY PATROL | Y3: ='[4]AHTS-1'!AG10 -> DAILY FUEL RUN EXPLOSIVE | Z3: ='[4]AHTS-1'!AH10 -> DAILY FUEL ASSET | AA3: ='[4]AHTS-1'!AI10 -> DAILY FUEL 'TIRTA RAJAWALI | AB3: ='[4]AHTS-1'!AJ10 -> DAILY FUEL S: SLICKLINE UNIT | AC3: ='[4]AHTS-1'!AK10 -> DAILY FUEL N: SLICKLINE (1) | AD3: ='[4]AHTS-1'!AL10 -> DAILY FUEL LAIN-LAIN | AE3: ='[4]AHTS-1'!AM10 -> DAILY FUEL SOIL BORING | AF3: ='[4]AHTS-1'!AN10 -> DAILY FUEL N: SLICKLINE (2) | ... BP3: ='[4]AHTS-1'!BX10 -> DAILY HIRE RATE P_SOUTH SECURITY PATROL
A4: 1 | B4: ='[4]AHTS-1'!$C$8 -> AHTS AMBER | C4: ='[4]AHTS-1'!AG80 -> 0 | D4: ='[4]AHTS-1'!AH80 -> 0 | E4: ='[4]AHTS-1'!AI80 -> 0 | F4: ='[4]AHTS-1'!AJ80 -> 0 | G4: ='[4]AHTS-1'!AK80 -> 0 | H4: ='[4]AHTS-1'!AL80 -> 0 | I4: ='[4]AHTS-1'!AM80 -> 0 | J4: ='[4]AHTS-1'!AN80 -> 0 | ... X4: ='[4]AHTS-1'!BB80 -> 0 | Y4: ='[4]AHTS-1'!AG42 -> 0 | Z4: ='[4]AHTS-1'!AH42 -> 0 | AA4: ='[4]AHTS-1'!AI42 -> 0 | AB4: ='[4]AHTS-1'!AJ42 -> 0 | AC4: ='[4]AHTS-1'!AK42 -> 0 | AD4: ='[4]AHTS-1'!AL42 -> 0 | AE4: ='[4]AHTS-1'!AM42 -> 0 | AF4: ='[4]AHTS-1'!AN42 -> 0 | ... BP4: ='[4]AHTS-1'!BX42 -> 0
A5: 2 | B5: ='[4]AHTS-2'!$C$8 -> AHTS Temasek Sepinggan | C5: ='[4]AHTS-2'!AG80 -> 0 | D5: ='[4]AHTS-2'!AH80 -> 0 | E5: ='[4]AHTS-2'!AI80 -> 0 | F5: ='[4]AHTS-2'!AJ80 -> 0 | G5: ='[4]AHTS-2'!AK80 -> 0 | H5: ='[4]AHTS-2'!AL80 -> 0 | I5: ='[4]AHTS-2'!AM80 -> 0 | J5: ='[4]AHTS-2'!AN80 -> 0 | ... X5: ='[4]AHTS-2'!BB80 -> 0 | Y5: ='[4]AHTS-2'!AG42 -> 0 | Z5: ='[4]AHTS-2'!AH42 -> 0 | AA5: ='[4]AHTS-2'!AI42 -> 0 | AB5: ='[4]AHTS-2'!AJ42 -> 0 | AC5: ='[4]AHTS-2'!AK42 -> 0 | AD5: ='[4]AHTS-2'!AL42 -> 0 | AE5: ='[4]AHTS-2'!AM42 -> 0 | AF5: ='[4]AHTS-2'!AN42 -> 0 | ... BP5: ='[4]AHTS-2'!BX42 -> 0
A6: 3 | B6: ='[4]AHTS-3'!$C$8 -> AHTS Temasek Attaka | C6: ='[4]AHTS-3'!AG80 -> 0 | D6: ='[4]AHTS-3'!AH80 -> 0 | E6: ='[4]AHTS-3'!AI80 -> 0 | F6: ='[4]AHTS-3'!AJ80 -> 0 | G6: ='[4]AHTS-3'!AK80 -> 0 | H6: ='[4]AHTS-3'!AL80 -> 0 | I6: ='[4]AHTS-3'!AM80 -> 0 | J6: ='[4]AHTS-3'!AN80 -> 0 | ... X6: ='[4]AHTS-3'!BB80 -> 0 | Y6: ='[4]AHTS-3'!AG42 -> 0 | Z6: ='[4]AHTS-3'!AH42 -> 0 | AA6: ='[4]AHTS-3'!AI42 -> 0 | AB6: ='[4]AHTS-3'!AJ42 -> 0 | AC6: ='[4]AHTS-3'!AK42 -> 0 | AD6: ='[4]AHTS-3'!AL42 -> 0 | AE6: ='[4]AHTS-3'!AM42 -> 0 | AF6: ='[4]AHTS-3'!AN42 -> 0 | ... BP6: ='[4]AHTS-3'!BX42 -> 0
A7: 4 | B7: ='[4]AHTS-4'!$C$8 -> 0 | C7: ='[4]AHTS-4'!AG80 -> 0 | D7: ='[4]AHTS-4'!AH80 -> 0 | E7: ='[4]AHTS-4'!AI80 -> 0 | F7: ='[4]AHTS-4'!AJ80 -> 0 | G7: ='[4]AHTS-4'!AK80 -> 0 | H7: ='[4]AHTS-4'!AL80 -> 0 | I7: ='[4]AHTS-4'!AM80 -> 0 | J7: ='[4]AHTS-4'!AN80 -> 0 | ... X7: ='[4]AHTS-4'!BB80 -> 0 | Y7: ='[4]AHTS-4'!AG42 -> 0 | Z7: ='[4]AHTS-4'!AH42 -> 0 | AA7: ='[4]AHTS-4'!AI42 -> 0 | AB7: ='[4]AHTS-4'!AJ42 -> 0 | AC7: ='[4]AHTS-4'!AK42 -> 0 | AD7: ='[4]AHTS-4'!AL42 -> 0 | AE7: ='[4]AHTS-4'!AM42 -> 0 | AF7: ='[4]AHTS-4'!AN42 -> 0 | ... BP7: ='[4]AHTS-4'!BX42 -> 0
A8: 5 | B8: ='[4]AHTS-5'!$C$8 -> 0 | C8: ='[4]AHTS-5'!AG80 -> 0 | D8: ='[4]AHTS-5'!AH80 -> 0 | E8: ='[4]AHTS-5'!AI80 -> 0 | F8: ='[4]AHTS-5'!AJ80 -> 0 | G8: ='[4]AHTS-5'!AK80 -> 0 | H8: ='[4]AHTS-5'!AL80 -> 0 | I8: ='[4]AHTS-5'!AM80 -> 0 | J8: ='[4]AHTS-5'!AN80 -> 0 | ... X8: ='[4]AHTS-5'!BB80 -> 0 | Y8: ='[4]AHTS-5'!AG42 -> 0 | Z8: ='[4]AHTS-5'!AH42 -> 0 | AA8: ='[4]AHTS-5'!AI42 -> 0 | AB8: ='[4]AHTS-5'!AJ42 -> 0 | AC8: ='[4]AHTS-5'!AK42 -> 0 | AD8: ='[4]AHTS-5'!AL42 -> 0 | AE8: ='[4]AHTS-5'!AM42 -> 0 | AF8: ='[4]AHTS-5'!AN42 -> 0 | ... BP8: ='[4]AHTS-5'!BX42 -> 0
A9: 6 | B9: ='[4]AHTS-6'!$C$8 -> 0 | C9: ='[4]AHTS-6'!AG80 -> 0 | D9: ='[4]AHTS-6'!AH80 -> 0 | E9: ='[4]AHTS-6'!AI80 -> 0 | F9: ='[4]AHTS-6'!AJ80 -> 0 | G9: ='[4]AHTS-6'!AK80 -> 0 | H9: ='[4]AHTS-6'!AL80 -> 0 | I9: ='[4]AHTS-6'!AM80 -> 0 | J9: ='[4]AHTS-6'!AN80 -> 0 | ... X9: ='[4]AHTS-6'!BB80 -> 0 | Y9: ='[4]AHTS-6'!AG42 -> 0 | Z9: ='[4]AHTS-6'!AH42 -> 0 | AA9: ='[4]AHTS-6'!AI42 -> 0 | AB9: ='[4]AHTS-6'!AJ42 -> 0 | AC9: ='[4]AHTS-6'!AK42 -> 0 | AD9: ='[4]AHTS-6'!AL42 -> 0 | AE9: ='[4]AHTS-6'!AM42 -> 0 | AF9: ='[4]AHTS-6'!AN42 -> 0 | ... BP9: ='[4]AHTS-6'!BX42 -> 0
A10: 7 | B10: ='[4]AHTS-7'!$C$8 -> 0 | C10: ='[4]AHTS-7'!AG80 -> 0 | D10: ='[4]AHTS-7'!AH80 -> 0 | E10: ='[4]AHTS-7'!AI80 -> 0 | F10: ='[4]AHTS-7'!AJ80 -> 0 | G10: ='[4]AHTS-7'!AK80 -> 0 | H10: ='[4]AHTS-7'!AL80 -> 0 | I10: ='[4]AHTS-7'!AM80 -> 0 | J10: ='[4]AHTS-7'!AN80 -> 0 | ... X10: ='[4]AHTS-7'!BB80 -> 0 | Y10: ='[4]AHTS-7'!AG42 -> 0 | Z10: ='[4]AHTS-7'!AH42 -> 0 | AA10: ='[4]AHTS-7'!AI42 -> 0 | AB10: ='[4]AHTS-7'!AJ42 -> 0 | AC10: ='[4]AHTS-7'!AK42 -> 0 | AD10: ='[4]AHTS-7'!AL42 -> 0 | AE10: ='[4]AHTS-7'!AM42 -> 0 | AF10: ='[4]AHTS-7'!AN42 -> 0 | ... BP10: ='[4]AHTS-7'!BX42 -> 0
A11: 8 | B11: ='[4]AHTS-8'!$C$8 -> 0 | C11: ='[4]AHTS-8'!AG80 -> 0 | D11: ='[4]AHTS-8'!AH80 -> 0 | E11: ='[4]AHTS-8'!AI80 -> 0 | F11: ='[4]AHTS-8'!AJ80 -> 0 | G11: ='[4]AHTS-8'!AK80 -> 0 | H11: ='[4]AHTS-8'!AL80 -> 0 | I11: ='[4]AHTS-8'!AM80 -> 0 | J11: ='[4]AHTS-8'!AN80 -> 0 | ... X11: ='[4]AHTS-8'!BB80 -> 0 | Y11: ='[4]AHTS-8'!AG42 -> 0 | Z11: ='[4]AHTS-8'!AH42 -> 0 | AA11: ='[4]AHTS-8'!AI42 -> 0 | AB11: ='[4]AHTS-8'!AJ42 -> 0 | AC11: ='[4]AHTS-8'!AK42 -> 0 | AD11: ='[4]AHTS-8'!AL42 -> 0 | AE11: ='[4]AHTS-8'!AM42 -> 0 | AF11: ='[4]AHTS-8'!AN42 -> 0 | ... BP11: ='[4]AHTS-8'!BX42 -> 0
A12: 9 | B12: ='[5]Barge-1'!$C$8 -> 0 | C12: ='[5]Barge-1'!AG80 -> 0 | D12: ='[5]Barge-1'!AH80 -> 0 | E12: ='[5]Barge-1'!AI80 -> 0 | F12: ='[5]Barge-1'!AJ80 -> 0 | G12: ='[5]Barge-1'!AK80 -> 0 | H12: ='[5]Barge-1'!AL80 -> 0 | I12: ='[5]Barge-1'!AM80 -> 0 | J12: ='[5]Barge-1'!AN80 -> 0 | ... X12: ='[5]Barge-1'!BB80 -> 0 | Y12: ='[5]Barge-1'!AG42 -> 0 | Z12: ='[5]Barge-1'!AH42 -> 0 | AA12: ='[5]Barge-1'!AI42 -> 0 | AB12: ='[5]Barge-1'!AJ42 -> 0 | AC12: ='[5]Barge-1'!AK42 -> 0 | AD12: ='[5]Barge-1'!AL42 -> 0 | AE12: ='[5]Barge-1'!AM42 -> 0 | AF12: ='[5]Barge-1'!AN42 -> 0 | ... BP12: ='[5]Barge-1'!BX42 -> 0
A13: 10 | B13: ='[6]CB-1'!$C$8 -> CB PEREGRIN | C13: ='[6]CB-1'!AG80 -> 0 | D13: ='[6]CB-1'!AH80 -> 0 | E13: ='[6]CB-1'!AI80 -> 0 | F13: ='[6]CB-1'!AJ80 -> 0 | G13: ='[6]CB-1'!AK80 -> 0 | H13: ='[6]CB-1'!AL80 -> 0 | I13: ='[6]CB-1'!AM80 -> 0 | J13: ='[6]CB-1'!AN80 -> 0 | ... X13: ='[6]CB-1'!BB80 -> 0 | Y13: ='[6]CB-1'!AG42 -> 0 | Z13: ='[6]CB-1'!AH42 -> 0 | AA13: ='[6]CB-1'!AI42 -> 0 | AB13: ='[6]CB-1'!AJ42 -> 0 | AC13: ='[6]CB-1'!AK42 -> 0 | AD13: ='[6]CB-1'!AL42 -> 0 | AE13: ='[6]CB-1'!AM42 -> 0 | AF13: ='[6]CB-1'!AN42 -> 0 | ... BP13: ='[6]CB-1'!BX42 -> 0
A14: 11 | B14: ='[6]CB-2'!$C$8 -> CB MALEO | C14: ='[6]CB-2'!AG80 -> 0 | D14: ='[6]CB-2'!AH80 -> 0 | E14: ='[6]CB-2'!AI80 -> 0 | F14: ='[6]CB-2'!AJ80 -> 0 | G14: ='[6]CB-2'!AK80 -> 0 | H14: ='[6]CB-2'!AL80 -> 0 | I14: ='[6]CB-2'!AM80 -> 0 | J14: ='[6]CB-2'!AN80 -> 0 | ... X14: ='[6]CB-2'!BB80 -> 0 | Y14: ='[6]CB-2'!AG42 -> 0 | Z14: ='[6]CB-2'!AH42 -> 0 | AA14: ='[6]CB-2'!AI42 -> 0 | AB14: ='[6]CB-2'!AJ42 -> 0 | AC14: ='[6]CB-2'!AK42 -> 0 | AD14: ='[6]CB-2'!AL42 -> 0 | AE14: ='[6]CB-2'!AM42 -> 0 | AF14: ='[6]CB-2'!AN42 -> 0 | ... BP14: ='[6]CB-2'!BX42 -> 0
A15: 12 | B15: ='[6]CB-3'!$C$8 -> CB COLIBRI-1 (2nd call out EXPRESS 68) | C15: ='[6]CB-3'!AG80 -> 0 | D15: ='[6]CB-3'!AH80 -> 0 | E15: ='[6]CB-3'!AI80 -> 0 | F15: ='[6]CB-3'!AJ80 -> 0 | G15: ='[6]CB-3'!AK80 -> 0 | H15: ='[6]CB-3'!AL80 -> 0 | I15: ='[6]CB-3'!AM80 -> 0 | J15: ='[6]CB-3'!AN80 -> 0 | ... X15: ='[6]CB-3'!BB80 -> 0 | Y15: ='[6]CB-3'!AG42 -> 0 | Z15: ='[6]CB-3'!AH42 -> 0 | AA15: ='[6]CB-3'!AI42 -> 0 | AB15: ='[6]CB-3'!AJ42 -> 0 | AC15: ='[6]CB-3'!AK42 -> 0 | AD15: ='[6]CB-3'!AL42 -> 0 | AE15: ='[6]CB-3'!AM42 -> 0 | AF15: ='[6]CB-3'!AN42 -> 0 | ... BP15: ='[6]CB-3'!BX42 -> 0
A16: 13 | B16: ='[6]CB-4'!$C$8 -> CB COCABORA (2nd call out EP ALFA) | C16: ='[6]CB-4'!AG80 -> 0 | D16: ='[6]CB-4'!AH80 -> 0 | E16: ='[6]CB-4'!AI80 -> 0 | F16: ='[6]CB-4'!AJ80 -> 0 | G16: ='[6]CB-4'!AK80 -> 0 | H16: ='[6]CB-4'!AL80 -> 0 | I16: ='[6]CB-4'!AM80 -> 0 | J16: ='[6]CB-4'!AN80 -> 0 | ... X16: ='[6]CB-4'!BB80 -> 0 | Y16: ='[6]CB-4'!AG42 -> 0 | Z16: ='[6]CB-4'!AH42 -> 0 | AA16: ='[6]CB-4'!AI42 -> 0 | AB16: ='[6]CB-4'!AJ42 -> 0 | AC16: ='[6]CB-4'!AK42 -> 0 | AD16: ='[6]CB-4'!AL42 -> 0 | AE16: ='[6]CB-4'!AM42 -> 0 | AF16: ='[6]CB-4'!AN42 -> 0 | ... BP16: ='[6]CB-4'!BX42 -> 0
A17: 14 | B17: ='[6]CB-5'!$C$8 -> CB TEGUH 16 (sub EP ALFA) | C17: ='[6]CB-5'!AG80 -> 0 | D17: ='[6]CB-5'!AH80 -> 0 | E17: ='[6]CB-5'!AI80 -> 0 | F17: ='[6]CB-5'!AJ80 -> 0 | G17: ='[6]CB-5'!AK80 -> 0 | H17: ='[6]CB-5'!AL80 -> 0 | I17: ='[6]CB-5'!AM80 -> 0 | J17: ='[6]CB-5'!AN80 -> 0 | ... X17: ='[6]CB-5'!BB80 -> 0 | Y17: ='[6]CB-5'!AG42 -> 0 | Z17: ='[6]CB-5'!AH42 -> 0 | AA17: ='[6]CB-5'!AI42 -> 0 | AB17: ='[6]CB-5'!AJ42 -> 0 | AC17: ='[6]CB-5'!AK42 -> 0 | AD17: ='[6]CB-5'!AL42 -> 0 | AE17: ='[6]CB-5'!AM42 -> 0 | AF17: ='[6]CB-5'!AN42 -> 0 | ... BP17: ='[6]CB-5'!BX42 -> 0
A18: 15 | B18: ='[6]CB-6'!$C$8 -> CB MANDAR (2nd call out CB GELATIK) | C18: ='[6]CB-6'!AG80 -> 0 | D18: ='[6]CB-6'!AH80 -> 0 | E18: ='[6]CB-6'!AI80 -> 0 | F18: ='[6]CB-6'!AJ80 -> 0 | G18: ='[6]CB-6'!AK80 -> 0 | H18: ='[6]CB-6'!AL80 -> 0 | I18: ='[6]CB-6'!AM80 -> 0 | J18: ='[6]CB-6'!AN80 -> 0 | ... X18: ='[6]CB-6'!BB80 -> 0 | Y18: ='[6]CB-6'!AG42 -> 0 | Z18: ='[6]CB-6'!AH42 -> 0 | AA18: ='[6]CB-6'!AI42 -> 0 | AB18: ='[6]CB-6'!AJ42 -> 0 | AC18: ='[6]CB-6'!AK42 -> 0 | AD18: ='[6]CB-6'!AL42 -> 0 | AE18: ='[6]CB-6'!AM42 -> 0 | AF18: ='[6]CB-6'!AN42 -> 0 | ... BP18: ='[6]CB-6'!BX42 -> 0
A19: 16 | B19: ='[6]CB-7'!$C$8 -> CB GELATIK | C19: ='[6]CB-7'!AG80 -> 0 | D19: ='[6]CB-7'!AH80 -> 0 | E19: ='[6]CB-7'!AI80 -> 0 | F19: ='[6]CB-7'!AJ80 -> 0 | G19: ='[6]CB-7'!AK80 -> 0 | H19: ='[6]CB-7'!AL80 -> 0 | I19: ='[6]CB-7'!AM80 -> 0 | J19: ='[6]CB-7'!AN80 -> 0 | ... X19: ='[6]CB-7'!BB80 -> 0 | Y19: ='[6]CB-7'!AG42 -> 0 | Z19: ='[6]CB-7'!AH42 -> 0 | AA19: ='[6]CB-7'!AI42 -> 0 | AB19: ='[6]CB-7'!AJ42 -> 0 | AC19: ='[6]CB-7'!AK42 -> 0 | AD19: ='[6]CB-7'!AL42 -> 0 | AE19: ='[6]CB-7'!AM42 -> 0 | AF19: ='[6]CB-7'!AN42 -> 0 | ... BP19: ='[6]CB-7'!BX42 -> 0
A20: 17 | B20: ='[6]CB-8'!$C$8 -> CB NURI | C20: ='[6]CB-8'!AG80 -> 0 | D20: ='[6]CB-8'!AH80 -> 0 | E20: ='[6]CB-8'!AI80 -> 0 | F20: ='[6]CB-8'!AJ80 -> 0 | G20: ='[6]CB-8'!AK80 -> 0 | H20: ='[6]CB-8'!AL80 -> 0 | I20: ='[6]CB-8'!AM80 -> 0 | J20: ='[6]CB-8'!AN80 -> 0 | ... X20: ='[6]CB-8'!BB80 -> 0 | Y20: ='[6]CB-8'!AG42 -> 0 | Z20: ='[6]CB-8'!AH42 -> 0 | AA20: ='[6]CB-8'!AI42 -> 0 | AB20: ='[6]CB-8'!AJ42 -> 0 | AC20: ='[6]CB-8'!AK42 -> 0 | AD20: ='[6]CB-8'!AL42 -> 0 | AE20: ='[6]CB-8'!AM42 -> 0 | AF20: ='[6]CB-8'!AN42 -> 0 | ... BP20: ='[6]CB-8'!BX42 -> 0
A21: 18 | B21: ='[6]CB-9'!$C$8 -> CB PUYUH (sub CB PEREGRIN) | C21: ='[6]CB-9'!AG80 -> 0 | D21: ='[6]CB-9'!AH80 -> 0 | E21: ='[6]CB-9'!AI80 -> 0 | F21: ='[6]CB-9'!AJ80 -> 0 | G21: ='[6]CB-9'!AK80 -> 0 | H21: ='[6]CB-9'!AL80 -> 0 | I21: ='[6]CB-9'!AM80 -> 0 | J21: ='[6]CB-9'!AN80 -> 0 | ... X21: ='[6]CB-9'!BB80 -> 0 | Y21: ='[6]CB-9'!AG42 -> 0 | Z21: ='[6]CB-9'!AH42 -> 0 | AA21: ='[6]CB-9'!AI42 -> 0 | AB21: ='[6]CB-9'!AJ42 -> 0 | AC21: ='[6]CB-9'!AK42 -> 0 | AD21: ='[6]CB-9'!AL42 -> 0 | AE21: ='[6]CB-9'!AM42 -> 0 | AF21: ='[6]CB-9'!AN42 -> 0 | ... BP21: ='[6]CB-9'!BX42 -> 0
A22: 19 | B22: ='[6]CB-10'!$C$8 -> 0 | C22: ='[6]CB-10'!AG80 -> 0 | D22: ='[6]CB-10'!AH80 -> 0 | E22: ='[6]CB-10'!AI80 -> 0 | F22: ='[6]CB-10'!AJ80 -> 0 | G22: ='[6]CB-10'!AK80 -> 0 | H22: ='[6]CB-10'!AL80 -> 0 | I22: ='[6]CB-10'!AM80 -> 0 | J22: ='[6]CB-10'!AN80 -> 0 | ... X22: ='[6]CB-10'!BB80 -> 0 | Y22: ='[6]CB-10'!AG42 -> 0 | Z22: ='[6]CB-10'!AH42 -> 0 | AA22: ='[6]CB-10'!AI42 -> 0 | AB22: ='[6]CB-10'!AJ42 -> 0 | AC22: ='[6]CB-10'!AK42 -> 0 | AD22: ='[6]CB-10'!AL42 -> 0 | AE22: ='[6]CB-10'!AM42 -> 0 | AF22: ='[6]CB-10'!AN42 -> 0 | ... BP22: ='[6]CB-10'!BX42 -> 0
A23: 20 | B23: ='[6]CB-11'!$C$8 -> CB KCT 1302 (sub Express 68) | C23: ='[6]CB-11'!AG80 -> 0 | D23: ='[6]CB-11'!AH80 -> 0 | E23: ='[6]CB-11'!AI80 -> 0 | F23: ='[6]CB-11'!AJ80 -> 0 | G23: ='[6]CB-11'!AK80 -> 0 | H23: ='[6]CB-11'!AL80 -> 0 | I23: ='[6]CB-11'!AM80 -> 0 | J23: ='[6]CB-11'!AN80 -> 0 | ... X23: ='[6]CB-11'!BB80 -> 0 | Y23: ='[6]CB-11'!AG42 -> 0 | Z23: ='[6]CB-11'!AH42 -> 0 | AA23: ='[6]CB-11'!AI42 -> 0 | AB23: ='[6]CB-11'!AJ42 -> 0 | AC23: ='[6]CB-11'!AK42 -> 0 | AD23: ='[6]CB-11'!AL42 -> 0 | AE23: ='[6]CB-11'!AM42 -> 0 | AF23: ='[6]CB-11'!AN42 -> 0 | ... BP23: ='[6]CB-11'!BX42 -> 0
A24: 21 | B24: ='[6]CB-12'!$C$8 -> CB Baruna 222 (2nd call out CB MALEO) | C24: ='[6]CB-12'!AG80 -> 0 | D24: ='[6]CB-12'!AH80 -> 0 | E24: ='[6]CB-12'!AI80 -> 0 | F24: ='[6]CB-12'!AJ80 -> 0 | G24: ='[6]CB-12'!AK80 -> 0 | H24: ='[6]CB-12'!AL80 -> 0 | I24: ='[6]CB-12'!AM80 -> 0 | J24: ='[6]CB-12'!AN80 -> 0 | ... X24: ='[6]CB-12'!BB80 -> 0 | Y24: ='[6]CB-12'!AG42 -> 0 | Z24: ='[6]CB-12'!AH42 -> 0 | AA24: ='[6]CB-12'!AI42 -> 0 | AB24: ='[6]CB-12'!AJ42 -> 0 | AC24: ='[6]CB-12'!AK42 -> 0 | AD24: ='[6]CB-12'!AL42 -> 0 | AE24: ='[6]CB-12'!AM42 -> 0 | AF24: ='[6]CB-12'!AN42 -> 0 | ... BP24: ='[6]CB-12'!BX42 -> 0
A25: 22 | B25: ='[6]CB-13'!$C$8 -> 0 | C25: ='[6]CB-13'!AG80 -> 0 | D25: ='[6]CB-13'!AH80 -> 0 | E25: ='[6]CB-13'!AI80 -> 0 | F25: ='[6]CB-13'!AJ80 -> 0 | G25: ='[6]CB-13'!AK80 -> 0 | H25: ='[6]CB-13'!AL80 -> 0 | I25: ='[6]CB-13'!AM80 -> 0 | J25: ='[6]CB-13'!AN80 -> 0 | ... X25: ='[6]CB-13'!BB80 -> 0 | Y25: ='[6]CB-13'!AG42 -> 0 | Z25: ='[6]CB-13'!AH42 -> 0 | AA25: ='[6]CB-13'!AI42 -> 0 | AB25: ='[6]CB-13'!AJ42 -> 0 | AC25: ='[6]CB-13'!AK42 -> 0 | AD25: ='[6]CB-13'!AL42 -> 0 | AE25: ='[6]CB-13'!AM42 -> 0 | AF25: ='[6]CB-13'!AN42 -> 0 | ... BP25: ='[6]CB-13'!BX42 -> 0
A26: 23 | B26: ='[6]CB-14'!$C$8 -> 0 | C26: ='[6]CB-14'!AG80 -> 0 | D26: ='[6]CB-14'!AH80 -> 0 | E26: ='[6]CB-14'!AI80 -> 0 | F26: ='[6]CB-14'!AJ80 -> 0 | G26: ='[6]CB-14'!AK80 -> 0 | H26: ='[6]CB-14'!AL80 -> 0 | I26: ='[6]CB-14'!AM80 -> 0 | J26: ='[6]CB-14'!AN80 -> 0 | ... X26: ='[6]CB-14'!BB80 -> 0 | Y26: ='[6]CB-14'!AG42 -> 0 | Z26: ='[6]CB-14'!AH42 -> 0 | AA26: ='[6]CB-14'!AI42 -> 0 | AB26: ='[6]CB-14'!AJ42 -> 0 | AC26: ='[6]CB-14'!AK42 -> 0 | AD26: ='[6]CB-14'!AL42 -> 0 | AE26: ='[6]CB-14'!AM42 -> 0 | AF26: ='[6]CB-14'!AN42 -> 0 | ... BP26: ='[6]CB-14'!BX42 -> 0
A27: 24 | B27: ='[6]CB-15'!$C$8 -> 0 | C27: ='[6]CB-15'!AG80 -> 0 | D27: ='[6]CB-15'!AH80 -> 0 | E27: ='[6]CB-15'!AI80 -> 0 | F27: ='[6]CB-15'!AJ80 -> 0 | G27: ='[6]CB-15'!AK80 -> 0 | H27: ='[6]CB-15'!AL80 -> 0 | I27: ='[6]CB-15'!AM80 -> 0 | J27: ='[6]CB-15'!AN80 -> 0 | ... X27: ='[6]CB-15'!BB80 -> 0 | Y27: ='[6]CB-15'!AG42 -> 0 | Z27: ='[6]CB-15'!AH42 -> 0 | AA27: ='[6]CB-15'!AI42 -> 0 | AB27: ='[6]CB-15'!AJ42 -> 0 | AC27: ='[6]CB-15'!AK42 -> 0 | AD27: ='[6]CB-15'!AL42 -> 0 | AE27: ='[6]CB-15'!AM42 -> 0 | AF27: ='[6]CB-15'!AN42 -> 0 | ... BP27: ='[6]CB-15'!BX42 -> 0
A28: 25 | B28: ='[6]CB-16'!$C$8 -> 0 | C28: ='[6]CB-16'!AG80 -> 0 | D28: ='[6]CB-16'!AH80 -> 0 | E28: ='[6]CB-16'!AI80 -> 0 | F28: ='[6]CB-16'!AJ80 -> 0 | G28: ='[6]CB-16'!AK80 -> 0 | H28: ='[6]CB-16'!AL80 -> 0 | I28: ='[6]CB-16'!AM80 -> 0 | J28: ='[6]CB-16'!AN80 -> 0 | ... X28: ='[6]CB-16'!BB80 -> 0 | Y28: ='[6]CB-16'!AG42 -> 0 | Z28: ='[6]CB-16'!AH42 -> 0 | AA28: ='[6]CB-16'!AI42 -> 0 | AB28: ='[6]CB-16'!AJ42 -> 0 | AC28: ='[6]CB-16'!AK42 -> 0 | AD28: ='[6]CB-16'!AL42 -> 0 | AE28: ='[6]CB-16'!AM42 -> 0 | AF28: ='[6]CB-16'!AN42 -> 0 | ... BP28: ='[6]CB-16'!BX42 -> 0
A29: 26 | B29: ='[6]CB-17'!$C$8 -> 0 | C29: ='[6]CB-17'!AG80 -> 0 | D29: ='[6]CB-17'!AH80 -> 0 | E29: ='[6]CB-17'!AI80 -> 0 | F29: ='[6]CB-17'!AJ80 -> 0 | G29: ='[6]CB-17'!AK80 -> 0 | H29: ='[6]CB-17'!AL80 -> 0 | I29: ='[6]CB-17'!AM80 -> 0 | J29: ='[6]CB-17'!AN80 -> 0 | ... X29: ='[6]CB-17'!BB80 -> 0 | Y29: ='[6]CB-17'!AG42 -> 0 | Z29: ='[6]CB-17'!AH42 -> 0 | AA29: ='[6]CB-17'!AI42 -> 0 | AB29: ='[6]CB-17'!AJ42 -> 0 | AC29: ='[6]CB-17'!AK42 -> 0 | AD29: ='[6]CB-17'!AL42 -> 0 | AE29: ='[6]CB-17'!AM42 -> 0 | AF29: ='[6]CB-17'!AN42 -> 0 | ... BP29: ='[6]CB-17'!BX42 -> 0
A30: 27 | B30: ='[6]CB-18'!$C$8 -> 0 | C30: ='[6]CB-18'!AG80 -> 0 | D30: ='[6]CB-18'!AH80 -> 0 | E30: ='[6]CB-18'!AI80 -> 0 | F30: ='[6]CB-18'!AJ80 -> 0 | G30: ='[6]CB-18'!AK80 -> 0 | H30: ='[6]CB-18'!AL80 -> 0 | I30: ='[6]CB-18'!AM80 -> 0 | J30: ='[6]CB-18'!AN80 -> 0 | ... X30: ='[6]CB-18'!BB80 -> 0 | Y30: ='[6]CB-18'!AG42 -> 0 | Z30: ='[6]CB-18'!AH42 -> 0 | AA30: ='[6]CB-18'!AI42 -> 0 | AB30: ='[6]CB-18'!AJ42 -> 0 | AC30: ='[6]CB-18'!AK42 -> 0 | AD30: ='[6]CB-18'!AL42 -> 0 | AE30: ='[6]CB-18'!AM42 -> 0 | AF30: ='[6]CB-18'!AN42 -> 0 | ... BP30: ='[6]CB-18'!BX42 -> 0
A31: 28 | B31: ='[6]CB-19'!$C$8 -> 0 | C31: ='[6]CB-19'!AG80 -> 0 | D31: ='[6]CB-19'!AH80 -> 0 | E31: ='[6]CB-19'!AI80 -> 0 | F31: ='[6]CB-19'!AJ80 -> 0 | G31: ='[6]CB-19'!AK80 -> 0 | H31: ='[6]CB-19'!AL80 -> 0 | I31: ='[6]CB-19'!AM80 -> 0 | J31: ='[6]CB-19'!AN80 -> 0 | ... X31: ='[6]CB-19'!BB80 -> 0 | Y31: ='[6]CB-19'!AG42 -> 0 | Z31: ='[6]CB-19'!AH42 -> 0 | AA31: ='[6]CB-19'!AI42 -> 0 | AB31: ='[6]CB-19'!AJ42 -> 0 | AC31: ='[6]CB-19'!AK42 -> 0 | AD31: ='[6]CB-19'!AL42 -> 0 | AE31: ='[6]CB-19'!AM42 -> 0 | AF31: ='[6]CB-19'!AN42 -> 0 | ... BP31: ='[6]CB-19'!BX42 -> 0
A32: 29 | B32: ='[6]CB-20'!$C$8 -> 0 | C32: ='[6]CB-20'!AG80 -> 0 | D32: ='[6]CB-20'!AH80 -> 0 | E32: ='[6]CB-20'!AI80 -> 0 | F32: ='[6]CB-20'!AJ80 -> 0 | G32: ='[6]CB-20'!AK80 -> 0 | H32: ='[6]CB-20'!AL80 -> 0 | I32: ='[6]CB-20'!AM80 -> 0 | J32: ='[6]CB-20'!AN80 -> 0 | ... X32: ='[6]CB-20'!BB80 -> 0 | Y32: ='[6]CB-20'!AG42 -> 0 | Z32: ='[6]CB-20'!AH42 -> 0 | AA32: ='[6]CB-20'!AI42 -> 0 | AB32: ='[6]CB-20'!AJ42 -> 0 | AC32: ='[6]CB-20'!AK42 -> 0 | AD32: ='[6]CB-20'!AL42 -> 0 | AE32: ='[6]CB-20'!AM42 -> 0 | AF32: ='[6]CB-20'!AN42 -> 0 | ... BP32: ='[6]CB-20'!BX42 -> 0
A33: 30 | B33: ='[6]CB-21'!$C$8 -> 0 | C33: ='[6]CB-21'!AG80 -> 0 | D33: ='[6]CB-21'!AH80 -> 0 | E33: ='[6]CB-21'!AI80 -> 0 | F33: ='[6]CB-21'!AJ80 -> 0 | G33: ='[6]CB-21'!AK80 -> 0 | H33: ='[6]CB-21'!AL80 -> 0 | I33: ='[6]CB-21'!AM80 -> 0 | J33: ='[6]CB-21'!AN80 -> 0 | ... X33: ='[6]CB-21'!BB80 -> 0 | Y33: ='[6]CB-21'!AG42 -> 0 | Z33: ='[6]CB-21'!AH42 -> 0 | AA33: ='[6]CB-21'!AI42 -> 0 | AB33: ='[6]CB-21'!AJ42 -> 0 | AC33: ='[6]CB-21'!AK42 -> 0 | AD33: ='[6]CB-21'!AL42 -> 0 | AE33: ='[6]CB-21'!AM42 -> 0 | AF33: ='[6]CB-21'!AN42 -> 0 | ... BP33: ='[6]CB-21'!BX42 -> 0
A34: 31 | B34: ='[6]CB-22'!$C$8 -> 0 | C34: ='[6]CB-22'!AG80 -> 0 | D34: ='[6]CB-22'!AH80 -> 0 | E34: ='[6]CB-22'!AI80 -> 0 | F34: ='[6]CB-22'!AJ80 -> 0 | G34: ='[6]CB-22'!AK80 -> 0 | H34: ='[6]CB-22'!AL80 -> 0 | I34: ='[6]CB-22'!AM80 -> 0 | J34: ='[6]CB-22'!AN80 -> 0 | ... X34: ='[6]CB-22'!BB80 -> 0 | Y34: ='[6]CB-22'!AG42 -> 0 | Z34: ='[6]CB-22'!AH42 -> 0 | AA34: ='[6]CB-22'!AI42 -> 0 | AB34: ='[6]CB-22'!AJ42 -> 0 | AC34: ='[6]CB-22'!AK42 -> 0 | AD34: ='[6]CB-22'!AL42 -> 0 | AE34: ='[6]CB-22'!AM42 -> 0 | AF34: ='[6]CB-22'!AN42 -> 0 | ... BP34: ='[6]CB-22'!BX42 -> 0
A35: 32 | B35: ='[6]CB-23'!$C$8 -> 0 | C35: ='[6]CB-23'!AG80 -> 0 | D35: ='[6]CB-23'!AH80 -> 0 | E35: ='[6]CB-23'!AI80 -> 0 | F35: ='[6]CB-23'!AJ80 -> 0 | G35: ='[6]CB-23'!AK80 -> 0 | H35: ='[6]CB-23'!AL80 -> 0 | I35: ='[6]CB-23'!AM80 -> 0 | J35: ='[6]CB-23'!AN80 -> 0 | ... X35: ='[6]CB-23'!BB80 -> 0 | Y35: ='[6]CB-23'!AG42 -> 0 | Z35: ='[6]CB-23'!AH42 -> 0 | AA35: ='[6]CB-23'!AI42 -> 0 | AB35: ='[6]CB-23'!AJ42 -> 0 | AC35: ='[6]CB-23'!AK42 -> 0 | AD35: ='[6]CB-23'!AL42 -> 0 | AE35: ='[6]CB-23'!AM42 -> 0 | AF35: ='[6]CB-23'!AN42 -> 0 | ... BP35: ='[6]CB-23'!BX42 -> 0
A36: 33 | B36: ='[6]CB-24'!$C$8 -> 0 | C36: ='[6]CB-24'!AG80 -> 0 | D36: ='[6]CB-24'!AH80 -> 0 | E36: ='[6]CB-24'!AI80 -> 0 | F36: ='[6]CB-24'!AJ80 -> 0 | G36: ='[6]CB-24'!AK80 -> 0 | H36: ='[6]CB-24'!AL80 -> 0 | I36: ='[6]CB-24'!AM80 -> 0 | J36: ='[6]CB-24'!AN80 -> 0 | ... X36: ='[6]CB-24'!BB80 -> 0 | Y36: ='[6]CB-24'!AG42 -> 0 | Z36: ='[6]CB-24'!AH42 -> 0 | AA36: ='[6]CB-24'!AI42 -> 0 | AB36: ='[6]CB-24'!AJ42 -> 0 | AC36: ='[6]CB-24'!AK42 -> 0 | AD36: ='[6]CB-24'!AL42 -> 0 | AE36: ='[6]CB-24'!AM42 -> 0 | AF36: ='[6]CB-24'!AN42 -> 0 | ... BP36: ='[6]CB-24'!BX42 -> 0
A37: 34 | B37: ='[7]DSV-1'!$C$8 -> DSV GARUDA OFFSHORE | C37: ='[7]DSV-1'!AG80 -> 0 | D37: ='[7]DSV-1'!AH80 -> 0 | E37: ='[7]DSV-1'!AI80 -> 0 | F37: ='[7]DSV-1'!AJ80 -> 0 | G37: ='[7]DSV-1'!AK80 -> 0 | H37: ='[7]DSV-1'!AL80 -> 0 | I37: ='[7]DSV-1'!AM80 -> 0 | J37: ='[7]DSV-1'!AN80 -> 0 | ... X37: ='[7]DSV-1'!BB80 -> 0 | Y37: ='[7]DSV-1'!AG42 -> 0 | Z37: ='[7]DSV-1'!AH42 -> 0 | AA37: ='[7]DSV-1'!AI42 -> 0 | AB37: ='[7]DSV-1'!AJ42 -> 0 | AC37: ='[7]DSV-1'!AK42 -> 0 | AD37: ='[7]DSV-1'!AL42 -> 0 | AE37: ='[7]DSV-1'!AM42 -> 0 | AF37: ='[7]DSV-1'!AN42 -> 0 | ... BP37: ='[7]DSV-1'!BX42 -> 0
A38: 35 | B38: ='[7]DSV-2'!$C$8 -> 0 | C38: ='[7]DSV-2'!AG80 -> 0 | D38: ='[7]DSV-2'!AH80 -> 0 | E38: ='[7]DSV-2'!AI80 -> 0 | F38: ='[7]DSV-2'!AJ80 -> 0 | G38: ='[7]DSV-2'!AK80 -> 0 | H38: ='[7]DSV-2'!AL80 -> 0 | I38: ='[7]DSV-2'!AM80 -> 0 | J38: ='[7]DSV-2'!AN80 -> 0 | ... X38: ='[7]DSV-2'!BB80 -> 0 | Y38: ='[7]DSV-2'!AG42 -> 0 | Z38: ='[7]DSV-2'!AH42 -> 0 | AA38: ='[7]DSV-2'!AI42 -> 0 | AB38: ='[7]DSV-2'!AJ42 -> 0 | AC38: ='[7]DSV-2'!AK42 -> 0 | AD38: ='[7]DSV-2'!AL42 -> 0 | AE38: ='[7]DSV-2'!AM42 -> 0 | AF38: ='[7]DSV-2'!AN42 -> 0 | ... BP38: ='[7]DSV-2'!BX42 -> 0
A39: 36 | B39: ='[7]DSV-3'!$C$8 -> 0 | C39: ='[7]DSV-3'!AG80 -> 0 | D39: ='[7]DSV-3'!AH80 -> 0 | E39: ='[7]DSV-3'!AI80 -> 0 | F39: ='[7]DSV-3'!AJ80 -> 0 | G39: ='[7]DSV-3'!AK80 -> 0 | H39: ='[7]DSV-3'!AL80 -> 0 | I39: ='[7]DSV-3'!AM80 -> 0 | J39: ='[7]DSV-3'!AN80 -> 0 | ... X39: ='[7]DSV-3'!BB80 -> 0 | Y39: ='[7]DSV-3'!AG42 -> 0 | Z39: ='[7]DSV-3'!AH42 -> 0 | AA39: ='[7]DSV-3'!AI42 -> 0 | AB39: ='[7]DSV-3'!AJ42 -> 0 | AC39: ='[7]DSV-3'!AK42 -> 0 | AD39: ='[7]DSV-3'!AL42 -> 0 | AE39: ='[7]DSV-3'!AM42 -> 0 | AF39: ='[7]DSV-3'!AN42 -> 0 | ... BP39: ='[7]DSV-3'!BX42 -> 0
A40: 37 | B40: ='[8]LCT-1'!$C$8 -> LCT Hamota 3 | C40: ='[8]LCT-1'!AG80 -> 0 | D40: ='[8]LCT-1'!AH80 -> 0 | E40: ='[8]LCT-1'!AI80 -> 0 | F40: ='[8]LCT-1'!AJ80 -> 0 | G40: ='[8]LCT-1'!AK80 -> 0 | H40: ='[8]LCT-1'!AL80 -> 0 | I40: ='[8]LCT-1'!AM80 -> 0 | J40: ='[8]LCT-1'!AN80 -> 0 | ... X40: ='[8]LCT-1'!BB80 -> 0 | Y40: ='[8]LCT-1'!AG42 -> 0 | Z40: ='[8]LCT-1'!AH42 -> 0 | AA40: ='[8]LCT-1'!AI42 -> 0 | AB40: ='[8]LCT-1'!AJ42 -> 0 | AC40: ='[8]LCT-1'!AK42 -> 0 | AD40: ='[8]LCT-1'!AL42 -> 0 | AE40: ='[8]LCT-1'!AM42 -> 0 | AF40: ='[8]LCT-1'!AN42 -> 0 | ... BP40: ='[8]LCT-1'!BX42 -> 0
A41: 38 | B41: ='[8]LCT-2'!$C$8 -> LCT Hamota Berau (call out contract since 25 Sept 2020) | C41: ='[8]LCT-2'!AG80 -> 0 | D41: ='[8]LCT-2'!AH80 -> 0 | E41: ='[8]LCT-2'!AI80 -> 0 | F41: ='[8]LCT-2'!AJ80 -> 0 | G41: ='[8]LCT-2'!AK80 -> 0 | H41: ='[8]LCT-2'!AL80 -> 0 | I41: ='[8]LCT-2'!AM80 -> 0 | J41: ='[8]LCT-2'!AN80 -> 0 | ... X41: ='[8]LCT-2'!BB80 -> 0 | Y41: ='[8]LCT-2'!AG42 -> 0 | Z41: ='[8]LCT-2'!AH42 -> 0 | AA41: ='[8]LCT-2'!AI42 -> 0 | AB41: ='[8]LCT-2'!AJ42 -> 0 | AC41: ='[8]LCT-2'!AK42 -> 0 | AD41: ='[8]LCT-2'!AL42 -> 0 | AE41: ='[8]LCT-2'!AM42 -> 0 | AF41: ='[8]LCT-2'!AN42 -> 0 | ... BP41: ='[8]LCT-2'!BX42 -> 0
...

Sheet Actual Cost Marine
A2: LOGISTICS
A3: No | B3: Nama Kapal | C3: Biaya BBM | E3: Biaya Sewa
C4: Liter | D4: USD
